Workbook

Sheet Master_สายพาน
B1: สายพาน | C1: SAP | D1: ProductNameTha | E1: Step
B2: ไหล่พิเศษ | C2: 23108242 | D2: สันคอหมูแต่งTT Spec-1 | E2: Step3
C3: 23015441 | D3: สันกลมแต่งพิเศษ 1 | E3: Step3
B4: เครื่องใน | C4: 23000197 | D4: เครื่องในชุด(หมู) | E4: Step1
B5: ต้มเลือด | C5: 23067920 | D5: เลือดก้อนTT | E5: Step2
B6: ต้มเลือด | C6: 23084674 | D6: เลือดหมูก้อนปรุงรสพาสเจอร์ไรซ์400กรัม-C | E6: Step2
B7: ไหล่ | C7: 23057697 | D7: ชิ้นมันคอTT | E7: Step2
B8: เศษ | C8: 23067921 | D8: เศษมันติดหนังTT | E8: Step2
B9: เศษ | C9: 23063344 | D9: เศษหนังTT | E9: Step2
B10: เครื่องใน | C10: 23000194 | D10: ไตหมู | E10: Step1
B11: เครื่องใน | C11: 23095558 | D11: ไตหมู (SIS) กก. ละ | E11: Step3
B12: ลวก | C12: 23000192 | D12: ไส้ใหญ่(ลวก) | E12: Step3
B13: เครื่องใน | C13: 23015350 | D13: ไส้ใหญ่ | E13: Step1
B14: เครื่องใน | C14: 23000181 | D14: ไส้ขม | E14: Step1
B15: ลวก | C15: 23014042 | D15: ไส้ตันลวก | E15: Step3
... B128: บด | C128: 23109359 | D128: หมูชีวาบด (ตรา ยูฟาร์ม) 400 กรัม | E128: Step3
C129: 23083450 | D129: น้ำมันหมู (ตรา ซีพี)
B130: เครื่องใน | C130: 23088112 | D130: เครื่องในหมูรวมหั่นชิ้น (M) | E130: Step2
B131: ต้มเลือด | C131: 23062107 | D131: เลือดก้อน(M) | E131: Step2
B132: ต้มเลือด | C132: 23084674 | D132: เลือดหมูก้อนปรุงรสพาสเจอร์ไรซ์400กรัม-C | E132: Step2
B133: ไหล่ | C133: 23000206 | D133: ชิ้นมันคอ | E133: Step2
B134: เครื่องใน | C134: 23058586 | D134: ไต (M) | E134: Step1
B135: เครื่องใน | C135: 23110617 | D135: เซ่งจี้หมู (ไตหมู) แพ็คถาด กก.ละ | E135: Step2
B136: ลวก | C136: 23058590 | D136: ไส้ใหญ่(ลวก) (M) | E136: Step3
B137: เครื่องใน | C137: 23110621 | D137: ไส้ใหญ่หมู แพ็คถาด กก.ละ | E137: Step2
B138: เครื่องใน | C138: 23066875 | D138: ไส้ขม(M) | E138: Step2
B139: ลวก | C139: 23062105 | D139: ไส้ตันลวก(M) | E139: Step3
B140: เครื่องใน | C140: 23093507 | D140: ไส้ตันหมู กก.ละ | E140: Step3
B141: เครื่องใน | C141: 23058589 | D141: ไส้อ่อน (M) | E141: Step2
... B185: เครื่องใน | C185: 23110580 | D185: หัวใจหมู แพ็คถาด กก.ละ | E185: Step2
B186: เปิดหมู | C186: 23023991 | D186: หัวติดลิ้น size M
B187: เผาขา | C187: 23062101 | D187: หางหมูเผา(M) | E187: Step3
B188: ไหล่ | C188: 23057809 | D188: เนื้อไหล่(M) | E188: Step2
B189: ไหล่พิเศษ | C189: 23086658 | D189: เนื้อไหล่ติดหนังสไลด์ | E189: Step3
B190: ไหล่พิเศษ | C190: 23088036 | D190: เนื้อไหล่หมูติดหนังหั่นชิ้น(M) | E190: Step3
B191: ไหล่พิเศษ | C191: 23097784 | D191: เนื้อไหล่หมูตัดชิ้น 1 กก. (M) | E191: Step3
B192: ไหล่ | C192: 23105751 | D192: เซพแพ็ค หัวไหล่หมู กก.ละ | E192: Step2
B193: ไหล่พิเศษ | C193: 23108712 | D193: ไหล่หมูตัดแต่ง แพ็ค กก.ละ | E193: Step3
B194: ไหล่พิเศษ | C194: 23110583 | D194: หัวไหล่ตัดชิ้น แพ็คถาด กก.ละ | E194: Step3
B195: สะโพกพิเศษ | C195: 23110589 | D195: เนื้อหมูหั่นแกง แพ็คถาด 1 กก. | E195: Step3
...

Sheet 0010
A1: รหัสและชื่อ | B1: โรงงาน | C1: คลัง | D1: รหัสสินค้า | E1: Product Name | F1: ว่าง1 | G1: ปริมาณยกมา | H1: น้ำหนักยกมา | I1: ว่าง2 | J1: ปริมาณผลิต | K1: น้ำหนักผลิต | L1: ว่าง3 | M1: ปริมาณจ่าย | N1: น้ำหนักจ่าย | O1: ว่าง4 | P1: ปริมาณเหลือ | Q1: น้ำหนักเหลือ | R1: W/Q | S1: หน่วย | T1: Product Code | U1: Plant Code | V1: รหัสคลังสินค้า
A2: 23078867>เศษสามชั้นสไลด์ | B2: 410310>โรงชำแหละสุกรพระพุทธบาท | C2: 0010>คลังสินค้าสำเร็จรูป WIP (00) | D2: 23078867 | E2: เศษสามชั้นสไลด์ | G2: 8 | H2: 40 | J2: 32 | K2: 160 | M2: 26 | N2: 130 | P2: 14 | Q2: 70 | R2: W | S2: ก.ก. | T2: 23078867 | U2: 410310 | V2: 10
A3: 90911002>เนื้อไหล่-Raw | B3: 410310>โรงชำแหละสุกรพระพุทธบาท | C3: 0010>คลังสินค้าสำเร็จรูป WIP (00) | D3: 90911002 | E3: เนื้อไหล่-Raw | G3: 36 | H3: 682.3 | J3: 159 | K3: 2923.65 | M3: 154 | N3: 2806.65 | P3: 41 | Q3: 799.3 | R3: W | S3: ก.ก. | T3: 23034410 | U3: 410310 | V3: 10
A4: 90912002>สะโพก-Raw | B4: 410310>โรงชำแหละสุกรพระพุทธบาท | C4: 0010>คลังสินค้าสำเร็จรูป WIP (00) | D4: 90912002 | E4: สะโพก-Raw | G4: 59 | H4: 1035.33 | J4: 337 | K4: 5414.38 | M4: 288 | N4: 4714.55 | P4: 108 | Q4: 1735.16 | R4: W | S4: ก.ก. | T4: 23034412 | U4: 410310 | V4: 10
A5: 90913001>สันนอก - Raw | B5: 410310>โรงชำแหละสุกรพระพุทธบาท | C5: 0010>คลังสินค้าสำเร็จรูป WIP (00) | D5: 90913001 | E5: สันนอก - Raw | G5: 200 | H5: 2764.72 | J5: 98 | K5: 1382.09 | M5: 48 | N5: 701.61 | P5: 250 | Q5: 3445.2 | R5: W | S5: ก.ก. | T5: 23034413 | U5: 410310 | V5: 10
A6: 90914001>สันใน-Raw | B6: 410310>โรงชำแหละสุกรพระพุทธบาท | C6: 0010>คลังสินค้าสำเร็จรูป WIP (00) | D6: 90914001 | E6: สันใน-Raw | G6: 2 | H6: 19.37 | J6: 13 | K6: 208.36 | M6: 12 | N6: 192.04 | P6: 3 | Q6: 35.69 | R6: W | S6: ก.ก. | T6: 23034415 | U6: 410310 | V6: 10
A7: 90915001>สันคอ-Raw | B7: 410310>โรงชำแหละสุกรพระพุทธบาท | C7: 0010>คลังสินค้าสำเร็จรูป WIP (00) | D7: 90915001 | E7: สันคอ-Raw | G7: 174 | H7: 2840.48 | J7: 97 | K7: 1553.23 | M7: 66 | N7: 1084.1 | P7: 205 | Q7: 3309.61 | R7: W | S7: ก.ก. | T7: 23034416 | U7: 410310 | V7: 10
A8: 90916001>สามชั้น-Raw | B8: 410310>โรงชำแหละสุกรพระพุทธบาท | C8: 0010>คลังสินค้าสำเร็จรูป WIP (00) | D8: 90916001 | E8: สามชั้น-Raw | G8: 57 | H8: 1015.94 | J8: 248 | K8: 3933.65 | M8: 262 | N8: 4231.52 | P8: 43 | Q8: 718.07 | R8: W | S8: ก.ก. | T8: 23034417 | U8: 410310 | V8: 10
A9: 90917001>ซี่โครงแผ่น-Raw | B9: 410310>โรงชำแหละสุกรพระพุทธบาท | C9: 0010>คลังสินค้าสำเร็จรูป WIP (00) | D9: 90917001 | E9: ซี่โครงแผ่น-Raw | G9: 6 | H9: 58.59 | J9: 140 | K9: 1449.45 | M9: 136 | N9: 1400.72 | P9: 10 | Q9: 107.32 | R9: W | S9: ก.ก. | T9: 23034418 | U9: 410310 | V9: 10
A10: 90920001>ขาหน้า-Raw | B10: 410310>โรงชำแหละสุกรพระพุทธบาท | C10: 0010>คลังสินค้าสำเร็จรูป WIP (00) | D10: 90920001 | E10: ขาหน้า-Raw | G10: 231 | H10: 4594.17 | J10: 101 | K10: 2064.02 | M10: 118 | N10: 2402.5 | P10: 214 | Q10: 4255.69 | R10: W | S10: ก.ก. | T10: 23034424 | U10: 410310 | V10: 10
A11: 90920002>ขาหลัง-Raw | B11: 410310>โรงชำแหละสุกรพระพุทธบาท | C11: 0010>คลังสินค้าสำเร็จรูป WIP (00) | D11: 90920002 | E11: ขาหลัง-Raw | G11: 220 | H11: 3953.72 | J11: 152 | K11: 2850.48 | M11: 186 | N11: 3455.07 | P11: 186 | Q11: 3349.13 | R11: W | S11: ก.ก. | T11: 23034425 | U11: 410310 | V11: 10
A12: 91110015>คอหมูย่าง (M) | B12: 410310>โรงชำแหละสุกรพระพุทธบาท | C12: 0010>คลังสินค้าสำเร็จรูป WIP (00) | D12: 91110015 | E12: คอหมูย่าง (M) | G12: 3 | H12: 15.4 | J12: 27 | K12: 137.7 | M12: 27 | N12: 137.6 | P12: 3 | Q12: 15.5 | R12: Q | S12: ก.ก. | T12: 23058551 | U12: 410310 | V12: 10
A13: 91110018>คอหมูย่างTT | B13: 410310>โรงชำแหละสุกรพระพุทธบาท | C13: 0010>คลังสินค้าสำเร็จรูป WIP (00) | D13: 91110018 | E13: คอหมูย่างTT | G13: 1 | H13: 5.28 | J13: 4 | K13: 20.42 | M13: 3 | N13: 15.54 | P13: 2 | Q13: 10.16 | R13: W | S13: ก.ก. | T13: 23057671 | U13: 410310 | V13: 10
... A126: 94128011>เลือดหมูก้อนปรุงรสพาสเจอร์ไรซ์400กรัม-C | B126: 410310>โรงชำแหละสุกรพระพุทธบาท | C126: 0010>คลังสินค้าสำเร็จรูป WIP (00) | D126: 94128011 | E126: เลือดหมูก้อนปรุงรสพาสเจอร์ไรซ์400กรัม-C | G126: 248 | H126: 99.2 | J126: 300 | K126: 120 | M126: 287 | N126: 114.8 | P126: 261 | Q126: 104.4 | R126: Q | S126: ถาด | T126: 23084674 | U126: 410310 | V126: 10

Sheet 20
A1: รหัสและชื่อ | B1: โรงงาน | C1: คลัง | D1: รหัสสินค้า | E1: Product Name | F1: ว่าง1 | G1: ปริมาณยกมา | H1: น้ำหนักยกมา | I1: ว่าง2 | J1: ปริมาณผลิต | K1: น้ำหนักผลิต | L1: ว่าง3 | M1: ปริมาณจ่าย | N1: น้ำหนักจ่าย | O1: ว่าง4 | P1: ปริมาณเหลือ | Q1: น้ำหนักเหลือ | R1: W/Q | S1: หน่วย | T1: Product Code | U1: Plant Code | V1: รหัสคลังสินค้า

Sheet ตลาด 11.00

Sheet ตลาด 12.00

Sheet ตลาด 13.00
A1: บมจ. ซีพีเอฟ โกลบอล ฟู้ด โซลูชั่น
A2: rDate1 | B2: rDate2 | C2: rRDate1 | D2: rRDate2 | E2: rRDate3 | F2: rOper_code | G2: rOper_name | H2: rSub_oper | I2: rSub_name | J2: rWarehouse | K2: rSub_warehouse | L2: rBst_code | M2: rBst_name | N2: rCv_code | O2: rCv_name | P2: rShip_to | Q2: rShip_name | R2: rDoc_date | S2: rReq_date | T2: rDoc_number | U2: rProduct_code | V2: rProduct_name | W2: rStock_qty | X2: rStock_wgt | Y2: rPlan_qty | Z2: rPlan_wgt | AA2: rDiff_stock_qty_plan | AB2: rDiff_stock_wgt_plan | AC2: rAllocate_stock_qty | AD2: rAllocate_stock_wgt | AE2: rDiff_stock_qty | AF2: rDiff_stock_wgt | AG2: rPlan_byquota_qty | AH2: rPlan_byquota_wgt | AI2: rBreak | AJ2: rEntry_type | AK2: rProduct_group_code1 | AL2: rProduct_group_code2 | AM2: rProduct_group_dim1 | AN2: rCv_channel | AO2: rCV_FLAG1 | AP2: rCV_FLAG2 | AQ2: rCV_FLAG3 | AR2: rCV_FLAG4 | AS2: rCV_FLAG5 | AT2: rOwner_so | AU2: rCreate_date_so | AV2: rUm_stock_qty | AW2: rUm_stock_wgt | AX2: rArea | AY2: nShow_area | AZ2: rModel | BA2: rPO_no | BB2: rDO_no | BC2: rINV_no | BD2: rDoc_issue | BE2: rPlant_code | BF2: rAllocate_remark | BG2: rVendor_code | BH2: rStatus | BI2: rStock_qty_pur | BJ2: rStock_wgt_pur | BK2: rCut_off_time | BL2: rOwner_create | BM2: rCo_load | BN2: rLicense_plate
C3: 244688 | D3: 244688 | F3: 0003TT | G3: DMCW-รชล-พระพุทธบาท | H3: 0 | I3: หน่วยงานกลาง | J3: F213 DMCW-รชล-พระพุทธบาท | K3: 00000 หน่วยงานกลาง | L3: 27 | N3: 3 | O3: FO แปดริ้ว | R3: 244688 | S3: 244688 | T3: 8292073673 | U3: 23034417 | V3: สามชั้น-Raw | W3: 50 | X3: 1000 | Y3: 50 | Z3: 1000 | AA3: 0 | AB3: 0 | AC3: 0 | AD3: 0 | AE3: 50 | AF3: 1000 | AI3: OPRCD0003TTOPRCD00000OPRCDF213OPRCD00000OPRCD027 | AJ3: ซื้อ / ขาย | AO3: TT | AV3: ตะกร้า | AW3: ก.ก. | AX3: NA | AY3: 0 | AZ3: N | BD3: 0 | BG3: 1333314600 | BH3: G | BI3: 50 | BJ3: 1000 | BK3: 1300 | BL3: TEERANUT.BOO
C4: 244688 | D4: 244688 | F4: 1183TT | G4: DMCW-รชล-พระพุทธบาท | H4: 0 | I4: หน่วยงานกลาง | J4: F213 DMCW-รชล-พระพุทธบาท | K4: 00000 หน่วยงานกลาง | L4: 27 | N4: 1183 | O4: DMBK- Pork Shopคลองหลวง | R4: 244688 | S4: 244688 | T4: 8292073676 | U4: 23026536 | V4: หมูซาก-RM | W4: 12000 | X4: 12000 | Y4: 12000 | Z4: 12000 | AA4: 0 | AB4: 0 | AC4: 0 | AD4: 0 | AE4: 12000 | AF4: 12000 | AI4: OPRCD1183TTOPRCD00000OPRCDF213OPRCD00000OPRCD027 | AJ4: ซื้อ / ขาย | AO4: TT | AV4: ตัว | AW4: ก.ก. | AX4: NA | AY4: 0 | AZ4: N | BD4: 0 | BG4: 1333314600 | BH4: G | BI4: 12000 | BJ4: 12000 | BK4: 1300 | BL4: TEERANUT.BOO
C5: 244688 | D5: 244688 | F5: 1183TT | G5: DMCW-รชล-พระพุทธบาท | H5: 0 | I5: หน่วยงานกลาง | J5: F213 DMCW-รชล-พระพุทธบาท | K5: 00000 หน่วยงานกลาง | L5: 27 | N5: 1183 | O5: DMBK- Pork Shopคลองหลวง | R5: 244688 | S5: 244688 | T5: 8292073679 | U5: 23034408 | V5: คอหมูย่าง-Raw | W5: 10 | X5: 200 | Y5: 10 | Z5: 200 | AA5: 0 | AB5: 0 | AC5: 0 | AD5: 0 | AE5: 10 | AF5: 200 | AI5: OPRCD1183TTOPRCD00000OPRCDF213OPRCD00000OPRCD027 | AJ5: ซื้อ / ขาย | AO5: TT | AV5: ตะกร้า | AW5: ก.ก. | AX5: NA | AY5: 0 | AZ5: N | BD5: 0 | BG5: 1333314600 | BH5: G | BI5: 10 | BJ5: 200 | BK5: 1300 | BL5: TEERANUT.BOO
C6: 244688 | D6: 244688 | F6: 2276ATT | G6: DMCW-รชล-พระพุทธบาท | H6: 0 | I6: หน่วยงานกลาง | J6: F213 DMCW-รชล-พระพุทธบาท | K6: 00000 หน่วยงานกลาง | L6: 27 | N6: 2276A | O6: CPFTH-โรงเชือดจิตรรุ่งเรือง | R6: 244688 | S6: 244688 | T6: 8292073678 | U6: 23000197 | V6: เครื่องในชุด(หมู) | W6: 150 | X6: 1500 | Y6: 150 | Z6: 1500 | AA6: 0 | AB6: 0 | AC6: 0 | AD6: 0 | AE6: 150 | AF6: 1500 | AI6: OPRCD2276ATTOPRCD00000OPRCDF213OPRCD00000OPRCD027 | AJ6: ซื้อ / ขาย | AK6: By proudct | AL6: Bulk Normal | AM6: สุกร | AO6: TT | AV6: ถุง | AW6: ก.ก. | AX6: NA | AY6: 0 | AZ6: N | BD6: 0 | BG6: F213 | BH6: G | BI6: 150 | BJ6: 1500 | BL6: TEERANUT.BOO
C7: 244688 | D7: 244688 | F7: 2585ATT | G7: DMCW-รชล-พระพุทธบาท | H7: 0 | I7: หน่วยงานกลาง | J7: F213 DMCW-รชล-พระพุทธบาท | K7: 00000 หน่วยงานกลาง | L7: 27 | N7: 2585A | O7: DMNL-โรงชำแหละและตัดแต่งกำแพงเพชร | R7: 244688 | S7: 244688 | T7: 8292073680 | U7: 23034424 | V7: ขาหน้า-Raw | W7: 50 | X7: 500 | Y7: 50 | Z7: 500 | AA7: 0 | AB7: 0 | AC7: 0 | AD7: 0 | AE7: 50 | AF7: 500 | AI7: OPRCD2585ATTOPRCD00000OPRCDF213OPRCD00000OPRCD027 | AJ7: ซื้อ / ขาย | AO7: TT | AV7: ตะกร้า | AW7: ก.ก. | AX7: NA | AY7: 0 | AZ7: N | BD7: 0 | BG7: 1333314600 | BH7: G | BI7: 50 | BJ7: 500 | BK7: 1300 | BL7: TEERANUT.BOO
C8: 244688 | D8: 244688 | F8: 2585ATT | G8: DMCW-รชล-พระพุทธบาท | H8: 0 | I8: หน่วยงานกลาง | J8: F213 DMCW-รชล-พระพุทธบาท | K8: 00000 หน่วยงานกลาง | L8: 27 | N8: 2585A | O8: DMNL-โรงชำแหละและตัดแต่งกำแพงเพชร | R8: 244688 | S8: 244688 | T8: 8292073680 | U8: 23034425 | V8: ขาหลัง-Raw | W8: 75 | X8: 1000 | Y8: 75 | Z8: 1000 | AA8: 0 | AB8: 0 | AC8: 0 | AD8: 0 | AE8: 75 | AF8: 1000 | AI8: OPRCD2585ATTOPRCD00000OPRCDF213OPRCD00000OPRCD027 | AJ8: ซื้อ / ขาย | AO8: TT | AV8: ตะกร้า | AW8: ก.ก. | AX8: NA | AY8: 0 | AZ8: N | BD8: 0 | BG8: 1333314600 | BH8: G | BI8: 75 | BJ8: 1000 | BK8: 1300 | BL8: TEERANUT.BOO
C9: 244688 | D9: 244688 | F9: CE15 | G9: TTCW2-นครปฐม | H9: 0 | I9: หน่วยงานกลาง | J9: F213 DMCW-รชล-พระพุทธบาท | K9: 00000 หน่วยงานกลาง | L9: 250 | N9: 2000254637 | O9: บจ. เบสท์ มีท (สำนักงานใหญ่) | P9: 1 | Q9: เบสท์ มีท | R9: 244688 | S9: 244688 | T9: I69A54NH0016097 | U9: 23000197 | V9: เครื่องในชุด(หมู) | W9: 50 | X9: 500 | Y9: 50 | Z9: 500 | AA9: 0 | AB9: 0 | AC9: 0 | AD9: 0 | AE9: 50 | AF9: 500 | AI9: OPRCDCE15OPRCD00000OPRCDF213OPRCD00000OPRCD250 | AJ9: ซื้อ / ขาย | AK9: By proudct | AL9: Bulk Normal | AM9: สุกร | AN9: 01 ขายเงินสด (POS) | AO9: TT | AU9: 2026-05-12-09.59.28.000000 | AV9: ถุง | AW9: ก.ก. | AY9: 0 | AZ9: N | BA9: 31789593 | BD9: 0 | BG9: 1333314600 | BH9: G | BI9: 50 | BJ9: 500 | BK9: 1300 | BL9: TEERANUT.BOO
C10: 244688 | D10: 244688 | F10: CE15 | G10: TTCW2-นครปฐม | H10: 0 | I10: หน่วยงานกลาง | J10: F213 DMCW-รชล-พระพุทธบาท | K10: 00000 หน่วยงานกลาง | L10: 250 | N10: 2000334891 | O10: บจ. หมูไตเติ้ล | P10: 1 | Q10: หมูไตเติ้ล | R10: 244688 | S10: 244688 | T10: I69A54NH0016137 | U10: 23107368 | V10: เครื่องในชุด(หมู)แต่ง | W10: 100 | X10: 1300 | Y10: 100 | Z10: 1300 | AA10: 0 | AB10: 0 | AC10: 0 | AD10: 0 | AE10: 100 | AF10: 1300 | AI10: OPRCDCE15OPRCD00000OPRCDF213OPRCD00000OPRCD250 | AJ10: ซื้อ / ขาย | AN10: TT1001 แผงและรถเข็น ตลาดสด | AO10: TT | AP10: 10 | AQ10: 1 | AU10: 2026-05-12-11.33.22.000000 | AV10: แพ็ค | AW10: ก.ก. | AY10: 0 | AZ10: N | BA10: 31796257 | BD10: 0 | BG10: 1333314600 | BH10: G | BI10: 100 | BJ10: 1300 | BK10: 1300 | BL10: TEERANUT.BOO
C11: 244688 | D11: 244688 | F11: CE17 | G11: TTCW3-ลพบุรี | H11: 0 | I11: หน่วยงานกลาง | J11: F213 DMCW-รชล-พระพุทธบาท | K11: 00000 หน่วยงานกลาง | L11: 250 | N11: 2000350887 | O11: นางสาว สปัญญา เจริญวงษ์ | P11: 1 | Q11: นางสาว สปัญญา เจริญวงษ์ | R11: 244688 | S11: 244688 | T11: I69A54NI0033941 | U11: 23015390 | V11: เลือดหมูสด | W11: 2 | X11: 2 | Y11: 2 | Z11: 2 | AA11: 0 | AB11: 0 | AC11: 0 | AD11: 0 | AE11: 2 | AF11: 2 | AI11: OPRCDCE17OPRCD00000OPRCDF213OPRCD00000OPRCD250 | AJ11: ซื้อ / ขาย | AK11: By proudct | AL11: Bulk Normal | AM11: สุกร | AN11: 837 ตลาดสด/ตลาดนัด(CPFM) | AO11: TT | AU11: 2026-05-12-07.49.38.000000 | AV11: ก.ก. | AW11: ก.ก. | AY11: 0 | AZ11: N | BA11: 31784170 | BD11: 0 | BG11: 1333314600 | BH11: G | BI11: 2 | BJ11: 2 | BK11: 1300 | BL11: TEERANUT.BOO
C12: 244688 | D12: 244688 | F12: CE17 | G12: TTCW3-ลพบุรี | H12: 0 | I12: หน่วยงานกลาง | J12: F213 DMCW-รชล-พระพุทธบาท | K12: 00000 หน่วยงานกลาง | L12: 250 | N12: 2000390415 | O12: นางสาว แฉล้ม จันทร์ทองเทศ | P12: 1 | Q12: นางสาว แฉล้ม จันทร์ทองเทศ | R12: 244688 | S12: 244688 | T12: I69A54NI0033945 | U12: 23071823 | V12: หนังขาหมู | W12: 10 | X12: 10 | Y12: 10 | Z12: 10 | AA12: 0 | AB12: 0 | AC12: 0 | AD12: 0 | AE12: 10 | AF12: 10 | AI12: OPRCDCE17OPRCD00000OPRCDF213OPRCD00000OPRCD250 | AJ12: ซื้อ / ขาย | AN12: 837 ตลาดสด/ตลาดนัด(CPFM) | AO12: TT | AU12: 2026-05-12-08.59.00.000000 | AV12: ก.ก. | AW12: ก.ก. | AY12: 0 | AZ12: N | BA12: 31785919 | BD12: 0 | BG12: 1333314600 | BH12: G | BI12: 10 | BJ12: 10 | BL12: TEERANUT.BOO
C13: 244688 | D13: 244688 | F13: CE17 | G13: TTCW3-ลพบุรี | H13: 0 | I13: หน่วยงานกลาง | J13: F213 DMCW-รชล-พระพุทธบาท | K13: 00000 หน่วยงานกลาง | L13: 250 | N13: 2000390415 | O13: นางสาว แฉล้ม จันทร์ทองเทศ | P13: 1 | Q13: นางสาว แฉล้ม จันทร์ทองเทศ | R13: 244688 | S13: 244688 | T13: I69A54NI0033945 | U13: 23057674 | V13: สันนอกTT | W13: 5 | X13: 5 | Y13: 5 | Z13: 5 | AA13: 0 | AB13: 0 | AC13: 0 | AD13: 0 | AE13: 5 | AF13: 5 | AI13: OPRCDCE17OPRCD00000OPRCDF213OPRCD00000OPRCD250 | AJ13: ซื้อ / ขาย | AK13: Main proudct | AL13: Bulk Normal | AM13: สุกร | AN13: 837 ตลาดสด/ตลาดนัด(CPFM) | AO13: TT | AU13: 2026-05-12-08.59.00.000000 | AV13: ก.ก. | AW13: ก.ก. | AY13: 0 | AZ13: N | BA13: 31785919 | BD13: 0 | BG13: 1333314600 | BH13: G | BI13: 5 | BJ13: 5 | BL13: TEERANUT.BOO
C14: 244688 | D14: 244688 | F14: CE17 | G14: TTCW3-ลพบุรี | H14: 0 | I14: หน่วยงานกลาง | J14: F213 DMCW-รชล-พระพุทธบาท | K14: 00000 หน่วยงานกลาง | L14: 250 | N14: 2000390415 | O14: นางสาว แฉล้ม จันทร์ทองเทศ | P14: 1 | Q14: นางสาว แฉล้ม จันทร์ทองเทศ | R14: 244688 | S14: 244688 | T14: I69A54NI0033945 | U14: 23072463 | V14: ขาหมูเลาะติดหนัง | W14: 30 | X14: 30 | Y14: 30 | Z14: 30 | AA14: 0 | AB14: 0 | AC14: 0 | AD14: 0 | AE14: 30 | AF14: 30 | AI14: OPRCDCE17OPRCD00000OPRCDF213OPRCD00000OPRCD250 | AJ14: ซื้อ / ขาย | AK14: By proudct | AL14: Bulk Normal | AM14: สุกร | AN14: 837 ตลาดสด/ตลาดนัด(CPFM) | AO14: TT | AU14: 2026-05-12-08.59.00.000000 | AV14: ก.ก. | AW14: ก.ก. | AY14: 0 | AZ14: N | BA14: 31785919 | BD14: 0 | BG14: 1333314600 | BH14: G | BI14: 30 | BJ14: 30 | BL14: TEERANUT.BOO
C15: 244688 | D15: 244688 | F15: CE17 | G15: TTCW3-ลพบุรี | H15: 0 | I15: หน่วยงานกลาง | J15: F213 DMCW-รชล-พระพุทธบาท | K15: 00000 หน่วยงานกลาง | L15: 250 | N15: 2000390415 | O15: นางสาว แฉล้ม จันทร์ทองเทศ | P15: 1 | Q15: นางสาว แฉล้ม จันทร์ทองเทศ | R15: 244688 | S15: 244688 | T15: I69A54NI0033945 | U15: 23000168 | V15: เนื้อขาเลาะ | W15: 10 | X15: 10 | Y15: 10 | Z15: 10 | AA15: 0 | AB15: 0 | AC15: 0 | AD15: 0 | AE15: 10 | AF15: 10 | AI15: OPRCDCE17OPRCD00000OPRCDF213OPRCD00000OPRCD250 | AJ15: ซื้อ / ขาย | AN15: 837 ตลาดสด/ตลาดนัด(CPFM) | AO15: TT | AU15: 2026-05-12-08.59.00.000000 | AV15: ก.ก. | AW15: ก.ก. | AY15: 0 | AZ15: N | BA15: 31785919 | BD15: 0 | BG15: 1333314600 | BH15: G | BI15: 10 | BJ15: 10 | BL15: TEERANUT.BOO
C16: 244688 | D16: 244688 | F16: CE17 | G16: TTCW3-ลพบุรี | H16: 0 | I16: หน่วยงานกลาง | J16: F213 DMCW-รชล-พระพุทธบาท | K16: 00000 หน่วยงานกลาง | L16: 250 | N16: 2000386385 | O16: นาง สำอางค์ เหนี่ยงจิตต์ | P16: 1 | Q16: นาง สำอางค์ เหนี่ยงจิตต์ | R16: 244688 | S16: 244688 | T16: I69A54NI0033949 | U16: 23089920 | V16: หมูนุ่มปรุงรส(SPC)_B2C 1 กก.-F | W16: 10 | X16: 10 | Y16: 10 | Z16: 10 | AA16: 0 | AB16: 0 | AC16: 0 | AD16: 0 | AE16: 10 | AF16: 10 | AI16: OPRCDCE17OPRCD00000OPRCDF213OPRCD00000OPRCD250 | AJ16: ซื้อ / ขาย | AK16: Main proudct | AL16: CP Brand(ซอง) | AM16: สุกร | AN16: 837 ตลาดสด/ตลาดนัด(CPFM) | AO16: TT | AU16: 2026-05-12-09.18.34.000000 | AV16: แพ็ค | AW16: ก.ก. | AY16: 0 | AZ16: N | BA16: 31786906 | BD16: 0 | BG16: 1333314600 | BH16: G | BI16: 1 | BJ16: 10 | BL16: TEERANUT.BOO
C17: 244688 | D17: 244688 | F17: CE17 | G17: TTCW3-ลพบุรี | H17: 0 | I17: หน่วยงานกลาง | J17: F213 DMCW-รชล-พระพุทธบาท | K17: 00000 หน่วยงานกลาง | L17: 250 | N17: 2000395213 | O17: นางสาว วนิดา วงษ์นรา | P17: 1 | Q17: นางสาว วนิดา วงษ์นรา | R17: 244688 | S17: 244688 | T17: I69A54NI0033952 | U17: 23000189 | V17: กระเพาะ | W17: 6 | X17: 6 | Y17: 6 | Z17: 6 | AA17: 0 | AB17: 0 | AC17: 0 | AD17: 0 | AE17: 6 | AF17: 6 | AI17: OPRCDCE17OPRCD00000OPRCDF213OPRCD00000OPRCD250 | AJ17: ซื้อ / ขาย | AK17: By proudct | AL17: Bulk Normal | AM17: สุกร | AN17: 837 ตลาดสด/ตลาดนัด(CPFM) | AO17: TT | AU17: 2026-05-12-09.30.34.000000 | AV17: ก.ก. | AW17: ก.ก. | AY17: 0 | AZ17: N | BA17: 31787608 | BD17: 0 | BG17: 1333314600 | BH17: G | BI17: 6 | BJ17: 6 | BK17: 1300 | BL17: TEERANUT.BOO
C18: 244688 | D18: 244688 | F18: CE17 | G18: TTCW3-ลพบุรี | H18: 0 | I18: หน่วยงานกลาง | J18: F213 DMCW-รชล-พระพุทธบาท | K18: 00000 หน่วยงานกลาง | L18: 250 | N18: 2000395213 | O18: นางสาว วนิดา วงษ์นรา | P18: 1 | Q18: นางสาว วนิดา วงษ์นรา | R18: 244688 | S18: 244688 | T18: I69A54NI0033952 | U18: 23057698 | V18: หมูบดTT | W18: 10 | X18: 10 | Y18: 10 | Z18: 10 | AA18: 0 | AB18: 0 | AC18: 0 | AD18: 0 | AE18: 10 | AF18: 10 | AI18: OPRCDCE17OPRCD00000OPRCDF213OPRCD00000OPRCD250 | AJ18: ซื้อ / ขาย | AK18: Main proudct | AL18: Bulk Normal | AM18: สุกร | AN18: 837 ตลาดสด/ตลาดนัด(CPFM) | AO18: TT | AU18: 2026-05-12-09.30.34.000000 | AV18: ก.ก. | AW18: ก.ก. | AY18: 0 | AZ18: N | BA18: 31787608 | BD18: 0 | BG18: 1333314600 | BH18: G | BI18: 10 | BJ18: 10 | BK18: 1300 | BL18: TEERANUT.BOO
C19: 244688 | D19: 244688 | F19: CE17 | G19: TTCW3-ลพบุรี | H19: 0 | I19: หน่วยงานกลาง | J19: F213 DMCW-รชล-พระพุทธบาท | K19: 00000 หน่วยงานกลาง | L19: 250 | N19: 2000395213 | O19: นางสาว วนิดา วงษ์นรา | P19: 1 | Q19: นางสาว วนิดา วงษ์นรา | R19: 244688 | S19: 244688 | T19: I69A54NI0033952 | U19: 23015189 | V19: เนื้อแดงหั่นชิ้น | W19: 5 | X19: 5 | Y19: 5 | Z19: 5 | AA19: 0 | AB19: 0 | AC19: 0 | AD19: 0 | AE19: 5 | AF19: 5 | AI19: OPRCDCE17OPRCD00000OPRCDF213OPRCD00000OPRCD250 | AJ19: ซื้อ / ขาย | AK19: Main proudct | AL19: Bulk Normal | AM19: สุกร | AN19: 837 ตลาดสด/ตลาดนัด(CPFM) | AO19: TT | AU19: 2026-05-12-09.30.34.000000 | AV19: ก.ก. | AW19: ก.ก. | AY19: 0 | AZ19: N | BA19: 31787608 | BD19: 0 | BG19: 1333314600 | BH19: G | BI19: 5 | BJ19: 5 | BK19: 1300 | BL19: TEERANUT.BOO
C20: 244688 | D20: 244688 | F20: CE17 | G20: TTCW3-ลพบุรี | H20: 0 | I20: หน่วยงานกลาง | J20: F213 DMCW-รชล-พระพุทธบาท | K20: 00000 หน่วยงานกลาง | L20: 250 | N20: 2000235043 | O20: นาย วิษณุ กันคำ | P20: 1 | Q20: วิษณุ กันคำ | R20: 244688 | S20: 244688 | T20: I69A54NI0033954 | U20: 23105855 | V20: สะโพกหมู B2B (Basic) | W20: 3 | X20: 30 | Y20: 3 | Z20: 30 | AA20: 0 | AB20: 0 | AC20: 0 | AD20: 0 | AE20: 3 | AF20: 30 | AI20: OPRCDCE17OPRCD00000OPRCDF213OPRCD00000OPRCD250 | AJ20: ซื้อ / ขาย | AK20: Main proudct | AL20: Bulk Normal | AM20: สุกร | AN20: 01 ขายเงินสด (POS) | AO20: TT | AU20: 2026-05-12-09.34.31.000000 | AV20: ถุง | AW20: ก.ก. | AY20: 0 | AZ20: N | BA20: 31787884 | BD20: 0 | BG20: 1333314600 | BH20: G | BI20: 3 | BJ20: 30 | BK20: 1300 | BL20: TEERANUT.BOO
C21: 244688 | D21: 244688 | F21: CE17 | G21: TTCW3-ลพบุรี | H21: 0 | I21: หน่วยงานกลาง | J21: F213 DMCW-รชล-พระพุทธบาท | K21: 00000 หน่วยงานกลาง | L21: 250 | N21: 2000235043 | O21: นาย วิษณุ กันคำ | P21: 1 | Q21: วิษณุ กันคำ | R21: 244688 | S21: 244688 | T21: I69A54NI0033954 | U21: 23000191 | V21: ไส้อ่อน | W21: 6 | X21: 6 | Y21: 6 | Z21: 6 | AA21: 0 | AB21: 0 | AC21: 0 | AD21: 0 | AE21: 6 | AF21: 6 | AI21: OPRCDCE17OPRCD00000OPRCDF213OPRCD00000OPRCD250 | AJ21: ซื้อ / ขาย | AK21: By proudct | AL21: Bulk Normal | AM21: สุกร | AN21: 01 ขายเงินสด (POS) | AO21: TT | AU21: 2026-05-12-09.34.31.000000 | AV21: ก.ก. | AW21: ก.ก. | AY21: 0 | AZ21: N | BA21: 31787884 | BD21: 0 | BG21: 1333314600 | BH21: G | BI21: 6 | BJ21: 6 | BK21: 1300 | BL21: TEERANUT.BOO
C22: 244688 | D22: 244688 | F22: CE17 | G22: TTCW3-ลพบุรี | H22: 0 | I22: หน่วยงานกลาง | J22: F213 DMCW-รชล-พระพุทธบาท | K22: 00000 หน่วยงานกลาง | L22: 250 | N22: 2000235043 | O22: นาย วิษณุ กันคำ | P22: 1 | Q22: วิษณุ กันคำ | R22: 244688 | S22: 244688 | T22: I69A54NI0033954 | U22: 23000188 | V22: ตับหมู | W22: 6 | X22: 6 | Y22: 6 | Z22: 6 | AA22: 0 | AB22: 0 | AC22: 0 | AD22: 0 | AE22: 6 | AF22: 6 | AI22: OPRCDCE17OPRCD00000OPRCDF213OPRCD00000OPRCD250 | AJ22: ซื้อ / ขาย | AK22: By proudct | AL22: Bulk Normal | AM22: สุกร | AN22: 01 ขายเงินสด (POS) | AO22: TT | AU22: 2026-05-12-09.34.31.000000 | AV22: ก.ก. | AW22: ก.ก. | AY22: 0 | AZ22: N | BA22: 31787884 | BD22: 0 | BG22: 1333314600 | BH22: G | BI22: 6 | BJ22: 6 | BK22: 1300 | BL22: TEERANUT.BOO
C23: 244688 | D23: 244688 | F23: CE17 | G23: TTCW3-ลพบุรี | H23: 0 | I23: หน่วยงานกลาง | J23: F213 DMCW-รชล-พระพุทธบาท | K23: 00000 หน่วยงานกลาง | L23: 250 | N23: 2000235043 | O23: นาย วิษณุ กันคำ | P23: 1 | Q23: วิษณุ กันคำ | R23: 244688 | S23: 244688 | T23: I69A54NI0033954 | U23: 23057675 | V23: สันในTT | W23: 5 | X23: 5 | Y23: 5 | Z23: 5 | AA23: 0 | AB23: 0 | AC23: 0 | AD23: 0 | AE23: 5 | AF23: 5 | AI23: OPRCDCE17OPRCD00000OPRCDF213OPRCD00000OPRCD250 | AJ23: ซื้อ / ขาย | AK23: Main proudct | AL23: Bulk Normal | AM23: สุกร | AN23: 01 ขายเงินสด (POS) | AO23: TT | AU23: 2026-05-12-09.34.31.000000 | AV23: ก.ก. | AW23: ก.ก. | AY23: 0 | AZ23: N | BA23: 31787884 | BD23: 0 | BG23: 1333314600 | BH23: G | BI23: 5 | BJ23: 5 | BK23: 1300 | BL23: TEERANUT.BOO
C24: 244688 | D24: 244688 | F24: CE17 | G24: TTCW3-ลพบุรี | H24: 0 | I24: หน่วยงานกลาง | J24: F213 DMCW-รชล-พระพุทธบาท | K24: 00000 หน่วยงานกลาง | L24: 250 | N24: 2000235043 | O24: นาย วิษณุ กันคำ | P24: 1 | Q24: วิษณุ กันคำ | R24: 244688 | S24: 244688 | T24: I69A54NI0033954 | U24: 23105856 | V24: สันนอกหมู B2B (Basic) | W24: 1 | X24: 12 | Y24: 1 | Z24: 12 | AA24: 0 | AB24: 0 | AC24: 0 | AD24: 0 | AE24: 1 | AF24: 12 | AI24: OPRCDCE17OPRCD00000OPRCDF213OPRCD00000OPRCD250 | AJ24: ซื้อ / ขาย | AK24: Main proudct | AL24: Bulk Normal | AM24: สุกร | AN24: 01 ขายเงินสด (POS) | AO24: TT | AU24: 2026-05-12-09.34.31.000000 | AV24: ถุง | AW24: ก.ก. | AY24: 0 | AZ24: N | BA24: 31787884 | BD24: 0 | BG24: 1333314600 | BH24: G | BI24: 1 | BJ24: 12 | BK24: 1300 | BL24: TEERANUT.BOO
C25: 244688 | D25: 244688 | F25: CE17 | G25: TTCW3-ลพบุรี | H25: 0 | I25: หน่วยงานกลาง | J25: F213 DMCW-รชล-พระพุทธบาท | K25: 00000 หน่วยงานกลาง | L25: 250 | N25: 2000235043 | O25: นาย วิษณุ กันคำ | P25: 1 | Q25: วิษณุ กันคำ | R25: 244688 | S25: 244688 | T25: I69A54NI0033954 | U25: 23057677 | V25: สามชั้นTT | W25: 28 | X25: 28 | Y25: 28 | Z25: 28 | AA25: 0 | AB25: 0 | AC25: 0 | AD25: 0 | AE25: 28 | AF25: 28 | AI25: OPRCDCE17OPRCD00000OPRCDF213OPRCD00000OPRCD250 | AJ25: ซื้อ / ขาย | AK25: Main proudct | AL25: Bulk Normal | AM25: สุกร | AN25: 01 ขายเงินสด (POS) | AO25: TT | AU25: 2026-05-12-09.34.31.000000 | AV25: ก.ก. | AW25: ก.ก. | AY25: 0 | AZ25: N | BA25: 31787884 | BD25: 0 | BG25: 1333314600 | BH25: G | BI25: 28 | BJ25: 28 | BK25: 1300 | BL25: TEERANUT.BOO
C26: 244688 | D26: 244688 | F26: CE17 | G26: TTCW3-ลพบุรี | H26: 0 | I26: หน่วยงานกลาง | J26: F213 DMCW-รชล-พระพุทธบาท | K26: 00000 หน่วยงานกลาง | L26: 250 | N26: 2000390629 | O26: นาย เจตริน อินทวงษ์ | P26: 1 | Q26: นาย เจตริน อินทวงษ์ | R26: 244688 | S26: 244688 | T26: I69A54NI0033957 | U26: 23057698 | V26: หมูบดTT | W26: 5 | X26: 5 | Y26: 5 | Z26: 5 | AA26: 0 | AB26: 0 | AC26: 0 | AD26: 0 | AE26: 5 | AF26: 5 | AI26: OPRCDCE17OPRCD00000OPRCDF213OPRCD00000OPRCD250 | AJ26: ซื้อ / ขาย | AK26: Main proudct | AL26: Bulk Normal | AM26: สุกร | AN26: 837 ตลาดสด/ตลาดนัด(CPFM) | AO26: TT | AU26: 2026-05-12-09.39.31.000000 | AV26: ก.ก. | AW26: ก.ก. | AY26: 0 | AZ26: N | BA26: 31788203 | BD26: 0 | BG26: 1333314600 | BH26: G | BI26: 5 | BJ26: 5 | BK26: 1300 | BL26: TEERANUT.BOO
C27: 244688 | D27: 244688 | F27: CE17 | G27: TTCW3-ลพบุรี | H27: 0 | I27: หน่วยงานกลาง | J27: F213 DMCW-รชล-พระพุทธบาท | K27: 00000 หน่วยงานกลาง | L27: 250 | N27: 2000404917 | O27: นางสาว ภิญญา เคนวงบริบูรณ์ | P27: 1 | Q27: นางสาว ภิญญา เคนวงบริบูรณ์ | R27: 244688 | S27: 244688 | T27: I69A54NI0033958 | U27: 23057673 | V27: สะโพกTT | W27: 9 | X27: 9 | Y27: 9 | Z27: 9 | AA27: 0 | AB27: 0 | AC27: 0 | AD27: 0 | AE27: 9 | AF27: 9 | AI27: OPRCDCE17OPRCD00000OPRCDF213OPRCD00000OPRCD250 | AJ27: ซื้อ / ขาย | AK27: Main proudct | AL27: Bulk Normal | AM27: สุกร | AN27: 837 ตลาดสด/ตลาดนัด(CPFM) | AO27: TT | AU27: 2026-05-12-09.41.14.000000 | AV27: ก.ก. | AW27: ก.ก. | AY27: 0 | AZ27: N | BA27: 31788324 | BD27: 0 | BG27: 1333314600 | BH27: G | BI27: 9 | BJ27: 9 | BL27: TEERANUT.BOO
C28: 244688 | D28: 244688 | F28: CE17 | G28: TTCW3-ลพบุรี | H28: 0 | I28: หน่วยงานกลาง | J28: F213 DMCW-รชล-พระพุทธบาท | K28: 00000 หน่วยงานกลาง | L28: 250 | N28: 2000404917 | O28: นางสาว ภิญญา เคนวงบริบูรณ์ | P28: 1 | Q28: นางสาว ภิญญา เคนวงบริบูรณ์ | R28: 244688 | S28: 244688 | T28: I69A54NI0033958 | U28: 23078867 | V28: เศษสามชั้นสไลด์ | W28: 5 | X28: 5 | Y28: 5 | Z28: 5 | AA28: 0 | AB28: 0 | AC28: 0 | AD28: 0 | AE28: 5 | AF28: 5 | AI28: OPRCDCE17OPRCD00000OPRCDF213OPRCD00000OPRCD250 | AJ28: ซื้อ / ขาย | AK28: Main proudct | AL28: Bulk Normal | AM28: สุกร | AN28: 837 ตลาดสด/ตลาดนัด(CPFM) | AO28: TT | AU28: 2026-05-12-09.41.14.000000 | AV28: ก.ก. | AW28: ก.ก. | AY28: 0 | AZ28: N | BA28: 31788324 | BD28: 0 | BG28: 1333314600 | BH28: G | BI28: 5 | BJ28: 5 | BL28: TEERANUT.BOO
C29: 244688 | D29: 244688 | F29: CE17 | G29: TTCW3-ลพบุรี | H29: 0 | I29: หน่วยงานกลาง | J29: F213 DMCW-รชล-พระพุทธบาท | K29: 00000 หน่วยงานกลาง | L29: 250 | N29: 2000392491 | O29: นาย ชัยพร บุตรพรม | P29: 1 | Q29: นาย ชัยพร บุตรพรม | R29: 244688 | S29: 244688 | T29: I69A54NI0033963 | U29: 23057677 | V29: สามชั้นTT | W29: 7 | X29: 7 | Y29: 7 | Z29: 7 | AA29: 0 | AB29: 0 | AC29: 0 | AD29: 0 | AE29: 7 | AF29: 7 | AI29: OPRCDCE17OPRCD00000OPRCDF213OPRCD00000OPRCD250 | AJ29: ซื้อ / ขาย | AK29: Main proudct | AL29: Bulk Normal | AM29: สุกร | AN29: 837 ตลาดสด/ตลาดนัด(CPFM) | AO29: TT | AU29: 2026-05-12-09.45.51.000000 | AV29: ก.ก. | AW29: ก.ก. | AY29: 0 | AZ29: N | BA29: 31788675 | BD29: 0 | BG29: 1333314600 | BH29: G | BI29: 7 | BJ29: 7 | BK29: 1300 | BL29: TEERANUT.BOO
C30: 244688 | D30: 244688 | F30: CE17 | G30: TTCW3-ลพบุรี | H30: 0 | I30: หน่วยงานกลาง | J30: F213 DMCW-รชล-พระพุทธบาท | K30: 00000 หน่วยงานกลาง | L30: 250 | N30: 2000392491 | O30: นาย ชัยพร บุตรพรม | P30: 1 | Q30: นาย ชัยพร บุตรพรม | R30: 244688 | S30: 244688 | T30: I69A54NI0033963 | U30: 23105855 | V30: สะโพกหมู B2B (Basic) | W30: 1 | X30: 10 | Y30: 1 | Z30: 10 | AA30: 0 | AB30: 0 | AC30: 0 | AD30: 0 | AE30: 1 | AF30: 10 | AI30: OPRCDCE17OPRCD00000OPRCDF213OPRCD00000OPRCD250 | AJ30: ซื้อ / ขาย | AK30: Main proudct | AL30: Bulk Normal | AM30: สุกร | AN30: 837 ตลาดสด/ตลาดนัด(CPFM) | AO30: TT | AU30: 2026-05-12-09.45.51.000000 | AV30: ถุง | AW30: ก.ก. | AY30: 0 | AZ30: N | BA30: 31788675 | BD30: 0 | BG30: 1333314600 | BH30: G | BI30: 1 | BJ30: 10 | BK30: 1300 | BL30: TEERANUT.BOO
C31: 244688 | D31: 244688 | F31: CE17 | G31: TTCW3-ลพบุรี | H31: 0 | I31: หน่วยงานกลาง | J31: F213 DMCW-รชล-พระพุทธบาท | K31: 00000 หน่วยงานกลาง | L31: 250 | N31: 2000392491 | O31: นาย ชัยพร บุตรพรม | P31: 1 | Q31: นาย ชัยพร บุตรพรม | R31: 244688 | S31: 244688 | T31: I69A54NI0033963 | U31: 23057702 | V31: กระดูกอกTT | W31: 5 | X31: 5 | Y31: 5 | Z31: 5 | AA31: 0 | AB31: 0 | AC31: 0 | AD31: 0 | AE31: 5 | AF31: 5 | AI31: OPRCDCE17OPRCD00000OPRCDF213OPRCD00000OPRCD250 | AJ31: ซื้อ / ขาย | AK31: By proudct | AL31: Bulk Normal | AM31: สุกร | AN31: 837 ตลาดสด/ตลาดนัด(CPFM) | AO31: TT | AU31: 2026-05-12-09.45.51.000000 | AV31: ก.ก. | AW31: ก.ก. | AY31: 0 | AZ31: N | BA31: 31788675 | BD31: 0 | BG31: 1333314600 | BH31: G | BI31: 5 | BJ31: 5 | BK31: 1300 | BL31: TEERANUT.BOO
C32: 244688 | D32: 244688 | F32: CE17 | G32: TTCW3-ลพบุรี | H32: 0 | I32: หน่วยงานกลาง | J32: F213 DMCW-รชล-พระพุทธบาท | K32: 00000 หน่วยงานกลาง | L32: 250 | N32: 2000392491 | O32: นาย ชัยพร บุตรพรม | P32: 1 | Q32: นาย ชัยพร บุตรพรม | R32: 244688 | S32: 244688 | T32: I69A54NI0033963 | U32: 23057685 | V32: มันแข็งTT | W32: 10 | X32: 10 | Y32: 10 | Z32: 10 | AA32: 0 | AB32: 0 | AC32: 0 | AD32: 0 | AE32: 10 | AF32: 10 | AI32: OPRCDCE17OPRCD00000OPRCDF213OPRCD00000OPRCD250 | AJ32: ซื้อ / ขาย | AK32: By proudct | AL32: Bulk Normal | AM32: สุกร | AN32: 837 ตลาดสด/ตลาดนัด(CPFM) | AO32: TT | AU32: 2026-05-12-09.45.51.000000 | AV32: ก.ก. | AW32: ก.ก. | AY32: 0 | AZ32: N | BA32: 31788675 | BD32: 0 | BG32: 1333314600 | BH32: G | BI32: 10 | BJ32: 10 | BK32: 1300 | BL32: TEERANUT.BOO
C33: 244688 | D33: 244688 | F33: CE17 | G33: TTCW3-ลพบุรี | H33: 0 | I33: หน่วยงานกลาง | J33: F213 DMCW-รชล-พระพุทธบาท | K33: 00000 หน่วยงานกลาง | L33: 250 | N33: 2000392491 | O33: นาย ชัยพร บุตรพรม | P33: 1 | Q33: นาย ชัยพร บุตรพรม | R33: 244688 | S33: 244688 | T33: I69A54NI0033963 | U33: 23057698 | V33: หมูบดTT | W33: 10 | X33: 10 | Y33: 10 | Z33: 10 | AA33: 0 | AB33: 0 | AC33: 0 | AD33: 0 | AE33: 10 | AF33: 10 | AI33: OPRCDCE17OPRCD00000OPRCDF213OPRCD00000OPRCD250 | AJ33: ซื้อ / ขาย | AK33: Main proudct | AL33: Bulk Normal | AM33: สุกร | AN33: 837 ตลาดสด/ตลาดนัด(CPFM) | AO33: TT | AU33: 2026-05-12-09.45.51.000000 | AV33: ก.ก. | AW33: ก.ก. | AY33: 0 | AZ33: N | BA33: 31788675 | BD33: 0 | BG33: 1333314600 | BH33: G | BI33: 10 | BJ33: 10 | BK33: 1300 | BL33: TEERANUT.BOO
C34: 244688 | D34: 244688 | F34: CE17 | G34: TTCW3-ลพบุรี | H34: 0 | I34: หน่วยงานกลาง | J34: F213 DMCW-รชล-พระพุทธบาท | K34: 00000 หน่วยงานกลาง | L34: 250 | N34: 2000392491 | O34: นาย ชัยพร บุตรพรม | P34: 1 | Q34: นาย ชัยพร บุตรพรม | R34: 244688 | S34: 244688 | T34: I69A54NI0033963 | U34: 23105856 | V34: สันนอกหมู B2B (Basic) | W34: 1 | X34: 12 | Y34: 1 | Z34: 12 | AA34: 0 | AB34: 0 | AC34: 0 | AD34: 0 | AE34: 1 | AF34: 12 | AI34: OPRCDCE17OPRCD00000OPRCDF213OPRCD00000OPRCD250 | AJ34: ซื้อ / ขาย | AK34: Main proudct | AL34: Bulk Normal | AM34: สุกร | AN34: 837 ตลาดสด/ตลาดนัด(CPFM) | AO34: TT | AU34: 2026-05-12-09.45.51.000000 | AV34: ถุง | AW34: ก.ก. | AY34: 0 | AZ34: N | BA34: 31788675 | BD34: 0 | BG34: 1333314600 | BH34: G | BI34: 1 | BJ34: 12 | BK34: 1300 | BL34: TEERANUT.BOO
C35: 244688 | D35: 244688 | F35: CE17 | G35: TTCW3-ลพบุรี | H35: 0 | I35: หน่วยงานกลาง | J35: F213 DMCW-รชล-พระพุทธบาท | K35: 00000 หน่วยงานกลาง | L35: 250 | N35: 2000197240 | O35: นาย คมป่าน วิกรัยพัฒน์ | P35: 1 | Q35: นาย คมป่าน วิกรัยพัฒน์ | R35: 244688 | S35: 244688 | T35: I69A54NI0033964 | U35: 23106552 | V35: หมูชิ้นส่วน ไม่รวมหัวเครื่องใน (P) | W35: 3 | X35: 270 | Y35: 3 | Z35: 270 | AA35: 0 | AB35: 0 | AC35: 0 | AD35: 0 | AE35: 3 | AF35: 270 | AI35: OPRCDCE17OPRCD00000OPRCDF213OPRCD00000OPRCD250 | AJ35: ซื้อ / ขาย | AN35: 01 ขายเงินสด (POS) | AO35: TT | AU35: 2026-05-12-09.47.10.000000 | AV35: ตัว | AW35: ก.ก. | AY35: 0 | AZ35: N | BA35: 31788720 | BD35: 0 | BG35: 1333314600 | BH35: G | BI35: 3 | BJ35: 270 | BK35: 1300 | BL35: TEERANUT.BOO
C36: 244688 | D36: 244688 | F36: CE17 | G36: TTCW3-ลพบุรี | H36: 0 | I36: หน่วยงานกลาง | J36: F213 DMCW-รชล-พระพุทธบาท | K36: 00000 หน่วยงานกลาง | L36: 250 | N36: 2000339770 | O36: นางสาว เรณู กฤษบุญ | P36: 1 | Q36: เรณู | R36: 244688 | S36: 244688 | T36: I69A54NI0033965 | U36: 23057673 | V36: สะโพกTT | W36: 9 | X36: 9 | Y36: 9 | Z36: 9 | AA36: 0 | AB36: 0 | AC36: 0 | AD36: 0 | AE36: 9 | AF36: 9 | AI36: OPRCDCE17OPRCD00000OPRCDF213OPRCD00000OPRCD250 | AJ36: ซื้อ / ขาย | AK36: Main proudct | AL36: Bulk Normal | AM36: สุกร | AN36: 01 ขายเงินสด (POS) | AO36: TT | AU36: 2026-05-12-09.47.48.000000 | AV36: ก.ก. | AW36: ก.ก. | AY36: 0 | AZ36: N | BA36: 31788767 | BD36: 0 | BG36: 1333314600 | BH36: G | BI36: 9 | BJ36: 9 | BK36: 1300 | BL36: TEERANUT.BOO
C37: 244688 | D37: 244688 | F37: CE17 | G37: TTCW3-ลพบุรี | H37: 0 | I37: หน่วยงานกลาง | J37: F213 DMCW-รชล-พระพุทธบาท | K37: 00000 หน่วยงานกลาง | L37: 250 | N37: 2000339770 | O37: นางสาว เรณู กฤษบุญ | P37: 1 | Q37: เรณู | R37: 244688 | S37: 244688 | T37: I69A54NI0033965 | U37: 23057691 | V37: มันเปลวTT | W37: 5 | X37: 5 | Y37: 5 | Z37: 5 | AA37: 0 | AB37: 0 | AC37: 0 | AD37: 0 | AE37: 5 | AF37: 5 | AI37: OPRCDCE17OPRCD00000OPRCDF213OPRCD00000OPRCD250 | AJ37: ซื้อ / ขาย | AK37: By proudct | AL37: Bulk Normal | AM37: สุกร | AN37: 01 ขายเงินสด (POS) | AO37: TT | AU37: 2026-05-12-09.47.48.000000 | AV37: ก.ก. | AW37: ก.ก. | AY37: 0 | AZ37: N | BA37: 31788767 | BD37: 0 | BG37: 1333314600 | BH37: G | BI37: 5 | BJ37: 5 | BK37: 1300 | BL37: TEERANUT.BOO
C38: 244688 | D38: 244688 | F38: CE17 | G38: TTCW3-ลพบุรี | H38: 0 | I38: หน่วยงานกลาง | J38: F213 DMCW-รชล-พระพุทธบาท | K38: 00000 หน่วยงานกลาง | L38: 250 | N38: 2000339770 | O38: นางสาว เรณู กฤษบุญ | P38: 1 | Q38: เรณู | R38: 244688 | S38: 244688 | T38: I69A54NI0033965 | U38: 23000188 | V38: ตับหมู | W38: 10 | X38: 10 | Y38: 10 | Z38: 10 | AA38: 0 | AB38: 0 | AC38: 0 | AD38: 0 | AE38: 10 | AF38: 10 | AI38: OPRCDCE17OPRCD00000OPRCDF213OPRCD00000OPRCD250 | AJ38: ซื้อ / ขาย | AK38: By proudct | AL38: Bulk Normal | AM38: สุกร | AN38: 01 ขายเงินสด (POS) | AO38: TT | AU38: 2026-05-12-09.47.48.000000 | AV38: ก.ก. | AW38: ก.ก. | AY38: 0 | AZ38: N | BA38: 31788767 | BD38: 0 | BG38: 1333314600 | BH38: G | BI38: 10 | BJ38: 10 | BK38: 1300 | BL38: TEERANUT.BOO
C39: 244688 | D39: 244688 | F39: CE17 | G39: TTCW3-ลพบุรี | H39: 0 | I39: หน่วยงานกลาง | J39: F213 DMCW-รชล-พระพุทธบาท | K39: 00000 หน่วยงานกลาง | L39: 250 | N39: 2000404002 | O39: นางสาว สิรินภา ชนะประสพ | P39: 1 | Q39: นางสาว สิรินภา ชนะประสพ | R39: 244688 | S39: 244688 | T39: I69A54NI0033967 | U39: 23057700 | V39: ซี่โครงTT | W39: 5 | X39: 5 | Y39: 5 | Z39: 5 | AA39: 0 | AB39: 0 | AC39: 0 | AD39: 0 | AE39: 5 | AF39: 5 | AI39: OPRCDCE17OPRCD00000OPRCDF213OPRCD00000OPRCD250 | AJ39: ซื้อ / ขาย | AK39: Main proudct | AL39: Bulk Normal | AM39: สุกร | AN39: 837 ตลาดสด/ตลาดนัด(CPFM) | AO39: TT | AU39: 2026-05-12-09.48.39.000000 | AV39: ก.ก. | AW39: ก.ก. | AY39: 0 | AZ39: N | BA39: 31788838 | BD39: 0 | BG39: 1333314600 | BH39: G | BI39: 5 | BJ39: 5 | BK39: 1300 | BL39: TEERANUT.BOO
C40: 244688 | D40: 244688 | F40: CE17 | G40: TTCW3-ลพบุรี | H40: 0 | I40: หน่วยงานกลาง | J40: F213 DMCW-รชล-พระพุทธบาท | K40: 00000 หน่วยงานกลาง | L40: 250 | N40: 2000404002 | O40: นางสาว สิรินภา ชนะประสพ | P40: 1 | Q40: นางสาว สิรินภา ชนะประสพ | R40: 244688 | S40: 244688 | T40: I69A54NI0033967 | U40: 23057698 | V40: หมูบดTT | W40: 5 | X40: 5 | Y40: 5 | Z40: 5 | AA40: 0 | AB40: 0 | AC40: 0 | AD40: 0 | AE40: 5 | AF40: 5 | AI40: OPRCDCE17OPRCD00000OPRCDF213OPRCD00000OPRCD250 | AJ40: ซื้อ / ขาย | AK40: Main proudct | AL40: Bulk Normal | AM40: สุกร | AN40: 837 ตลาดสด/ตลาดนัด(CPFM) | AO40: TT | AU40: 2026-05-12-09.48.39.000000 | AV40: ก.ก. | AW40: ก.ก. | AY40: 0 | AZ40: N | BA40: 31788838 | BD40: 0 | BG40: 1333314600 | BH40: G | BI40: 5 | BJ40: 5 | BK40: 1300 | BL40: TEERANUT.BOO
...

Sheet LOTUS 11.00

Sheet LOTUS 12.00

Sheet LOTUS 13.00
A1: บมจ. ซีพีเอฟ โกลบอล ฟู้ด โซลูชั่น
A2: rDate1 | B2: rDate2 | C2: rRDate1 | D2: rRDate2 | E2: rRDate3 | F2: rOper_code | G2: rOper_name | H2: rSub_oper | I2: rSub_name | J2: rWarehouse | K2: rSub_warehouse | L2: rBst_code | M2: rBst_name | N2: rCv_code | O2: rCv_name | P2: rShip_to | Q2: rShip_name | R2: rDoc_date | S2: rReq_date | T2: rDoc_number | U2: rProduct_code | V2: rProduct_name | W2: rStock_qty | X2: rStock_wgt | Y2: rPlan_qty | Z2: rPlan_wgt | AA2: rDiff_stock_qty_plan | AB2: rDiff_stock_wgt_plan | AC2: rAllocate_stock_qty | AD2: rAllocate_stock_wgt | AE2: rDiff_stock_qty | AF2: rDiff_stock_wgt | AG2: rPlan_byquota_qty | AH2: rPlan_byquota_wgt | AI2: rBreak | AJ2: rEntry_type | AK2: rProduct_group_code1 | AL2: rProduct_group_code2 | AM2: rProduct_group_dim1 | AN2: rCv_channel | AO2: rCV_FLAG1 | AP2: rCV_FLAG2 | AQ2: rCV_FLAG3 | AR2: rCV_FLAG4 | AS2: rCV_FLAG5 | AT2: rOwner_so | AU2: rCreate_date_so | AV2: rUm_stock_qty | AW2: rUm_stock_wgt | AX2: rArea | AY2: nShow_area | AZ2: rModel | BA2: rPO_no | BB2: rDO_no | BC2: rINV_no | BD2: rDoc_issue | BE2: rPlant_code | BF2: rAllocate_remark | BG2: rVendor_code | BH2: rStatus | BI2: rStock_qty_pur | BJ2: rStock_wgt_pur | BK2: rCut_off_time | BL2: rOwner_create | BM2: rCo_load | BN2: rLicense_plate
C3: 244482 | D3: 244482 | F3: 489 | G3: Modern Trade | H3: 23 | I3: MT Term 30-2 | J3: F213 DMCW-รชล-พระพุทธบาท | K3: 00000 หน่วยงานกลาง | L3: 923 | N3: 1A532857L0 | O3: บมจ. ซีพี แอ็กซ์ตร้า ลำนารายณ์ (5188) | P3: 1 | Q3: ลำนารายณ์ (5188) | R3: 244480 | S3: 244482 | T3: H6954RLG0901153 | U3: 23025552 | V3: หมูบดอนามัยซีพี 500 กรัม | W3: 1 | X3: 0.5 | Y3: 1 | Z3: 0.5 | AA3: 0 | AB3: 0 | AC3: 0 | AD3: 0 | AE3: 1 | AF3: 0.5 | AI3: OPRCD0489OPRCD00023OPRCDF213OPRCD00000OPRCD923 | AJ3: ซื้อ / ขาย | AK3: Main proudct | AL3: CP Brand(ซอง) | AM3: สุกร | AN3: MT1001 HYPER-Lotus | AO3: MT | AP3: 10 | AQ3: 1 | AT3: System Batch | AU3: 2026-05-11-09.40.55.000000 | AV3: แพ็ค | AW3: ก.ก. | AY3: 0 | AZ3: N | BA3: 1196840851148 | BD3: 1 | BF3: ;Delivery S | BG3: 1333314600 | BH3: G | BI3: 1 | BJ3: 0.5 | BL3: INTERFACE
C4: 244482 | D4: 244482 | F4: 489 | G4: Modern Trade | H4: 23 | I4: MT Term 30-2 | J4: F213 DMCW-รชล-พระพุทธบาท | K4: 00000 หน่วยงานกลาง | L4: 923 | N4: 1A532857L0 | O4: บมจ. ซีพี แอ็กซ์ตร้า ลำนารายณ์ (5188) | P4: 1 | Q4: ลำนารายณ์ (5188) | R4: 244480 | S4: 244482 | T4: H6954RLG0901153 | U4: 23026834 | V4: สันคอหมูสไลซ์อนามัยซีพี 1000 กรัม | W4: 5 | X4: 5 | Y4: 5 | Z4: 5 | AA4: 0 | AB4: 0 | AC4: 0 | AD4: 0 | AE4: 5 | AF4: 5 | AI4: OPRCD0489OPRCD00023OPRCDF213OPRCD00000OPRCD923 | AJ4: ซื้อ / ขาย | AK4: Main proudct | AL4: CP Brand(ซอง) | AM4: สุกร | AN4: MT1001 HYPER-Lotus | AO4: MT | AP4: 10 | AQ4: 1 | AT4: System Batch | AU4: 2026-05-11-09.40.55.000000 | AV4: แพ็ค | AW4: ก.ก. | AY4: 0 | AZ4: N | BA4: 1196840851148 | BD4: 1 | BF4: ;Delivery S | BG4: 1333314600 | BH4: G | BI4: 5 | BJ4: 5 | BL4: INTERFACE
C5: 244482 | D5: 244482 | F5: 489 | G5: Modern Trade | H5: 23 | I5: MT Term 30-2 | J5: F213 DMCW-รชล-พระพุทธบาท | K5: 00000 หน่วยงานกลาง | L5: 923 | N5: 1A532857L0 | O5: บมจ. ซีพี แอ็กซ์ตร้า ลำนารายณ์ (5188) | P5: 1 | Q5: ลำนารายณ์ (5188) | R5: 244480 | S5: 244482 | T5: H6954RLG0901153 | U5: 23028092 | V5: หมูสามชั้นสไลซ์อนามัยซีพี 500 กรัม | W5: 1 | X5: 0.5 | Y5: 1 | Z5: 0.5 | AA5: 0 | AB5: 0 | AC5: 0 | AD5: 0 | AE5: 1 | AF5: 0.5 | AI5: OPRCD0489OPRCD00023OPRCDF213OPRCD00000OPRCD923 | AJ5: ซื้อ / ขาย | AK5: Main proudct | AL5: CP Brand(ซอง) | AM5: สุกร | AN5: MT1001 HYPER-Lotus | AO5: MT | AP5: 10 | AQ5: 1 | AT5: System Batch | AU5: 2026-05-11-09.40.55.000000 | AV5: แพ็ค | AW5: ก.ก. | AY5: 0 | AZ5: N | BA5: 1196840851148 | BD5: 1 | BF5: ;Delivery S | BG5: 1333314600 | BH5: G | BI5: 1 | BJ5: 0.5 | BL5: INTERFACE
C6: 244482 | D6: 244482 | F6: 489 | G6: Modern Trade | H6: 23 | I6: MT Term 30-2 | J6: F213 DMCW-รชล-พระพุทธบาท | K6: 00000 หน่วยงานกลาง | L6: 923 | N6: 1A530181L0 | O6: บมจ. ซีพี แอ็กซ์ตร้า สระบุรี (5005) | P6: 1 | Q6: LOTUS สระบุรี (5005) | R6: 244480 | S6: 244482 | T6: H6954RLG0901180 | U6: 23028088 | V6: สันคอหมูสไลซ์อนามัยซีพี 500 กรัม | W6: 3 | X6: 1.5 | Y6: 3 | Z6: 1.5 | AA6: 0 | AB6: 0 | AC6: 0 | AD6: 0 | AE6: 3 | AF6: 1.5 | AI6: OPRCD0489OPRCD00023OPRCDF213OPRCD00000OPRCD923 | AJ6: ซื้อ / ขาย | AK6: Main proudct | AL6: CP Brand(ซอง) | AM6: สุกร | AN6: MT1001 HYPER-Lotus | AO6: MT | AP6: 10 | AQ6: 1 | AT6: System Batch | AU6: 2026-05-11-09.40.55.000000 | AV6: แพ็ค | AW6: ก.ก. | AY6: 0 | AZ6: N | BA6: 1196840854124 | BD6: 1 | BF6: ;Delivery S | BG6: 1333314600 | BH6: G | BI6: 3 | BJ6: 1.5 | BK6: 1300 | BL6: INTERFACE
C7: 244482 | D7: 244482 | F7: 489 | G7: Modern Trade | H7: 23 | I7: MT Term 30-2 | J7: F213 DMCW-รชล-พระพุทธบาท | K7: 00000 หน่วยงานกลาง | L7: 923 | N7: 1A530181L0 | O7: บมจ. ซีพี แอ็กซ์ตร้า สระบุรี (5005) | P7: 1 | Q7: LOTUS สระบุรี (5005) | R7: 244480 | S7: 244482 | T7: H6954RLG0901180 | U7: 23109359 | V7: หมูชีวาบด (ตรา ยูฟาร์ม) 400 กรัม | W7: 12 | X7: 4.8 | Y7: 12 | Z7: 4.8 | AA7: 0 | AB7: 0 | AC7: 0 | AD7: 0 | AE7: 12 | AF7: 4.8 | AI7: OPRCD0489OPRCD00023OPRCDF213OPRCD00000OPRCD923 | AJ7: ซื้อ / ขาย | AK7: Main proudct | AL7: Seal Pack | AM7: สุกร | AN7: MT1001 HYPER-Lotus | AO7: MT | AP7: 10 | AQ7: 1 | AT7: System Batch | AU7: 2026-05-11-09.40.55.000000 | AV7: แพ็ค | AW7: ก.ก. | AY7: 0 | AZ7: N | BA7: 1196840854124 | BD7: 1 | BF7: ;Delivery S | BG7: 1333314600 | BH7: G | BI7: 12 | BJ7: 4.8 | BK7: 1300 | BL7: INTERFACE
C8: 244482 | D8: 244482 | F8: 489 | G8: Modern Trade | H8: 23 | I8: MT Term 30-2 | J8: F213 DMCW-รชล-พระพุทธบาท | K8: 00000 หน่วยงานกลาง | L8: 923 | N8: 1A530181L0 | O8: บมจ. ซีพี แอ็กซ์ตร้า สระบุรี (5005) | P8: 1 | Q8: LOTUS สระบุรี (5005) | R8: 244480 | S8: 244482 | T8: H6954RLG0901180 | U8: 23109353 | V8: สันคอหมูชีวาสไลซ์(ตรา ยูฟาร์ม) 250 กรัม | W8: 8 | X8: 2 | Y8: 8 | Z8: 2 | AA8: 0 | AB8: 0 | AC8: 0 | AD8: 0 | AE8: 8 | AF8: 2 | AI8: OPRCD0489OPRCD00023OPRCDF213OPRCD00000OPRCD923 | AJ8: ซื้อ / ขาย | AK8: Main proudct | AL8: Seal Pack | AM8: สุกร | AN8: MT1001 HYPER-Lotus | AO8: MT | AP8: 10 | AQ8: 1 | AT8: System Batch | AU8: 2026-05-11-09.40.55.000000 | AV8: แพ็ค | AW8: ก.ก. | AY8: 0 | AZ8: N | BA8: 1196840854124 | BD8: 1 | BF8: ;Delivery S | BG8: 1333314600 | BH8: G | BI8: 8 | BJ8: 2 | BK8: 1300 | BL8: INTERFACE
C9: 244482 | D9: 244482 | F9: 489 | G9: Modern Trade | H9: 23 | I9: MT Term 30-2 | J9: F213 DMCW-รชล-พระพุทธบาท | K9: 00000 หน่วยงานกลาง | L9: 923 | N9: 1A530181L0 | O9: บมจ. ซีพี แอ็กซ์ตร้า สระบุรี (5005) | P9: 1 | Q9: LOTUS สระบุรี (5005) | R9: 244480 | S9: 244482 | T9: H6954RLG0901180 | U9: 23025552 | V9: หมูบดอนามัยซีพี 500 กรัม | W9: 3 | X9: 1.5 | Y9: 3 | Z9: 1.5 | AA9: 0 | AB9: 0 | AC9: 0 | AD9: 0 | AE9: 3 | AF9: 1.5 | AI9: OPRCD0489OPRCD00023OPRCDF213OPRCD00000OPRCD923 | AJ9: ซื้อ / ขาย | AK9: Main proudct | AL9: CP Brand(ซอง) | AM9: สุกร | AN9: MT1001 HYPER-Lotus | AO9: MT | AP9: 10 | AQ9: 1 | AT9: System Batch | AU9: 2026-05-11-09.40.55.000000 | AV9: แพ็ค | AW9: ก.ก. | AY9: 0 | AZ9: N | BA9: 1196840854124 | BD9: 1 | BF9: ;Delivery S | BG9: 1333314600 | BH9: G | BI9: 3 | BJ9: 1.5 | BK9: 1300 | BL9: INTERFACE
C10: 244482 | D10: 244482 | F10: 489 | G10: Modern Trade | H10: 23 | I10: MT Term 30-2 | J10: F213 DMCW-รชล-พระพุทธบาท | K10: 00000 หน่วยงานกลาง | L10: 923 | N10: 1A530181L0 | O10: บมจ. ซีพี แอ็กซ์ตร้า สระบุรี (5005) | P10: 1 | Q10: LOTUS สระบุรี (5005) | R10: 244480 | S10: 244482 | T10: H6954RLG0901180 | U10: 23109351 | V10: สามชั้นหมูชีวาสไลซ์(ตรา ยูฟาร์ม)250 กรัม | W10: 4 | X10: 1 | Y10: 4 | Z10: 1 | AA10: 0 | AB10: 0 | AC10: 0 | AD10: 0 | AE10: 4 | AF10: 1 | AI10: OPRCD0489OPRCD00023OPRCDF213OPRCD00000OPRCD923 | AJ10: ซื้อ / ขาย | AK10: Main proudct | AL10: Seal Pack | AM10: สุกร | AN10: MT1001 HYPER-Lotus | AO10: MT | AP10: 10 | AQ10: 1 | AT10: System Batch | AU10: 2026-05-11-09.40.55.000000 | AV10: แพ็ค | AW10: ก.ก. | AY10: 0 | AZ10: N | BA10: 1196840854124 | BD10: 1 | BF10: ;Delivery S | BG10: 1333314600 | BH10: G | BI10: 4 | BJ10: 1 | BK10: 1300 | BL10: INTERFACE
C11: 244482 | D11: 244482 | F11: 489 | G11: Modern Trade | H11: 23 | I11: MT Term 30-2 | J11: F213 DMCW-รชล-พระพุทธบาท | K11: 00000 หน่วยงานกลาง | L11: 923 | N11: 1A530181L0 | O11: บมจ. ซีพี แอ็กซ์ตร้า สระบุรี (5005) | P11: 1 | Q11: LOTUS สระบุรี (5005) | R11: 244480 | S11: 244482 | T11: H6954RLG0901180 | U11: 23109352 | V11: สันนอกหมูชีวาสไลซ์(ตรา ยูฟาร์ม) 250 กรัม | W11: 8 | X11: 2 | Y11: 8 | Z11: 2 | AA11: 0 | AB11: 0 | AC11: 0 | AD11: 0 | AE11: 8 | AF11: 2 | AI11: OPRCD0489OPRCD00023OPRCDF213OPRCD00000OPRCD923 | AJ11: ซื้อ / ขาย | AK11: Main proudct | AL11: Seal Pack | AM11: สุกร | AN11: MT1001 HYPER-Lotus | AO11: MT | AP11: 10 | AQ11: 1 | AT11: System Batch | AU11: 2026-05-11-09.40.55.000000 | AV11: แพ็ค | AW11: ก.ก. | AY11: 0 | AZ11: N | BA11: 1196840854124 | BD11: 1 | BF11: ;Delivery S | BG11: 1333314600 | BH11: G | BI11: 8 | BJ11: 2 | BK11: 1300 | BL11: INTERFACE
C12: 244482 | D12: 244482 | F12: 489 | G12: Modern Trade | H12: 23 | I12: MT Term 30-2 | J12: F213 DMCW-รชล-พระพุทธบาท | K12: 00000 หน่วยงานกลาง | L12: 923 | N12: 1A530181L0 | O12: บมจ. ซีพี แอ็กซ์ตร้า สระบุรี (5005) | P12: 1 | Q12: LOTUS สระบุรี (5005) | R12: 244480 | S12: 244482 | T12: H6954RLG0901180 | U12: 23028092 | V12: หมูสามชั้นสไลซ์อนามัยซีพี 500 กรัม | W12: 3 | X12: 1.5 | Y12: 3 | Z12: 1.5 | AA12: 0 | AB12: 0 | AC12: 0 | AD12: 0 | AE12: 3 | AF12: 1.5 | AI12: OPRCD0489OPRCD00023OPRCDF213OPRCD00000OPRCD923 | AJ12: ซื้อ / ขาย | AK12: Main proudct | AL12: CP Brand(ซอง) | AM12: สุกร | AN12: MT1001 HYPER-Lotus | AO12: MT | AP12: 10 | AQ12: 1 | AT12: System Batch | AU12: 2026-05-11-09.40.55.000000 | AV12: แพ็ค | AW12: ก.ก. | AY12: 0 | AZ12: N | BA12: 1196840854124 | BD12: 1 | BF12: ;Delivery S | BG12: 1333314600 | BH12: G | BI12: 3 | BJ12: 1.5 | BK12: 1300 | BL12: INTERFACE
C13: 244482 | D13: 244482 | F13: 489 | G13: Modern Trade | H13: 23 | I13: MT Term 30-2 | J13: F213 DMCW-รชล-พระพุทธบาท | K13: 00000 หน่วยงานกลาง | L13: 923 | N13: 1A530181L0 | O13: บมจ. ซีพี แอ็กซ์ตร้า สระบุรี (5005) | P13: 1 | Q13: LOTUS สระบุรี (5005) | R13: 244480 | S13: 244482 | T13: H6954RLG0901180 | U13: 23028090 | V13: สันนอกหมูสไลซ์อนามัยซีพี 500 กรัม | W13: 2 | X13: 1 | Y13: 2 | Z13: 1 | AA13: 0 | AB13: 0 | AC13: 0 | AD13: 0 | AE13: 2 | AF13: 1 | AI13: OPRCD0489OPRCD00023OPRCDF213OPRCD00000OPRCD923 | AJ13: ซื้อ / ขาย | AK13: Main proudct | AL13: CP Brand(ซอง) | AM13: สุกร | AN13: MT1001 HYPER-Lotus | AO13: MT | AP13: 10 | AQ13: 1 | AT13: System Batch | AU13: 2026-05-11-09.40.55.000000 | AV13: แพ็ค | AW13: ก.ก. | AY13: 0 | AZ13: N | BA13: 1196840854124 | BD13: 1 | BF13: ;Delivery S | BG13: 1333314600 | BH13: G | BI13: 2 | BJ13: 1 | BK13: 1300 | BL13: INTERFACE
C14: 244482 | D14: 244482 | F14: 489 | G14: Modern Trade | H14: 23 | I14: MT Term 30-2 | J14: F213 DMCW-รชล-พระพุทธบาท | K14: 00000 หน่วยงานกลาง | L14: 923 | N14: 1A532209L0 | O14: บมจ. ซีพี แอ็กซ์ตร้า คงธรรม (4044) | P14: 1 | Q14: LOTUS คงธรรม (4044) | R14: 244481 | S14: 244482 | T14: H6954RLG0909048 | U14: 23000186 | V14: ขั้วตับหมู | W14: 2 | X14: 2 | Y14: 2 | Z14: 2 | AA14: 0 | AB14: 0 | AC14: 0 | AD14: 0 | AE14: 2 | AF14: 2 | AI14: OPRCD0489OPRCD00023OPRCDF213OPRCD00000OPRCD923 | AJ14: ซื้อ / ขาย | AK14: By proudct | AL14: Bulk Normal | AM14: สุกร | AN14: MT1001 HYPER-Lotus | AO14: MT | AP14: 10 | AQ14: 1 | AT14: System Batch | AU14: 2026-05-12-09.40.40.000000 | AV14: ก.ก. | AW14: ก.ก. | AY14: 0 | AZ14: N | BA14: 1179740873360 | BD14: 1 | BF14: ;Delivery S | BG14: 1333314600 | BH14: G | BI14: 2 | BJ14: 2 | BK14: 1300 | BL14: INTERFACE
C15: 244482 | D15: 244482 | F15: 489 | G15: Modern Trade | H15: 23 | I15: MT Term 30-2 | J15: F213 DMCW-รชล-พระพุทธบาท | K15: 00000 หน่วยงานกลาง | L15: 923 | N15: 1A530439L0 | O15: บมจ. ซีพี แอ็กซ์ตร้า ลพบุรี อินน์ (5057) | P15: 1 | Q15: LOTUS ลพบุรี อินน์ (5057) | R15: 244481 | S15: 244482 | T15: H6954RLG0909049 | U15: 23000191 | V15: ไส้อ่อน | W15: 2 | X15: 2 | Y15: 2 | Z15: 2 | AA15: 0 | AB15: 0 | AC15: 0 | AD15: 0 | AE15: 2 | AF15: 2 | AI15: OPRCD0489OPRCD00023OPRCDF213OPRCD00000OPRCD923 | AJ15: ซื้อ / ขาย | AK15: By proudct | AL15: Bulk Normal | AM15: สุกร | AN15: MT1001 HYPER-Lotus | AO15: MT | AP15: 10 | AQ15: 1 | AT15: System Batch | AU15: 2026-05-12-09.40.40.000000 | AV15: ก.ก. | AW15: ก.ก. | AY15: 0 | AZ15: N | BA15: 1179740877377 | BD15: 1 | BF15: ;Delivery S | BG15: 1333314600 | BH15: G | BI15: 2 | BJ15: 2 | BK15: 1300 | BL15: INTERFACE
C16: 244482 | D16: 244482 | F16: 489 | G16: Modern Trade | H16: 23 | I16: MT Term 30-2 | J16: F213 DMCW-รชล-พระพุทธบาท | K16: 00000 หน่วยงานกลาง | L16: 923 | N16: 1A530439L0 | O16: บมจ. ซีพี แอ็กซ์ตร้า ลพบุรี อินน์ (5057) | P16: 1 | Q16: LOTUS ลพบุรี อินน์ (5057) | R16: 244481 | S16: 244482 | T16: H6954RLG0909049 | U16: 23000188 | V16: ตับหมู | W16: 2 | X16: 2 | Y16: 2 | Z16: 2 | AA16: 0 | AB16: 0 | AC16: 0 | AD16: 0 | AE16: 2 | AF16: 2 | AI16: OPRCD0489OPRCD00023OPRCDF213OPRCD00000OPRCD923 | AJ16: ซื้อ / ขาย | AK16: By proudct | AL16: Bulk Normal | AM16: สุกร | AN16: MT1001 HYPER-Lotus | AO16: MT | AP16: 10 | AQ16: 1 | AT16: System Batch | AU16: 2026-05-12-09.40.40.000000 | AV16: ก.ก. | AW16: ก.ก. | AY16: 0 | AZ16: N | BA16: 1179740877377 | BD16: 1 | BF16: ;Delivery S | BG16: 1333314600 | BH16: G | BI16: 2 | BJ16: 2 | BK16: 1300 | BL16: INTERFACE
C17: 244482 | D17: 244482 | F17: 489 | G17: Modern Trade | H17: 23 | I17: MT Term 30-2 | J17: F213 DMCW-รชล-พระพุทธบาท | K17: 00000 หน่วยงานกลาง | L17: 923 | N17: 1A530491L0 | O17: บมจ. ซีพี แอ็กซ์ตร้า อุตสาหกรรมวังน้อย (1613) | P17: 1 | Q17: LOTUS อุตสาหกรรมวังน้อย (1613) | R17: 244481 | S17: 244482 | T17: H6954RLG0914051 | U17: 23086968 | V17: สามชั้นตัดเส้น SIS กก.ละ | W17: 6 | X17: 6 | Y17: 6 | Z17: 6 | AA17: 0 | AB17: 0 | AC17: 0 | AD17: 0 | AE17: 6 | AF17: 6 | AI17: OPRCD0489OPRCD00023OPRCDF213OPRCD00000OPRCD923 | AJ17: ซื้อ / ขาย | AK17: Main proudct | AL17: Bulk Normal | AM17: สุกร | AN17: MT1001 HYPER-Lotus | AO17: MT | AP17: 10 | AQ17: 1 | AT17: System Batch | AU17: 2026-05-12-12.11.25.000000 | AV17: ก.ก. | AW17: ก.ก. | AY17: 0 | AZ17: N | BA17: 1179740890338 | BD17: 1 | BF17: ;INCLUDE_We | BG17: 1333314600 | BH17: G | BI17: 6 | BJ17: 6 | BK17: 1300 | BL17: INTERFACE
... C42: 244482 | D42: 244482 | F42: 489 | G42: Modern Trade | H42: 23 | I42: MT Term 30-2 | J42: F213 DMCW-รชล-พระพุทธบาท | K42: 00000 หน่วยงานกลาง | L42: 923 | N42: 1A530811L0 | O42: บมจ. ซีพี แอ็กซ์ตร้า โคกสำโรง (1937) | P42: 1 | Q42: LOTUS โคกสำโรง (1937) | R42: 244481 | S42: 244482 | T42: H6954RLG0914054 | U42: 23090975 | V42: สามชั้นสไลซ์ SIS กก.ละ | W42: 3 | X42: 3 | Y42: 3 | Z42: 3 | AA42: 0 | AB42: 0 | AC42: 0 | AD42: 0 | AE42: 3 | AF42: 3 | AI42: OPRCD0489OPRCD00023OPRCDF213OPRCD00000OPRCD923 | AJ42: ซื้อ / ขาย | AK42: Main proudct | AL42: Bulk Normal | AM42: สุกร | AN42: MT1001 HYPER-Lotus | AO42: MT | AP42: 10 | AQ42: 1 | AT42: System Batch | AU42: 2026-05-12-12.11.25.000000 | AV42: ก.ก. | AW42: ก.ก. | AY42: 0 | AZ42: N | BA42: 1179740890350 | BD42: 1 | BF42: ;INCLUDE_We | BG42: 1333314600 | BH42: G | BI42: 3 | BJ42: 3 | BK42: 1300 | BL42: INTERFACE
C43: 244482 | D43: 244482 | F43: 489 | G43: Modern Trade | H43: 23 | I43: MT Term 30-2 | J43: F213 DMCW-รชล-พระพุทธบาท | K43: 00000 หน่วยงานกลาง | L43: 923 | N43: 1A531845L0 | O43: บมจ. ซีพี แอ็กซ์ตร้า พีเอ็มที โรจนะ (3095) | P43: 1 | Q43: LOTUS พีเอ็มที โรจนะ (3095) | R43: 244481 | S43: 244482 | T43: H6954RLG0914058 | U43: 23039556 | V43: หมูบดปนมัน 30 % | W43: 1 | X43: 5 | Y43: 1 | Z43: 5 | AA43: 0 | AB43: 0 | AC43: 0 | AD43: 0 | AE43: 1 | AF43: 5 | AI43: OPRCD0489OPRCD00023OPRCDF213OPRCD00000OPRCD923 | AJ43: ซื้อ / ขาย | AK43: Main proudct | AL43: Bulk Normal | AM43: สุกร | AN43: MT1001 HYPER-Lotus | AO43: MT | AP43: 10 | AQ43: 1 | AT43: System Batch | AU43: 2026-05-12-12.11.25.000000 | AV43: ถุง | AW43: ก.ก. | AY43: 0 | AZ43: N | BA43: 1179740890381 | BD43: 1 | BF43: ;INCLUDE_We | BG43: 1333314600 | BH43: G | BI43: 1 | BJ43: 5 | BL43: INTERFACE
C44: 244482 | D44: 244482 | F44: 489 | G44: Modern Trade | H44: 23 | I44: MT Term 30-2 | J44: F213 DMCW-รชล-พระพุทธบาท | K44: 00000 หน่วยงานกลาง | L44: 923 | N44: 1A531845L0 | O44: บมจ. ซีพี แอ็กซ์ตร้า พีเอ็มที โรจนะ (3095) | P44: 1 | Q44: LOTUS พีเอ็มที โรจนะ (3095) | R44: 244481 | S44: 244482 | T44: H6954RLG0914058 | U44: 23090967 | V44: กระดูกซุป SIS กก.ละ | W44: 3 | X44: 3 | Y44: 3 | Z44: 3 | AA44: 0 | AB44: 0 | AC44: 0 | AD44: 0 | AE44: 3 | AF44: 3 | AI44: OPRCD0489OPRCD00023OPRCDF213OPRCD00000OPRCD923 | AJ44: ซื้อ / ขาย | AK44: By proudct | AL44: Bulk Normal | AM44: สุกร | AN44: MT1001 HYPER-Lotus | AO44: MT | AP44: 10 | AQ44: 1 | AT44: System Batch | AU44: 2026-05-12-12.11.25.000000 | AV44: ก.ก. | AW44: ก.ก. | AY44: 0 | AZ44: N | BA44: 1179740890381 | BD44: 1 | BF44: ;INCLUDE_We | BG44: 1333314600 | BH44: G | BI44: 3 | BJ44: 3 | BL44: INTERFACE
C45: 244482 | D45: 244482 | F45: 489 | G45: Modern Trade | H45: 23 | I45: MT Term 30-2 | J45: F213 DMCW-รชล-พระพุทธบาท | K45: 00000 หน่วยงานกลาง | L45: 923 | N45: 1A531845L0 | O45: บมจ. ซีพี แอ็กซ์ตร้า พีเอ็มที โรจนะ (3095) | P45: 1 | Q45: LOTUS พีเอ็มที โรจนะ (3095) | R45: 244481 | S45: 244482 | T45: H6954RLG0914058 | U45: 23086968 | V45: สามชั้นตัดเส้น SIS กก.ละ | W45: 3 | X45: 3 | Y45: 3 | Z45: 3 | AA45: 0 | AB45: 0 | AC45: 0 | AD45: 0 | AE45: 3 | AF45: 3 | AI45: OPRCD0489OPRCD00023OPRCDF213OPRCD00000OPRCD923 | AJ45: ซื้อ / ขาย | AK45: Main proudct | AL45: Bulk Normal | AM45: สุกร | AN45: MT1001 HYPER-Lotus | AO45: MT | AP45: 10 | AQ45: 1 | AT45: System Batch | AU45: 2026-05-12-12.11.25.000000 | AV45: ก.ก. | AW45: ก.ก. | AY45: 0 | AZ45: N | BA45: 1179740890381 | BD45: 1 | BF45: ;INCLUDE_We | BG45: 1333314600 | BH45: G | BI45: 3 | BJ45: 3 | BL45: INTERFACE
C46: 244482 | D46: 244482 | F46: 489 | G46: Modern Trade | H46: 23 | I46: MT Term 30-2 | J46: F213 DMCW-รชล-พระพุทธบาท | K46: 00000 หน่วยงานกลาง | L46: 923 | N46: 1A531845L0 | O46: บมจ. ซีพี แอ็กซ์ตร้า พีเอ็มที โรจนะ (3095) | P46: 1 | Q46: LOTUS พีเอ็มที โรจนะ (3095) | R46: 244481 | S46: 244482 | T46: H6954RLG0914058 | U46: 23095547 | V46: เนื้อหมูหั่นชิ้น (SIS) กก. ละ | W46: 3 | X46: 3 | Y46: 3 | Z46: 3 | AA46: 0 | AB46: 0 | AC46: 0 | AD46: 0 | AE46: 3 | AF46: 3 | AI46: OPRCD0489OPRCD00023OPRCDF213OPRCD00000OPRCD923 | AJ46: ซื้อ / ขาย | AK46: Main proudct | AL46: Bulk Normal | AM46: สุกร | AN46: MT1001 HYPER-Lotus | AO46: MT | AP46: 10 | AQ46: 1 | AT46: System Batch | AU46: 2026-05-12-12.11.25.000000 | AV46: ก.ก. | AW46: ก.ก. | AY46: 0 | AZ46: N | BA46: 1179740890381 | BD46: 1 | BF46: ;INCLUDE_We | BG46: 1333314600 | BH46: G | BI46: 3 | BJ46: 3 | BL46: INTERFACE
C47: 244482 | D47: 244482 | F47: 489 | G47: Modern Trade | H47: 23 | I47: MT Term 30-2 | J47: F213 DMCW-รชล-พระพุทธบาท | K47: 00000 หน่วยงานกลาง | L47: 923 | N47: 1A531845L0 | O47: บมจ. ซีพี แอ็กซ์ตร้า พีเอ็มที โรจนะ (3095) | P47: 1 | Q47: LOTUS พีเอ็มที โรจนะ (3095) | R47: 244481 | S47: 244482 | T47: H6954RLG0914058 | U47: 23086969 | V47: ซี่โครงแข็งตัดเส้น 2 นิ้ว SIS กก.ละ | W47: 3 | X47: 3 | Y47: 3 | Z47: 3 | AA47: 0 | AB47: 0 | AC47: 0 | AD47: 0 | AE47: 3 | AF47: 3 | AI47: OPRCD0489OPRCD00023OPRCDF213OPRCD00000OPRCD923 | AJ47: ซื้อ / ขาย | AK47: Main proudct | AL47: Bulk Normal | AM47: สุกร | AN47: MT1001 HYPER-Lotus | AO47: MT | AP47: 10 | AQ47: 1 | AT47: System Batch | AU47: 2026-05-12-12.11.25.000000 | AV47: ก.ก. | AW47: ก.ก. | AY47: 0 | AZ47: N | BA47: 1179740890381 | BD47: 1 | BF47: ;INCLUDE_We | BG47: 1333314600 | BH47: G | BI47: 3 | BJ47: 3 | BL47: INTERFACE
C48: 244482 | D48: 244482 | F48: 489 | G48: Modern Trade | H48: 23 | I48: MT Term 30-2 | J48: F213 DMCW-รชล-พระพุทธบาท | K48: 00000 หน่วยงานกลาง | L48: 923 | N48: 1A531845L0 | O48: บมจ. ซีพี แอ็กซ์ตร้า พีเอ็มที โรจนะ (3095) | P48: 1 | Q48: LOTUS พีเอ็มที โรจนะ (3095) | R48: 244481 | S48: 244482 | T48: H6954RLG0914058 | U48: 23086963 | V48: เนื้อแดงแต่งตัดชิ้น SIS กก.ละ | W48: 3 | X48: 3 | Y48: 3 | Z48: 3 | AA48: 0 | AB48: 0 | AC48: 0 | AD48: 0 | AE48: 3 | AF48: 3 | AI48: OPRCD0489OPRCD00023OPRCDF213OPRCD00000OPRCD923 | AJ48: ซื้อ / ขาย | AK48: Main proudct | AL48: Bulk Normal | AM48: สุกร | AN48: MT1001 HYPER-Lotus | AO48: MT | AP48: 10 | AQ48: 1 | AT48: System Batch | AU48: 2026-05-12-12.11.25.000000 | AV48: ก.ก. | AW48: ก.ก. | AY48: 0 | AZ48: N | BA48: 1179740890381 | BD48: 1 | BF48: ;INCLUDE_We | BG48: 1333314600 | BH48: G | BI48: 3 | BJ48: 3 | BL48: INTERFACE
C49: 244482 | D49: 244482 | F49: 489 | G49: Modern Trade | H49: 23 | I49: MT Term 30-2 | J49: F213 DMCW-รชล-พระพุทธบาท | K49: 00000 หน่วยงานกลาง | L49: 923 | N49: 1A531845L0 | O49: บมจ. ซีพี แอ็กซ์ตร้า พีเอ็มที โรจนะ (3095) | P49: 1 | Q49: LOTUS พีเอ็มที โรจนะ (3095) | R49: 244481 | S49: 244482 | T49: H6954RLG0914058 | U49: 23090975 | V49: สามชั้นสไลซ์ SIS กก.ละ | W49: 3 | X49: 3 | Y49: 3 | Z49: 3 | AA49: 0 | AB49: 0 | AC49: 0 | AD49: 0 | AE49: 3 | AF49: 3 | AI49: OPRCD0489OPRCD00023OPRCDF213OPRCD00000OPRCD923 | AJ49: ซื้อ / ขาย | AK49: Main proudct | AL49: Bulk Normal | AM49: สุกร | AN49: MT1001 HYPER-Lotus | AO49: MT | AP49: 10 | AQ49: 1 | AT49: System Batch | AU49: 2026-05-12-12.11.25.000000 | AV49: ก.ก. | AW49: ก.ก. | AY49: 0 | AZ49: N | BA49: 1179740890381 | BD49: 1 | BF49: ;INCLUDE_We | BG49: 1333314600 | BH49: G | BI49: 3 | BJ49: 3 | BL49: INTERFACE
C50: 244482 | D50: 244482 | F50: 489 | G50: Modern Trade | H50: 23 | I50: MT Term 30-2 | J50: F213 DMCW-รชล-พระพุทธบาท | K50: 00000 หน่วยงานกลาง | L50: 923 | N50: 1A531896L0 | O50: บมจ. ซีพี แอ็กซ์ตร้า ตลาดคลองถม (3148) | P50: 1 | Q50: LOTUS ตลาดคลองถม (3148) | R50: 244481 | S50: 244482 | T50: H6954RLG0914059 | U50: 23095553 | V50: กระดูกอ่อนใบพาย (SIS) กก. ละ | W50: 3 | X50: 3 | Y50: 3 | Z50: 3 | AA50: 0 | AB50: 0 | AC50: 0 | AD50: 0 | AE50: 3 | AF50: 3 | AI50: OPRCD0489OPRCD00023OPRCDF213OPRCD00000OPRCD923 | AJ50: ซื้อ / ขาย | AK50: By proudct | AL50: Bulk Normal | AM50: สุกร | AN50: MT1001 HYPER-Lotus | AO50: MT | AP50: 10 | AQ50: 1 | AT50: System Batch | AU50: 2026-05-12-12.11.25.000000 | AV50: ก.ก. | AW50: ก.ก. | AY50: 0 | AZ50: N | BA50: 1179740890384 | BD50: 1 | BF50: ;INCLUDE_We | BG50: 1333314600 | BH50: G | BI50: 3 | BJ50: 3 | BK50: 1300 | BL50: INTERFACE
C51: 244482 | D51: 244482 | F51: 489 | G51: Modern Trade | H51: 23 | I51: MT Term 30-2 | J51: F213 DMCW-รชล-พระพุทธบาท | K51: 00000 หน่วยงานกลาง | L51: 923 | N51: 1A531896L0 | O51: บมจ. ซีพี แอ็กซ์ตร้า ตลาดคลองถม (3148) | P51: 1 | Q51: LOTUS ตลาดคลองถม (3148) | R51: 244481 | S51: 244482 | T51: H6954RLG0914059 | U51: 23086963 | V51: เนื้อแดงแต่งตัดชิ้น SIS กก.ละ | W51: 3 | X51: 3 | Y51: 3 | Z51: 3 | AA51: 0 | AB51: 0 | AC51: 0 | AD51: 0 | AE51: 3 | AF51: 3 | AI51: OPRCD0489OPRCD00023OPRCDF213OPRCD00000OPRCD923 | AJ51: ซื้อ / ขาย | AK51: Main proudct | AL51: Bulk Normal | AM51: สุกร | AN51: MT1001 HYPER-Lotus | AO51: MT | AP51: 10 | AQ51: 1 | AT51: System Batch | AU51: 2026-05-12-12.11.25.000000 | AV51: ก.ก. | AW51: ก.ก. | AY51: 0 | AZ51: N | BA51: 1179740890384 | BD51: 1 | BF51: ;INCLUDE_We | BG51: 1333314600 | BH51: G | BI51: 3 | BJ51: 3 | BK51: 1300 | BL51: INTERFACE
