Workbook

Sheet Sheet1
A1: rOper_name | B1: Modern Trade (Makro)
A2: rBst_code | B2: 923
A3: rProduct_group_code2 | B3: (ทั้งหมด)
A4: rShip_name | B4: (ทั้งหมด)
A5: rPO_no | B5: (ทั้งหมด)
A6: rReq_date | B6: 14/5/2569
A7: rDoc_number | B7: (ทั้งหมด)
B8: คืน 13.5
A9: Sum of rPlan_wgt
A10: rProduct_code | B10: rProduct_name | C10: ผลรวม
A11: 23000206 | B11: ชิ้นมันคอ | C11: 20
A12: 23015265 | B12: ซี่โครงหั่นชิ้น | C12: 100
A13: 23047038 | B13: หมุบดเบอร์ 1 | C13: 200
A14: 23057809 | B14: เนื้อไหล่(M) | C14: 290
A15: 23057812 | B15: สะโพก(M) | C15: 1130
A16: 23057815 | B16: สันนอก(M) | C16: 540
A17: 23057818 | B17: สันใน(M) | C17: 75
A18: 23057821 | B18: สันคอ(M) | C18: 165
A19: 23057824 | B19: สามชั้น(M) | C19: 230
A20: 23057827 | B20: ซี่โครง(M) | C20: 5
A21: 23058551 | B21: คอหมูย่าง (M) | C21: 150
A22: 23058552 | B22: มันสันหลัง (M) | C22: 90
... A128: 23074627 | B128: สันนอกหมูตัดชิ้น (M) | C128: 40
A129: ผลรวมทั้งหมด | C129: 9816.9998

Sheet mk 001 10.3
A1: บมจ. ซีพีเอฟ โกลบอล ฟู้ด โซลูชั่น
A2: rDate1 | B2: rDate2 | C2: rRDate1 | D2: rRDate2 | E2: rRDate3 | F2: rOper_code | G2: rOper_name | H2: rSub_oper | I2: rSub_name | J2: rWarehouse | K2: rSub_warehouse | L2: rBst_code | M2: rBst_name | N2: rCv_code | O2: rCv_name | P2: rShip_to | Q2: rShip_name | R2: rDoc_date | S2: rReq_date | T2: rDoc_number | U2: rProduct_code | V2: rProduct_name | W2: rStock_qty | X2: rStock_wgt | Y2: rPlan_qty | Z2: rPlan_wgt | AA2: rDiff_stock_qty_plan | AB2: rDiff_stock_wgt_plan | AC2: rAllocate_stock_qty | AD2: rAllocate_stock_wgt | AE2: rDiff_stock_qty | AF2: rDiff_stock_wgt | AG2: rPlan_byquota_qty | AH2: rPlan_byquota_wgt | AI2: rBreak | AJ2: rEntry_type | AK2: rProduct_group_code1 | AL2: rProduct_group_code2 | AM2: rProduct_group_dim1 | AN2: rCv_channel | AO2: rCV_FLAG1 | AP2: rCV_FLAG2 | AQ2: rCV_FLAG3 | AR2: rCV_FLAG4 | AS2: rCV_FLAG5 | AT2: rOwner_so | AU2: rCreate_date_so | AV2: rUm_stock_qty | AW2: rUm_stock_wgt | AX2: rArea | AY2: nShow_area | AZ2: rModel | BA2: rPO_no | BB2: rDO_no | BC2: rINV_no | BD2: rDoc_issue | BE2: rPlant_code | BF2: rAllocate_remark | BG2: rVendor_code | BH2: rStatus | BI2: rStock_qty_pur | BJ2: rStock_wgt_pur | BK2: rCut_off_time | BL2: rOwner_create | BM2: rCo_load | BN2: rLicense_plate
C3: 14/5/2569 | D3: 14/5/2569 | F3: 489M | G3: Modern Trade (Makro) | H3: 0 | I3: หน่วยงานกลาง | J3: F213 DMCW-รชล-พระพุทธบาท | K3: 00000 หน่วยงานกลาง | L3: 923 | N3: 1A53017200 | O3: บมจ. ซีพี แอ็กซ์ตร้า สาขาชัยนาท | P3: 2 | Q3: MAKRO 0164 สาขาชัยนาท | R3: 244566 | S3: 14/5/2569 | T3: H6954RMA0058184 | U3: 23057821 | V3: สันคอ(M) | W3: 20 | X3: 20 | Y3: 20 | Z3: 20 | AA3: 0 | AB3: 0 | AC3: 0 | AD3: 0 | AE3: 20 | AF3: 20 | AI3: OPRCD489MOPRCD00000OPRCDF213OPRCD00000OPRCD923 | AJ3: ซื้อ / ขาย | AK3: Main proudct | AL3: Bulk Normal | AM3: สุกร | AN3: MT2001 SUPER MK.-Makro | AO3: MT | AP3: 20 | AQ3: 1 | AT3: เบญจพจน์ เพชรเหลี่ยม | AU3: 2026-05-08-13.09.12.000000 | AV3: ก.ก. | AW3: ก.ก. | AY3: 0 | AZ3: N | BA3: 9044989472405 | BD3: 1 | BF3: ;0000 | BG3: 1333314600 | BH3: G | BI3: 20 | BJ3: 20 | BL3: SYSBATCH
C4: 14/5/2569 | D4: 14/5/2569 | F4: 489M | G4: Modern Trade (Makro) | H4: 0 | I4: หน่วยงานกลาง | J4: F213 DMCW-รชล-พระพุทธบาท | K4: 00000 หน่วยงานกลาง | L4: 923 | N4: 1A53017200 | O4: บมจ. ซีพี แอ็กซ์ตร้า สาขาชัยนาท | P4: 2 | Q4: MAKRO 0164 สาขาชัยนาท | R4: 244566 | S4: 14/5/2569 | T4: H6954RMA0058184 | U4: 23057812 | V4: สะโพก(M) | W4: 130 | X4: 130 | Y4: 130 | Z4: 130 | AA4: 0 | AB4: 0 | AC4: 0 | AD4: 0 | AE4: 130 | AF4: 130 | AI4: OPRCD489MOPRCD00000OPRCDF213OPRCD00000OPRCD923 | AJ4: ซื้อ / ขาย | AK4: Main proudct | AL4: Bulk Normal | AM4: สุกร | AN4: MT2001 SUPER MK.-Makro | AO4: MT | AP4: 20 | AQ4: 1 | AT4: เบญจพจน์ เพชรเหลี่ยม | AU4: 2026-05-08-13.09.12.000000 | AV4: ก.ก. | AW4: ก.ก. | AY4: 0 | AZ4: N | BA4: 9044989472405 | BD4: 1 | BF4: ;0000 | BG4: 1333314600 | BH4: G | BI4: 130 | BJ4: 130 | BL4: SYSBATCH
C5: 14/5/2569 | D5: 14/5/2569 | F5: 489M | G5: Modern Trade (Makro) | H5: 0 | I5: หน่วยงานกลาง | J5: F213 DMCW-รชล-พระพุทธบาท | K5: 00000 หน่วยงานกลาง | L5: 923 | N5: 1A53017200 | O5: บมจ. ซีพี แอ็กซ์ตร้า สาขาชัยนาท | P5: 2 | Q5: MAKRO 0164 สาขาชัยนาท | R5: 244566 | S5: 14/5/2569 | T5: H6954RMA0058184 | U5: 23065143 | V5: สามชั้นสไลด์ | W5: 90 | X5: 90 | Y5: 90 | Z5: 90 | AA5: 0 | AB5: 0 | AC5: 0 | AD5: 0 | AE5: 90 | AF5: 90 | AI5: OPRCD489MOPRCD00000OPRCDF213OPRCD00000OPRCD923 | AJ5: ซื้อ / ขาย | AK5: Main proudct | AL5: Bulk Normal | AM5: สุกร | AN5: MT2001 SUPER MK.-Makro | AO5: MT | AP5: 20 | AQ5: 1 | AT5: เบญจพจน์ เพชรเหลี่ยม | AU5: 2026-05-08-13.09.12.000000 | AV5: ก.ก. | AW5: ก.ก. | AY5: 0 | AZ5: N | BA5: 9044989472405 | BD5: 1 | BF5: ;0000 | BG5: 1333314600 | BH5: G | BI5: 90 | BJ5: 90 | BL5: SYSBATCH
C6: 14/5/2569 | D6: 14/5/2569 | F6: 489M | G6: Modern Trade (Makro) | H6: 0 | I6: หน่วยงานกลาง | J6: F213 DMCW-รชล-พระพุทธบาท | K6: 00000 หน่วยงานกลาง | L6: 923 | N6: 1A53017200 | O6: บมจ. ซีพี แอ็กซ์ตร้า สาขาชัยนาท | P6: 2 | Q6: MAKRO 0164 สาขาชัยนาท | R6: 244566 | S6: 14/5/2569 | T6: H6954RMA0058184 | U6: 23109326 | V6: ขาหมูเผาเลาะติดหนัง กก.ละ | W6: 80 | X6: 80 | Y6: 80 | Z6: 80 | AA6: 0 | AB6: 0 | AC6: 0 | AD6: 0 | AE6: 80 | AF6: 80 | AI6: OPRCD489MOPRCD00000OPRCDF213OPRCD00000OPRCD923 | AJ6: ซื้อ / ขาย | AK6: By proudct | AL6: Bulk Normal | AM6: สุกร | AN6: MT2001 SUPER MK.-Makro | AO6: MT | AP6: 20 | AQ6: 1 | AT6: เบญจพจน์ เพชรเหลี่ยม | AU6: 2026-05-08-13.09.12.000000 | AV6: ก.ก. | AW6: ก.ก. | AY6: 0 | AZ6: N | BA6: 9044989472405 | BD6: 1 | BF6: ;0000 | BG6: 1333314600 | BH6: G | BI6: 80 | BJ6: 80 | BL6: SYSBATCH
C7: 14/5/2569 | D7: 14/5/2569 | F7: 489M | G7: Modern Trade (Makro) | H7: 0 | I7: หน่วยงานกลาง | J7: F213 DMCW-รชล-พระพุทธบาท | K7: 00000 หน่วยงานกลาง | L7: 923 | N7: 1A53017200 | O7: บมจ. ซีพี แอ็กซ์ตร้า สาขาชัยนาท | P7: 2 | Q7: MAKRO 0164 สาขาชัยนาท | R7: 244566 | S7: 14/5/2569 | T7: H6954RMA0058184 | U7: 23062101 | V7: หางหมูเผา(M) | W7: 0 | X7: 0 | Y7: 0 | Z7: 0 | AA7: 0 | AB7: 0 | AC7: 0 | AD7: 0 | AE7: 0 | AF7: 0 | AI7: OPRCD489MOPRCD00000OPRCDF213OPRCD00000OPRCD923 | AJ7: ซื้อ / ขาย | AK7: By proudct | AL7: Bulk Normal | AM7: สุกร | AN7: MT2001 SUPER MK.-Makro | AO7: MT | AP7: 20 | AQ7: 1 | AT7: เบญจพจน์ เพชรเหลี่ยม | AU7: 2026-05-08-13.09.12.000000 | AV7: ก.ก. | AW7: ก.ก. | AY7: 0 | AZ7: N | BA7: 9044989472405 | BD7: 1 | BF7: ;0000 | BG7: 1333314600 | BH7: G | BI7: 0 | BJ7: 0 | BL7: SYSBATCH
C8: 14/5/2569 | D8: 14/5/2569 | F8: 489M | G8: Modern Trade (Makro) | H8: 0 | I8: หน่วยงานกลาง | J8: F213 DMCW-รชล-พระพุทธบาท | K8: 00000 หน่วยงานกลาง | L8: 923 | N8: 1A53017200 | O8: บมจ. ซีพี แอ็กซ์ตร้า สาขาชัยนาท | P8: 2 | Q8: MAKRO 0164 สาขาชัยนาท | R8: 244566 | S8: 14/5/2569 | T8: H6954RMA0058184 | U8: 23058556 | V8: กระเพาะลวก (M) | W8: 0 | X8: 0 | Y8: 0 | Z8: 0 | AA8: 0 | AB8: 0 | AC8: 0 | AD8: 0 | AE8: 0 | AF8: 0 | AI8: OPRCD489MOPRCD00000OPRCDF213OPRCD00000OPRCD923 | AJ8: ซื้อ / ขาย | AK8: By proudct | AL8: Bulk Normal | AM8: สุกร | AN8: MT2001 SUPER MK.-Makro | AO8: MT | AP8: 20 | AQ8: 1 | AT8: เบญจพจน์ เพชรเหลี่ยม | AU8: 2026-05-08-13.09.12.000000 | AV8: ก.ก. | AW8: ก.ก. | AY8: 0 | AZ8: N | BA8: 9044989472405 | BD8: 1 | BF8: ;0000 | BG8: 1333314600 | BH8: G | BI8: 0 | BJ8: 0 | BL8: SYSBATCH
C9: 14/5/2569 | D9: 14/5/2569 | F9: 489M | G9: Modern Trade (Makro) | H9: 0 | I9: หน่วยงานกลาง | J9: F213 DMCW-รชล-พระพุทธบาท | K9: 00000 หน่วยงานกลาง | L9: 923 | N9: 1A53017200 | O9: บมจ. ซีพี แอ็กซ์ตร้า สาขาชัยนาท | P9: 2 | Q9: MAKRO 0164 สาขาชัยนาท | R9: 244566 | S9: 14/5/2569 | T9: H6954RMA0058184 | U9: 23073188 | V9: กระดูกอก(M) | W9: 10 | X9: 10 | Y9: 10 | Z9: 10 | AA9: 0 | AB9: 0 | AC9: 0 | AD9: 0 | AE9: 10 | AF9: 10 | AI9: OPRCD489MOPRCD00000OPRCDF213OPRCD00000OPRCD923 | AJ9: ซื้อ / ขาย | AK9: By proudct | AL9: Bulk Normal | AM9: สุกร | AN9: MT2001 SUPER MK.-Makro | AO9: MT | AP9: 20 | AQ9: 1 | AT9: เบญจพจน์ เพชรเหลี่ยม | AU9: 2026-05-08-13.09.12.000000 | AV9: ก.ก. | AW9: ก.ก. | AY9: 0 | AZ9: N | BA9: 9044989472405 | BD9: 1 | BF9: ;0000 | BG9: 1333314600 | BH9: G | BI9: 10 | BJ9: 10 | BL9: SYSBATCH
C10: 14/5/2569 | D10: 14/5/2569 | F10: 489M | G10: Modern Trade (Makro) | H10: 0 | I10: หน่วยงานกลาง | J10: F213 DMCW-รชล-พระพุทธบาท | K10: 00000 หน่วยงานกลาง | L10: 923 | N10: 1A53017200 | O10: บมจ. ซีพี แอ็กซ์ตร้า สาขาชัยนาท | P10: 2 | Q10: MAKRO 0164 สาขาชัยนาท | R10: 244566 | S10: 14/5/2569 | T10: H6954RMA0058184 | U10: 23088036 | V10: เนื้อไหล่หมูติดหนังหั่นชิ้น(M) | W10: 0 | X10: 0 | Y10: 0 | Z10: 0 | AA10: 0 | AB10: 0 | AC10: 0 | AD10: 0 | AE10: 0 | AF10: 0 | AI10: OPRCD489MOPRCD00000OPRCDF213OPRCD00000OPRCD923 | AJ10: ซื้อ / ขาย | AK10: Main proudct | AL10: Bulk Normal | AM10: สุกร | AN10: MT2001 SUPER MK.-Makro | AO10: MT | AP10: 20 | AQ10: 1 | AT10: เบญจพจน์ เพชรเหลี่ยม | AU10: 2026-05-08-13.09.12.000000 | AV10: ก.ก. | AW10: ก.ก. | AY10: 0 | AZ10: N | BA10: 9044989472405 | BD10: 1 | BF10: ;0000 | BG10: 1333314600 | BH10: G | BI10: 0 | BJ10: 0 | BL10: SYSBATCH
C11: 14/5/2569 | D11: 14/5/2569 | F11: 489M | G11: Modern Trade (Makro) | H11: 0 | I11: หน่วยงานกลาง | J11: F213 DMCW-รชล-พระพุทธบาท | K11: 00000 หน่วยงานกลาง | L11: 923 | N11: 1A53017200 | O11: บมจ. ซีพี แอ็กซ์ตร้า สาขาชัยนาท | P11: 2 | Q11: MAKRO 0164 สาขาชัยนาท | R11: 244566 | S11: 14/5/2569 | T11: H6954RMA0058184 | U11: 23098991 | V11: พอร์คชอพตัดสเต็ก กก.ละ | W11: 0 | X11: 0 | Y11: 0 | Z11: 0 | AA11: 0 | AB11: 0 | AC11: 0 | AD11: 0 | AE11: 0 | AF11: 0 | AI11: OPRCD489MOPRCD00000OPRCDF213OPRCD00000OPRCD923 | AJ11: ซื้อ / ขาย | AK11: Main proudct | AL11: Bulk Normal | AM11: สุกร | AN11: MT2001 SUPER MK.-Makro | AO11: MT | AP11: 20 | AQ11: 1 | AT11: เบญจพจน์ เพชรเหลี่ยม | AU11: 2026-05-08-13.09.12.000000 | AV11: ก.ก. | AW11: ก.ก. | AY11: 0 | AZ11: N | BA11: 9044989472405 | BD11: 1 | BF11: ;0000 | BG11: 1333314600 | BH11: G | BI11: 0 | BJ11: 0 | BL11: SYSBATCH
C12: 14/5/2569 | D12: 14/5/2569 | F12: 489M | G12: Modern Trade (Makro) | H12: 0 | I12: หน่วยงานกลาง | J12: F213 DMCW-รชล-พระพุทธบาท | K12: 00000 หน่วยงานกลาง | L12: 923 | N12: 1A53017200 | O12: บมจ. ซีพี แอ็กซ์ตร้า สาขาชัยนาท | P12: 2 | Q12: MAKRO 0164 สาขาชัยนาท | R12: 244566 | S12: 14/5/2569 | T12: H6954RMA0058184 | U12: 23062105 | V12: ไส้ตันลวก(M) | W12: 0 | X12: 0 | Y12: 0 | Z12: 0 | AA12: 0 | AB12: 0 | AC12: 0 | AD12: 0 | AE12: 0 | AF12: 0 | AI12: OPRCD489MOPRCD00000OPRCDF213OPRCD00000OPRCD923 | AJ12: ซื้อ / ขาย | AK12: By proudct | AL12: Bulk Normal | AM12: สุกร | AN12: MT2001 SUPER MK.-Makro | AO12: MT | AP12: 20 | AQ12: 1 | AT12: เบญจพจน์ เพชรเหลี่ยม | AU12: 2026-05-08-13.09.12.000000 | AV12: ก.ก. | AW12: ก.ก. | AY12: 0 | AZ12: N | BA12: 9044989472405 | BD12: 1 | BF12: ;0000 | BG12: 1333314600 | BH12: G | BI12: 0 | BJ12: 0 | BL12: SYSBATCH
C13: 14/5/2569 | D13: 14/5/2569 | F13: 489M | G13: Modern Trade (Makro) | H13: 0 | I13: หน่วยงานกลาง | J13: F213 DMCW-รชล-พระพุทธบาท | K13: 00000 หน่วยงานกลาง | L13: 923 | N13: 1A53017200 | O13: บมจ. ซีพี แอ็กซ์ตร้า สาขาชัยนาท | P13: 2 | Q13: MAKRO 0164 สาขาชัยนาท | R13: 244566 | S13: 14/5/2569 | T13: H6954RMA0058184 | U13: 23058551 | V13: คอหมูย่าง (M) | W13: 5 | X13: 5 | Y13: 5 | Z13: 5 | AA13: 0 | AB13: 0 | AC13: 0 | AD13: 0 | AE13: 5 | AF13: 5 | AI13: OPRCD489MOPRCD00000OPRCDF213OPRCD00000OPRCD923 | AJ13: ซื้อ / ขาย | AK13: Main proudct | AL13: Bulk Normal | AM13: สุกร | AN13: MT2001 SUPER MK.-Makro | AO13: MT | AP13: 20 | AQ13: 1 | AT13: เบญจพจน์ เพชรเหลี่ยม | AU13: 2026-05-08-13.09.12.000000 | AV13: ก.ก. | AW13: ก.ก. | AY13: 0 | AZ13: N | BA13: 9044989472405 | BD13: 1 | BF13: ;0000 | BG13: 1333314600 | BH13: G | BI13: 5 | BJ13: 5 | BL13: SYSBATCH
C14: 14/5/2569 | D14: 14/5/2569 | F14: 489M | G14: Modern Trade (Makro) | H14: 0 | I14: หน่วยงานกลาง | J14: F213 DMCW-รชล-พระพุทธบาท | K14: 00000 หน่วยงานกลาง | L14: 923 | N14: 1A53017200 | O14: บมจ. ซีพี แอ็กซ์ตร้า สาขาชัยนาท | P14: 2 | Q14: MAKRO 0164 สาขาชัยนาท | R14: 244566 | S14: 14/5/2569 | T14: H6954RMA0058184 | U14: 23062095 | V14: หน้ากากหมูเผา(M) | W14: 5 | X14: 5 | Y14: 5 | Z14: 5 | AA14: 0 | AB14: 0 | AC14: 0 | AD14: 0 | AE14: 5 | AF14: 5 | AI14: OPRCD489MOPRCD00000OPRCDF213OPRCD00000OPRCD923 | AJ14: ซื้อ / ขาย | AK14: By proudct | AL14: Bulk Normal | AM14: สุกร | AN14: MT2001 SUPER MK.-Makro | AO14: MT | AP14: 20 | AQ14: 1 | AT14: เบญจพจน์ เพชรเหลี่ยม | AU14: 2026-05-08-13.09.12.000000 | AV14: ก.ก. | AW14: ก.ก. | AY14: 0 | AZ14: N | BA14: 9044989472405 | BD14: 1 | BF14: ;0000 | BG14: 1333314600 | BH14: G | BI14: 5 | BJ14: 5 | BL14: SYSBATCH
... C52: 14/5/2569 | D52: 14/5/2569 | F52: 489M | G52: Modern Trade (Makro) | H52: 0 | I52: หน่วยงานกลาง | J52: F213 DMCW-รชล-พระพุทธบาท | K52: 00000 หน่วยงานกลาง | L52: 923 | N52: 1A53017200 | O52: บมจ. ซีพี แอ็กซ์ตร้า สาขาชัยนาท | P52: 2 | Q52: MAKRO 0164 สาขาชัยนาท | R52: 244566 | S52: 14/5/2569 | T52: H6954RMA0058184 | U52: 23062097 | V52: ลิ้นหมู(M) | W52: 5 | X52: 5 | Y52: 5 | Z52: 5 | AA52: 0 | AB52: 0 | AC52: 0 | AD52: 0 | AE52: 5 | AF52: 5 | AI52: OPRCD489MOPRCD00000OPRCDF213OPRCD00000OPRCD923 | AJ52: ซื้อ / ขาย | AK52: By proudct | AL52: Bulk Normal | AM52: สุกร | AN52: MT2001 SUPER MK.-Makro | AO52: MT | AP52: 20 | AQ52: 1 | AT52: เบญจพจน์ เพชรเหลี่ยม | AU52: 2026-05-08-13.09.12.000000 | AV52: ก.ก. | AW52: ก.ก. | AY52: 0 | AZ52: N | BA52: 9044989472405 | BD52: 1 | BF52: ;0000 | BG52: 1333314600 | BH52: G | BI52: 5 | BJ52: 5 | BL52: SYSBATCH
C53: 14/5/2569 | D53: 14/5/2569 | F53: 489M | G53: Modern Trade (Makro) | H53: 0 | I53: หน่วยงานกลาง | J53: F213 DMCW-รชล-พระพุทธบาท | K53: 00000 หน่วยงานกลาง | L53: 923 | N53: 1A53008400 | O53: บมจ. ซีพี แอ็กซ์ตร้า สาขานครอินทร์ | P53: 2 | Q53: MAKRO 0083 นครอินทร์ | R53: 244658 | S53: 14/5/2569 | T53: H6954RMA0059103 | U53: 23097791 | V53: สันในหมู 1 กก. (M) | W53: 2 | X53: 2 | Y53: 2 | Z53: 2 | AA53: 0 | AB53: 0 | AC53: 0 | AD53: 0 | AE53: 2 | AF53: 2 | AI53: OPRCD489MOPRCD00000OPRCDF213OPRCD00000OPRCD923 | AJ53: ซื้อ / ขาย | AK53: Main proudct | AL53: Bulk Normal | AM53: สุกร | AN53: OT002 CC-Makro | AO53: MT | AP53: 2 | AT53: System Batch | AU53: 2026-05-11-12.40.50.000000 | AV53: แพ็ค | AW53: ก.ก. | AY53: 0 | AZ53: N | BA53: 9045089536563 | BD53: 1 | BG53: 1333314600 | BH53: G | BI53: 2 | BJ53: 2 | BK53: 1300 | BL53: SYSBATCH
C54: 14/5/2569 | D54: 14/5/2569 | F54: 489M | G54: Modern Trade (Makro) | H54: 0 | I54: หน่วยงานกลาง | J54: F213 DMCW-รชล-พระพุทธบาท | K54: 00000 หน่วยงานกลาง | L54: 923 | N54: 1A53008400 | O54: บมจ. ซีพี แอ็กซ์ตร้า สาขานครอินทร์ | P54: 2 | Q54: MAKRO 0083 นครอินทร์ | R54: 244658 | S54: 14/5/2569 | T54: H6954RMA0059103 | U54: 23097783 | V54: เนื้อไหล่หมูบด 1 กก. (M) | W54: 50 | X54: 50 | Y54: 50 | Z54: 50 | AA54: 0 | AB54: 0 | AC54: 0 | AD54: 0 | AE54: 50 | AF54: 50 | AI54: OPRCD489MOPRCD00000OPRCDF213OPRCD00000OPRCD923 | AJ54: ซื้อ / ขาย | AK54: Main proudct | AL54: Bulk Normal | AM54: สุกร | AN54: OT002 CC-Makro | AO54: MT | AP54: 2 | AT54: System Batch | AU54: 2026-05-11-12.40.50.000000 | AV54: แพ็ค | AW54: ก.ก. | AY54: 0 | AZ54: N | BA54: 9045089536563 | BD54: 1 | BG54: 1333314600 | BH54: G | BI54: 50 | BJ54: 50 | BK54: 1300 | BL54: SYSBATCH
C55: 14/5/2569 | D55: 14/5/2569 | F55: 489M | G55: Modern Trade (Makro) | H55: 0 | I55: หน่วยงานกลาง | J55: F213 DMCW-รชล-พระพุทธบาท | K55: 00000 หน่วยงานกลาง | L55: 923 | N55: 1A53008400 | O55: บมจ. ซีพี แอ็กซ์ตร้า สาขานครอินทร์ | P55: 2 | Q55: MAKRO 0083 นครอินทร์ | R55: 244658 | S55: 14/5/2569 | T55: H6954RMA0059103 | U55: 23109359 | V55: หมูชีวาบด (ตรา ยูฟาร์ม) 400 กรัม | W55: 12 | X55: 4.8 | Y55: 12 | Z55: 4.8 | AA55: 0 | AB55: 0 | AC55: 0 | AD55: 0 | AE55: 12 | AF55: 4.8 | AI55: OPRCD489MOPRCD00000OPRCDF213OPRCD00000OPRCD923 | AJ55: ซื้อ / ขาย | AK55: Main proudct | AL55: Seal Pack | AM55: สุกร | AN55: OT002 CC-Makro | AO55: MT | AP55: 2 | AT55: System Batch | AU55: 2026-05-11-12.40.50.000000 | AV55: แพ็ค | AW55: ก.ก. | AY55: 0 | AZ55: N | BA55: 9045089536563 | BD55: 1 | BG55: 1333314600 | BH55: G | BI55: 12 | BJ55: 4.8 | BK55: 1300 | BL55: SYSBATCH
C56: 14/5/2569 | D56: 14/5/2569 | F56: 489M | G56: Modern Trade (Makro) | H56: 0 | I56: หน่วยงานกลาง | J56: F213 DMCW-รชล-พระพุทธบาท | K56: 00000 หน่วยงานกลาง | L56: 923 | N56: 1A53008400 | O56: บมจ. ซีพี แอ็กซ์ตร้า สาขานครอินทร์ | P56: 2 | Q56: MAKRO 0083 นครอินทร์ | R56: 244658 | S56: 14/5/2569 | T56: H6954RMA0059103 | U56: 23109357 | V56: สะโพกหมูชีวา (ตรา ยูฟาร์ม) 400 กรัม | W56: 2 | X56: 0.8 | Y56: 2 | Z56: 0.8 | AA56: 0 | AB56: 0 | AC56: 0 | AD56: 0 | AE56: 2 | AF56: 0.8 | AI56: OPRCD489MOPRCD00000OPRCDF213OPRCD00000OPRCD923 | AJ56: ซื้อ / ขาย | AK56: Main proudct | AL56: Seal Pack | AM56: สุกร | AN56: OT002 CC-Makro | AO56: MT | AP56: 2 | AT56: System Batch | AU56: 2026-05-11-12.40.50.000000 | AV56: แพ็ค | AW56: ก.ก. | AY56: 0 | AZ56: N | BA56: 9045089536563 | BD56: 1 | BG56: 1333314600 | BH56: G | BI56: 2 | BJ56: 0.8 | BK56: 1300 | BL56: SYSBATCH
C57: 14/5/2569 | D57: 14/5/2569 | F57: 489M | G57: Modern Trade (Makro) | H57: 0 | I57: หน่วยงานกลาง | J57: F213 DMCW-รชล-พระพุทธบาท | K57: 00000 หน่วยงานกลาง | L57: 923 | N57: 1A53008400 | O57: บมจ. ซีพี แอ็กซ์ตร้า สาขานครอินทร์ | P57: 2 | Q57: MAKRO 0083 นครอินทร์ | R57: 244658 | S57: 14/5/2569 | T57: H6954RMA0059103 | U57: 23109351 | V57: สามชั้นหมูชีวาสไลซ์(ตรา ยูฟาร์ม)250 กรัม | W57: 4 | X57: 1 | Y57: 4 | Z57: 1 | AA57: 0 | AB57: 0 | AC57: 0 | AD57: 0 | AE57: 4 | AF57: 1 | AI57: OPRCD489MOPRCD00000OPRCDF213OPRCD00000OPRCD923 | AJ57: ซื้อ / ขาย | AK57: Main proudct | AL57: Seal Pack | AM57: สุกร | AN57: OT002 CC-Makro | AO57: MT | AP57: 2 | AT57: System Batch | AU57: 2026-05-11-12.40.50.000000 | AV57: แพ็ค | AW57: ก.ก. | AY57: 0 | AZ57: N | BA57: 9045089536563 | BD57: 1 | BG57: 1333314600 | BH57: G | BI57: 4 | BJ57: 1 | BK57: 1300 | BL57: SYSBATCH
C58: 14/5/2569 | D58: 14/5/2569 | F58: 489M | G58: Modern Trade (Makro) | H58: 0 | I58: หน่วยงานกลาง | J58: F213 DMCW-รชล-พระพุทธบาท | K58: 00000 หน่วยงานกลาง | L58: 923 | N58: 1A53008400 | O58: บมจ. ซีพี แอ็กซ์ตร้า สาขานครอินทร์ | P58: 2 | Q58: MAKRO 0083 นครอินทร์ | R58: 244658 | S58: 14/5/2569 | T58: H6954RMA0059103 | U58: 23097788 | V58: ตับหมู 1 กก. (M) | W58: 2 | X58: 2 | Y58: 2 | Z58: 2 | AA58: 0 | AB58: 0 | AC58: 0 | AD58: 0 | AE58: 2 | AF58: 2 | AI58: OPRCD489MOPRCD00000OPRCDF213OPRCD00000OPRCD923 | AJ58: ซื้อ / ขาย | AK58: By proudct | AL58: Bulk Normal | AM58: สุกร | AN58: OT002 CC-Makro | AO58: MT | AP58: 2 | AT58: System Batch | AU58: 2026-05-11-12.40.50.000000 | AV58: แพ็ค | AW58: ก.ก. | AY58: 0 | AZ58: N | BA58: 9045089536563 | BD58: 1 | BG58: 1333314600 | BH58: G | BI58: 2 | BJ58: 2 | BK58: 1300 | BL58: SYSBATCH
C59: 14/5/2569 | D59: 14/5/2569 | F59: 489M | G59: Modern Trade (Makro) | H59: 0 | I59: หน่วยงานกลาง | J59: F213 DMCW-รชล-พระพุทธบาท | K59: 00000 หน่วยงานกลาง | L59: 923 | N59: 1A53008400 | O59: บมจ. ซีพี แอ็กซ์ตร้า สาขานครอินทร์ | P59: 2 | Q59: MAKRO 0083 นครอินทร์ | R59: 244658 | S59: 14/5/2569 | T59: H6954RMA0059103 | U59: 23109358 | V59: สามชั้นหมูชีวา (ตรา ยูฟาร์ม) 400 กรัม | W59: 4 | X59: 1.6 | Y59: 4 | Z59: 1.6 | AA59: 0 | AB59: 0 | AC59: 0 | AD59: 0 | AE59: 4 | AF59: 1.6 | AI59: OPRCD489MOPRCD00000OPRCDF213OPRCD00000OPRCD923 | AJ59: ซื้อ / ขาย | AK59: Main proudct | AL59: Seal Pack | AM59: สุกร | AN59: OT002 CC-Makro | AO59: MT | AP59: 2 | AT59: System Batch | AU59: 2026-05-11-12.40.50.000000 | AV59: แพ็ค | AW59: ก.ก. | AY59: 0 | AZ59: N | BA59: 9045089536563 | BD59: 1 | BG59: 1333314600 | BH59: G | BI59: 4 | BJ59: 1.6 | BK59: 1300 | BL59: SYSBATCH
C60: 14/5/2569 | D60: 14/5/2569 | F60: 489M | G60: Modern Trade (Makro) | H60: 0 | I60: หน่วยงานกลาง | J60: F213 DMCW-รชล-พระพุทธบาท | K60: 00000 หน่วยงานกลาง | L60: 923 | N60: 1A53008400 | O60: บมจ. ซีพี แอ็กซ์ตร้า สาขานครอินทร์ | P60: 2 | Q60: MAKRO 0083 นครอินทร์ | R60: 244658 | S60: 14/5/2569 | T60: H6954RMA0059103 | U60: 23109532 | V60: ตับหมูชีวา 400 กรัม | W60: 4 | X60: 1.6 | Y60: 4 | Z60: 1.6 | AA60: 0 | AB60: 0 | AC60: 0 | AD60: 0 | AE60: 4 | AF60: 1.6 | AI60: OPRCD489MOPRCD00000OPRCDF213OPRCD00000OPRCD923 | AJ60: ซื้อ / ขาย | AK60: By proudct | AL60: Seal Pack | AM60: สุกร | AN60: OT002 CC-Makro | AO60: MT | AP60: 2 | AT60: System Batch | AU60: 2026-05-11-12.40.50.000000 | AV60: แพ็ค | AW60: ก.ก. | AY60: 0 | AZ60: N | BA60: 9045089536563 | BD60: 1 | BG60: 1333314600 | BH60: G | BI60: 4 | BJ60: 1.6 | BK60: 1300 | BL60: SYSBATCH
C61: 14/5/2569 | D61: 14/5/2569 | F61: 489M | G61: Modern Trade (Makro) | H61: 0 | I61: หน่วยงานกลาง | J61: F213 DMCW-รชล-พระพุทธบาท | K61: 00000 หน่วยงานกลาง | L61: 923 | N61: 1A53008400 | O61: บมจ. ซีพี แอ็กซ์ตร้า สาขานครอินทร์ | P61: 2 | Q61: MAKRO 0083 นครอินทร์ | R61: 244658 | S61: 14/5/2569 | T61: H6954RMA0059103 | U61: 23097793 | V61: สันคอหมูสไลซ์ 1 กก. (M) | W61: 24 | X61: 24 | Y61: 24 | Z61: 24 | AA61: 0 | AB61: 0 | AC61: 0 | AD61: 0 | AE61: 24 | AF61: 24 | AI61: OPRCD489MOPRCD00000OPRCDF213OPRCD00000OPRCD923 | AJ61: ซื้อ / ขาย | AK61: Main proudct | AL61: Bulk Normal | AM61: สุกร | AN61: OT002 CC-Makro | AO61: MT | AP61: 2 | AT61: System Batch | AU61: 2026-05-11-12.40.50.000000 | AV61: แพ็ค | AW61: ก.ก. | AY61: 0 | AZ61: N | BA61: 9045089536563 | BD61: 1 | BG61: 1333314600 | BH61: G | BI61: 24 | BJ61: 24 | BK61: 1300 | BL61: SYSBATCH
C62: 14/5/2569 | D62: 14/5/2569 | F62: 489M | G62: Modern Trade (Makro) | H62: 0 | I62: หน่วยงานกลาง | J62: F213 DMCW-รชล-พระพุทธบาท | K62: 00000 หน่วยงานกลาง | L62: 923 | N62: 1A53008400 | O62: บมจ. ซีพี แอ็กซ์ตร้า สาขานครอินทร์ | P62: 2 | Q62: MAKRO 0083 นครอินทร์ | R62: 244658 | S62: 14/5/2569 | T62: H6954RMA0059103 | U62: 23109352 | V62: สันนอกหมูชีวาสไลซ์(ตรา ยูฟาร์ม) 250 กรัม | W62: 12 | X62: 3 | Y62: 12 | Z62: 3 | AA62: 0 | AB62: 0 | AC62: 0 | AD62: 0 | AE62: 12 | AF62: 3 | AI62: OPRCD489MOPRCD00000OPRCDF213OPRCD00000OPRCD923 | AJ62: ซื้อ / ขาย | AK62: Main proudct | AL62: Seal Pack | AM62: สุกร | AN62: OT002 CC-Makro | AO62: MT | AP62: 2 | AT62: System Batch | AU62: 2026-05-11-12.40.50.000000 | AV62: แพ็ค | AW62: ก.ก. | AY62: 0 | AZ62: N | BA62: 9045089536563 | BD62: 1 | BG62: 1333314600 | BH62: G | BI62: 12 | BJ62: 3 | BK62: 1300 | BL62: SYSBATCH
C63: 14/5/2569 | D63: 14/5/2569 | F63: 489M | G63: Modern Trade (Makro) | H63: 0 | I63: หน่วยงานกลาง | J63: F213 DMCW-รชล-พระพุทธบาท | K63: 00000 หน่วยงานกลาง | L63: 923 | N63: 1A53008400 | O63: บมจ. ซีพี แอ็กซ์ตร้า สาขานครอินทร์ | P63: 2 | Q63: MAKRO 0083 นครอินทร์ | R63: 244658 | S63: 14/5/2569 | T63: H6954RMA0059103 | U63: 23109353 | V63: สันคอหมูชีวาสไลซ์(ตรา ยูฟาร์ม) 250 กรัม | W63: 12 | X63: 3 | Y63: 12 | Z63: 3 | AA63: 0 | AB63: 0 | AC63: 0 | AD63: 0 | AE63: 12 | AF63: 3 | AI63: OPRCD489MOPRCD00000OPRCDF213OPRCD00000OPRCD923 | AJ63: ซื้อ / ขาย | AK63: Main proudct | AL63: Seal Pack | AM63: สุกร | AN63: OT002 CC-Makro | AO63: MT | AP63: 2 | AT63: System Batch | AU63: 2026-05-11-12.40.50.000000 | AV63: แพ็ค | AW63: ก.ก. | AY63: 0 | AZ63: N | BA63: 9045089536563 | BD63: 1 | BG63: 1333314600 | BH63: G | BI63: 12 | BJ63: 3 | BK63: 1300 | BL63: SYSBATCH
C64: 14/5/2569 | D64: 14/5/2569 | F64: 489M | G64: Modern Trade (Makro) | H64: 0 | I64: หน่วยงานกลาง | J64: F213 DMCW-รชล-พระพุทธบาท | K64: 00000 หน่วยงานกลาง | L64: 923 | N64: 1A53008400 | O64: บมจ. ซีพี แอ็กซ์ตร้า สาขานครอินทร์ | P64: 2 | Q64: MAKRO 0083 นครอินทร์ | R64: 244658 | S64: 14/5/2569 | T64: H6954RMA0059103 | U64: 23097790 | V64: สะโพกหมูสไลซ์ 1 กก. (M) | W64: 20 | X64: 20 | Y64: 20 | Z64: 20 | AA64: 0 | AB64: 0 | AC64: 0 | AD64: 0 | AE64: 20 | AF64: 20 | AI64: OPRCD489MOPRCD00000OPRCDF213OPRCD00000OPRCD923 | AJ64: ซื้อ / ขาย | AK64: Main proudct | AL64: Bulk Normal | AM64: สุกร | AN64: OT002 CC-Makro | AO64: MT | AP64: 2 | AT64: System Batch | AU64: 2026-05-11-12.40.50.000000 | AV64: แพ็ค | AW64: ก.ก. | AY64: 0 | AZ64: N | BA64: 9045089536563 | BD64: 1 | BG64: 1333314600 | BH64: G | BI64: 20 | BJ64: 20 | BK64: 1300 | BL64: SYSBATCH
... C97: 14/5/2569 | D97: 14/5/2569 | F97: 489M | G97: Modern Trade (Makro) | H97: 0 | I97: หน่วยงานกลาง | J97: F213 DMCW-รชล-พระพุทธบาท | K97: 00000 หน่วยงานกลาง | L97: 923 | N97: 1A53010800 | O97: บมจ. ซีพี แอ็กซ์ตร้า สาขาสิงห์บุรี | P97: 2 | Q97: MAKRO 0114 สิงห์บุรี | R97: 244658 | S97: 14/5/2569 | T97: H6954RMA0059110 | U97: 23110623 | V97: หน้ากากหมูหั่นชิ้น แพ็คถาด 500 กรัม | W97: 4 | X97: 2 | Y97: 4 | Z97: 2 | AA97: 0 | AB97: 0 | AC97: 0 | AD97: 0 | AE97: 4 | AF97: 2 | AI97: OPRCD489MOPRCD00000OPRCDF213OPRCD00000OPRCD923 | AJ97: ซื้อ / ขาย | AK97: By proudct | AL97: Seal Pack | AM97: สุกร | AN97: OT002 CC-Makro | AO97: MT | AP97: 2 | AT97: System Batch | AU97: 2026-05-11-12.40.50.000000 | AV97: แพ็ค | AW97: ก.ก. | AY97: 0 | AZ97: N | BA97: 9045089536574 | BD97: 1 | BG97: 1333314600 | BH97: G | BI97: 4 | BJ97: 2 | BK97: 1300 | BL97: SYSBATCH
C98: 14/5/2569 | D98: 14/5/2569 | F98: 489M | G98: Modern Trade (Makro) | H98: 0 | I98: หน่วยงานกลาง | J98: F213 DMCW-รชล-พระพุทธบาท | K98: 00000 หน่วยงานกลาง | L98: 923 | N98: 1A53003900 | O98: บมจ. ซีพี แอ็กซ์ตร้า สาขาสระบุรี | P98: 2 | Q98: MAKRO 0038 สระบุรี | R98: 244658 | S98: 14/5/2569 | T98: H6954RMA0059184 | U98: 23065141 | V98: สันนอกสไลด์ | W98: 30 | X98: 30 | Y98: 30 | Z98: 30 | AA98: 0 | AB98: 0 | AC98: 0 | AD98: 0 | AE98: 30 | AF98: 30 | AI98: OPRCD489MOPRCD00000OPRCDF213OPRCD00000OPRCD923 | AJ98: ซื้อ / ขาย | AK98: Main proudct | AL98: Bulk Normal | AM98: สุกร | AN98: OT002 CC-Makro | AO98: MT | AP98: 2 | AT98: เบญจพจน์ เพชรเหลี่ยม | AU98: 2026-05-11-13.33.46.000000 | AV98: ก.ก. | AW98: ก.ก. | AY98: 0 | AZ98: N | BA98: 9044989536402 | BD98: 1 | BF98: ;0000 | BG98: 1333314600 | BH98: G | BI98: 30 | BJ98: 30 | BK98: 1300 | BL98: SYSBATCH
C99: 14/5/2569 | D99: 14/5/2569 | F99: 489M | G99: Modern Trade (Makro) | H99: 0 | I99: หน่วยงานกลาง | J99: F213 DMCW-รชล-พระพุทธบาท | K99: 00000 หน่วยงานกลาง | L99: 923 | N99: 1A53003900 | O99: บมจ. ซีพี แอ็กซ์ตร้า สาขาสระบุรี | P99: 2 | Q99: MAKRO 0038 สระบุรี | R99: 244658 | S99: 14/5/2569 | T99: H6954RMA0059184 | U99: 23065143 | V99: สามชั้นสไลด์ | W99: 180 | X99: 180 | Y99: 180 | Z99: 180 | AA99: 0 | AB99: 0 | AC99: 0 | AD99: 0 | AE99: 180 | AF99: 180 | AI99: OPRCD489MOPRCD00000OPRCDF213OPRCD00000OPRCD923 | AJ99: ซื้อ / ขาย | AK99: Main proudct | AL99: Bulk Normal | AM99: สุกร | AN99: OT002 CC-Makro | AO99: MT | AP99: 2 | AT99: เบญจพจน์ เพชรเหลี่ยม | AU99: 2026-05-11-13.33.46.000000 | AV99: ก.ก. | AW99: ก.ก. | AY99: 0 | AZ99: N | BA99: 9044989536402 | BD99: 1 | BF99: ;0000 | BG99: 1333314600 | BH99: G | BI99: 180 | BJ99: 180 | BK99: 1300 | BL99: SYSBATCH
C100: 14/5/2569 | D100: 14/5/2569 | F100: 489M | G100: Modern Trade (Makro) | H100: 0 | I100: หน่วยงานกลาง | J100: F213 DMCW-รชล-พระพุทธบาท | K100: 00000 หน่วยงานกลาง | L100: 923 | N100: 1A53003900 | O100: บมจ. ซีพี แอ็กซ์ตร้า สาขาสระบุรี | P100: 2 | Q100: MAKRO 0038 สระบุรี | R100: 244658 | S100: 14/5/2569 | T100: H6954RMA0059184 | U100: 23068390 | V100: กระดูกซุปติดเนื้อพิเศษ(M) | W100: 40 | X100: 40 | Y100: 40 | Z100: 40 | AA100: 0 | AB100: 0 | AC100: 0 | AD100: 0 | AE100: 40 | AF100: 40 | AI100: OPRCD489MOPRCD00000OPRCDF213OPRCD00000OPRCD923 | AJ100: ซื้อ / ขาย | AK100: By proudct | AL100: Bulk Normal | AM100: สุกร | AN100: OT002 CC-Makro | AO100: MT | AP100: 2 | AT100: เบญจพจน์ เพชรเหลี่ยม | AU100: 2026-05-11-13.33.46.000000 | AV100: ก.ก. | AW100: ก.ก. | AY100: 0 | AZ100: N | BA100: 9044989536402 | BD100: 1 | BF100: ;0000 | BG100: 1333314600 | BH100: G | BI100: 40 | BJ100: 40 | BK100: 1300 | BL100: SYSBATCH
C101: 14/5/2569 | D101: 14/5/2569 | F101: 489M | G101: Modern Trade (Makro) | H101: 0 | I101: หน่วยงานกลาง | J101: F213 DMCW-รชล-พระพุทธบาท | K101: 00000 หน่วยงานกลาง | L101: 923 | N101: 1A53003900 | O101: บมจ. ซีพี แอ็กซ์ตร้า สาขาสระบุรี | P101: 2 | Q101: MAKRO 0038 สระบุรี | R101: 244658 | S101: 14/5/2569 | T101: H6954RMA0059184 | U101: 23065142 | V101: สันคอสไลด์ | W101: 20 | X101: 20 | Y101: 20 | Z101: 20 | AA101: 0 | AB101: 0 | AC101: 0 | AD101: 0 | AE101: 20 | AF101: 20 | AI101: OPRCD489MOPRCD00000OPRCDF213OPRCD00000OPRCD923 | AJ101: ซื้อ / ขาย | AK101: Main proudct | AL101: Bulk Normal | AM101: สุกร | AN101: OT002 CC-Makro | AO101: MT | AP101: 2 | AT101: เบญจพจน์ เพชรเหลี่ยม | AU101: 2026-05-11-13.33.46.000000 | AV101: ก.ก. | AW101: ก.ก. | AY101: 0 | AZ101: N | BA101: 9044989536402 | BD101: 1 | BF101: ;0000 | BG101: 1333314600 | BH101: G | BI101: 20 | BJ101: 20 | BK101: 1300 | BL101: SYSBATCH
C102: 14/5/2569 | D102: 14/5/2569 | F102: 489M | G102: Modern Trade (Makro) | H102: 0 | I102: หน่วยงานกลาง | J102: F213 DMCW-รชล-พระพุทธบาท | K102: 00000 หน่วยงานกลาง | L102: 923 | N102: 1A53003900 | O102: บมจ. ซีพี แอ็กซ์ตร้า สาขาสระบุรี | P102: 2 | Q102: MAKRO 0038 สระบุรี | R102: 244658 | S102: 14/5/2569 | T102: H6954RMA0059184 | U102: 23057821 | V102: สันคอ(M) | W102: 0 | X102: 0 | Y102: 0 | Z102: 0 | AA102: 0 | AB102: 0 | AC102: 0 | AD102: 0 | AE102: 0 | AF102: 0 | AI102: OPRCD489MOPRCD00000OPRCDF213OPRCD00000OPRCD923 | AJ102: ซื้อ / ขาย | AK102: Main proudct | AL102: Bulk Normal | AM102: สุกร | AN102: OT002 CC-Makro | AO102: MT | AP102: 2 | AT102: เบญจพจน์ เพชรเหลี่ยม | AU102: 2026-05-11-13.33.46.000000 | AV102: ก.ก. | AW102: ก.ก. | AY102: 0 | AZ102: N | BA102: 9044989536402 | BD102: 1 | BF102: ;0000 | BG102: 1333314600 | BH102: G | BI102: 0 | BJ102: 0 | BK102: 1300 | BL102: SYSBATCH
C103: 14/5/2569 | D103: 14/5/2569 | F103: 489M | G103: Modern Trade (Makro) | H103: 0 | I103: หน่วยงานกลาง | J103: F213 DMCW-รชล-พระพุทธบาท | K103: 00000 หน่วยงานกลาง | L103: 923 | N103: 1A53003900 | O103: บมจ. ซีพี แอ็กซ์ตร้า สาขาสระบุรี | P103: 2 | Q103: MAKRO 0038 สระบุรี | R103: 244658 | S103: 14/5/2569 | T103: H6954RMA0059184 | U103: 23108462 | V103: หมูบดปนมัน 30% แพ็ค กก.(M) | W103: 100 | X103: 100 | Y103: 100 | Z103: 100 | AA103: 0 | AB103: 0 | AC103: 0 | AD103: 0 | AE103: 100 | AF103: 100 | AI103: OPRCD489MOPRCD00000OPRCDF213OPRCD00000OPRCD923 | AJ103: ซื้อ / ขาย | AK103: Main proudct | AL103: Bulk Normal | AM103: สุกร | AN103: OT002 CC-Makro | AO103: MT | AP103: 2 | AT103: เบญจพจน์ เพชรเหลี่ยม | AU103: 2026-05-11-13.33.46.000000 | AV103: ถุง | AW103: ก.ก. | AY103: 0 | AZ103: N | BA103: 9044989536402 | BD103: 1 | BF103: ;0000 | BG103: 1333314600 | BH103: G | BI103: 100 | BJ103: 100 | BK103: 1300 | BL103: SYSBATCH
C104: 14/5/2569 | D104: 14/5/2569 | F104: 489M | G104: Modern Trade (Makro) | H104: 0 | I104: หน่วยงานกลาง | J104: F213 DMCW-รชล-พระพุทธบาท | K104: 00000 หน่วยงานกลาง | L104: 923 | N104: 1A53003900 | O104: บมจ. ซีพี แอ็กซ์ตร้า สาขาสระบุรี | P104: 2 | Q104: MAKRO 0038 สระบุรี | R104: 244658 | S104: 14/5/2569 | T104: H6954RMA0059184 | U104: 23062095 | V104: หน้ากากหมูเผา(M) | W104: 20 | X104: 20 | Y104: 20 | Z104: 20 | AA104: 0 | AB104: 0 | AC104: 0 | AD104: 0 | AE104: 20 | AF104: 20 | AI104: OPRCD489MOPRCD00000OPRCDF213OPRCD00000OPRCD923 | AJ104: ซื้อ / ขาย | AK104: By proudct | AL104: Bulk Normal | AM104: สุกร | AN104: OT002 CC-Makro | AO104: MT | AP104: 2 | AT104: เบญจพจน์ เพชรเหลี่ยม | AU104: 2026-05-11-13.33.46.000000 | AV104: ก.ก. | AW104: ก.ก. | AY104: 0 | AZ104: N | BA104: 9044989536402 | BD104: 1 | BF104: ;0000 | BG104: 1333314600 | BH104: G | BI104: 20 | BJ104: 20 | BK104: 1300 | BL104: SYSBATCH
C105: 14/5/2569 | D105: 14/5/2569 | F105: 489M | G105: Modern Trade (Makro) | H105: 0 | I105: หน่วยงานกลาง | J105: F213 DMCW-รชล-พระพุทธบาท | K105: 00000 หน่วยงานกลาง | L105: 923 | N105: 1A53003900 | O105: บมจ. ซีพี แอ็กซ์ตร้า สาขาสระบุรี | P105: 2 | Q105: MAKRO 0038 สระบุรี | R105: 244658 | S105: 14/5/2569 | T105: H6954RMA0059184 | U105: 23057812 | V105: สะโพก(M) | W105: 0 | X105: 0 | Y105: 0 | Z105: 0 | AA105: 0 | AB105: 0 | AC105: 0 | AD105: 0 | AE105: 0 | AF105: 0 | AI105: OPRCD489MOPRCD00000OPRCDF213OPRCD00000OPRCD923 | AJ105: ซื้อ / ขาย | AK105: Main proudct | AL105: Bulk Normal | AM105: สุกร | AN105: OT002 CC-Makro | AO105: MT | AP105: 2 | AT105: เบญจพจน์ เพชรเหลี่ยม | AU105: 2026-05-11-13.33.46.000000 | AV105: ก.ก. | AW105: ก.ก. | AY105: 0 | AZ105: N | BA105: 9044989536402 | BD105: 1 | BF105: ;0000 | BG105: 1333314600 | BH105: G | BI105: 0 | BJ105: 0 | BK105: 1300 | BL105: SYSBATCH
C106: 14/5/2569 | D106: 14/5/2569 | F106: 489M | G106: Modern Trade (Makro) | H106: 0 | I106: หน่วยงานกลาง | J106: F213 DMCW-รชล-พระพุทธบาท | K106: 00000 หน่วยงานกลาง | L106: 923 | N106: 1A53003900 | O106: บมจ. ซีพี แอ็กซ์ตร้า สาขาสระบุรี | P106: 2 | Q106: MAKRO 0038 สระบุรี | R106: 244658 | S106: 14/5/2569 | T106: H6954RMA0059184 | U106: 23015265 | V106: ซี่โครงหั่นชิ้น | W106: 30 | X106: 30 | Y106: 30 | Z106: 30 | AA106: 0 | AB106: 0 | AC106: 0 | AD106: 0 | AE106: 30 | AF106: 30 | AI106: OPRCD489MOPRCD00000OPRCDF213OPRCD00000OPRCD923 | AJ106: ซื้อ / ขาย | AK106: Main proudct | AL106: Bulk Normal | AM106: สุกร | AN106: OT002 CC-Makro | AO106: MT | AP106: 2 | AT106: เบญจพจน์ เพชรเหลี่ยม | AU106: 2026-05-11-13.33.46.000000 | AV106: ก.ก. | AW106: ก.ก. | AY106: 0 | AZ106: N | BA106: 9044989536402 | BD106: 1 | BF106: ;0000 | BG106: 1333314600 | BH106: G | BI106: 30 | BJ106: 30 | BK106: 1300 | BL106: SYSBATCH
C107: 14/5/2569 | D107: 14/5/2569 | F107: 489M | G107: Modern Trade (Makro) | H107: 0 | I107: หน่วยงานกลาง | J107: F213 DMCW-รชล-พระพุทธบาท | K107: 00000 หน่วยงานกลาง | L107: 923 | N107: 1A53003900 | O107: บมจ. ซีพี แอ็กซ์ตร้า สาขาสระบุรี | P107: 2 | Q107: MAKRO 0038 สระบุรี | R107: 244658 | S107: 14/5/2569 | T107: H6954RMA0059184 | U107: 23058555 | V107: กระดูกซุป (M) | W107: 40 | X107: 40 | Y107: 40 | Z107: 40 | AA107: 0 | AB107: 0 | AC107: 0 | AD107: 0 | AE107: 40 | AF107: 40 | AI107: OPRCD489MOPRCD00000OPRCDF213OPRCD00000OPRCD923 | AJ107: ซื้อ / ขาย | AK107: By proudct | AL107: Bulk Normal | AM107: สุกร | AN107: OT002 CC-Makro | AO107: MT | AP107: 2 | AT107: เบญจพจน์ เพชรเหลี่ยม | AU107: 2026-05-11-13.33.46.000000 | AV107: ก.ก. | AW107: ก.ก. | AY107: 0 | AZ107: N | BA107: 9044989536402 | BD107: 1 | BF107: ;0000 | BG107: 1333314600 | BH107: G | BI107: 40 | BJ107: 40 | BK107: 1300 | BL107: SYSBATCH
C108: 14/5/2569 | D108: 14/5/2569 | F108: 489M | G108: Modern Trade (Makro) | H108: 0 | I108: หน่วยงานกลาง | J108: F213 DMCW-รชล-พระพุทธบาท | K108: 00000 หน่วยงานกลาง | L108: 923 | N108: 1A53003900 | O108: บมจ. ซีพี แอ็กซ์ตร้า สาขาสระบุรี | P108: 2 | Q108: MAKRO 0038 สระบุรี | R108: 244658 | S108: 14/5/2569 | T108: H6954RMA0059184 | U108: 23065140 | V108: สะโพกสไลด์ | W108: 220 | X108: 220 | Y108: 220 | Z108: 220 | AA108: 0 | AB108: 0 | AC108: 0 | AD108: 0 | AE108: 220 | AF108: 220 | AI108: OPRCD489MOPRCD00000OPRCDF213OPRCD00000OPRCD923 | AJ108: ซื้อ / ขาย | AK108: Main proudct | AL108: Bulk Normal | AM108: สุกร | AN108: OT002 CC-Makro | AO108: MT | AP108: 2 | AT108: เบญจพจน์ เพชรเหลี่ยม | AU108: 2026-05-11-13.33.46.000000 | AV108: ก.ก. | AW108: ก.ก. | AY108: 0 | AZ108: N | BA108: 9044989536402 | BD108: 1 | BF108: ;0000 | BG108: 1333314600 | BH108: G | BI108: 220 | BJ108: 220 | BK108: 1300 | BL108: SYSBATCH
C109: 14/5/2569 | D109: 14/5/2569 | F109: 489M | G109: Modern Trade (Makro) | H109: 0 | I109: หน่วยงานกลาง | J109: F213 DMCW-รชล-พระพุทธบาท | K109: 00000 หน่วยงานกลาง | L109: 923 | N109: 1A53004800 | O109: บมจ. ซีพี แอ็กซ์ตร้า สาขาลพบุรี | P109: 2 | Q109: MAKRO 0047 ลพบุรี | R109: 244658 | S109: 14/5/2569 | T109: H6954RMA0059202 | U109: 23058551 | V109: คอหมูย่าง (M) | W109: 20 | X109: 20 | Y109: 20 | Z109: 20 | AA109: 0 | AB109: 0 | AC109: 0 | AD109: 0 | AE109: 20 | AF109: 20 | AI109: OPRCD489MOPRCD00000OPRCDF213OPRCD00000OPRCD923 | AJ109: ซื้อ / ขาย | AK109: Main proudct | AL109: Bulk Normal | AM109: สุกร | AN109: OT002 CC-Makro | AO109: MT | AP109: 2 | AT109: เบญจพจน์ เพชรเหลี่ยม | AU109: 2026-05-11-13.33.46.000000 | AV109: ก.ก. | AW109: ก.ก. | AY109: 0 | AZ109: N | BA109: 9044989536419 | BD109: 1 | BF109: ;0000 | BG109: 1333314600 | BH109: G | BI109: 20 | BJ109: 20 | BK109: 1300 | BL109: SYSBATCH
...

Sheet Mk หลังแก้
A1: ='mk 001 10.3'!A2 -> rDate1 | B1: ='mk 001 10.3'!B2 -> rDate2 | C1: ='mk 001 10.3'!C2 -> rRDate1 | D1: ='mk 001 10.3'!D2 -> rRDate2 | E1: ='mk 001 10.3'!E2 -> rRDate3 | F1: ='mk 001 10.3'!F2 -> rOper_code | G1: ='mk 001 10.3'!G2 -> rOper_name | H1: ='mk 001 10.3'!H2 -> rSub_oper | ... BN1: ='mk 001 10.3'!BN2 -> rLicense_plate
A2: ='mk 001 10.3'!A3 -> 0 | B2: ='mk 001 10.3'!B3 -> 0 | C2: ='mk 001 10.3'!C3 -> 14/5/2569 | D2: ='mk 001 10.3'!D3 -> 14/5/2569 | E2: ='mk 001 10.3'!E3 -> 0 | F2: ='mk 001 10.3'!F3 -> 489M | G2: ='mk 001 10.3'!G3 -> Modern Trade (Makro) | H2: ='mk 001 10.3'!H3 -> 0 | ... X2: ='mk 001 10.3'!X3 -> 20 | Y2: =IFERROR(W2*Z2/X2,0) -> 20 | Z2: =IF(COUNTIFS(แปลงข้อมูล!H:H,Q2,แปลงข้อมูล!I:I,U2,แปลงข้อมูล!J:J,V2)>0,SUMIFS(แปลงข้อมูล!Q:Q,แปลงข้อมูล!I:I,U2,แปลงข้อมูล!H:H,Q2,แปลงข้อมูล!J:J,V2),'mk 001 10.3'!Z3) -> 20 | AA2: ='mk 001 10.3'!AA3 -> 0 | AB2: ='mk 001 10.3'!AB3 -> 0 | AC2: ='mk 001 10.3'!AC3 -> 0 | AD2: ='mk 001 10.3'!AD3 -> 0 | AE2: ='mk 001 10.3'!AE3 -> 20 | AF2: ='mk 001 10.3'!AF3 -> 20 | AG2: ='mk 001 10.3'!AG3 -> 0 | AH2: ='mk 001 10.3'!AH3 -> 0 | ... BN2: ='mk 001 10.3'!BN3 -> 0
A3: ='mk 001 10.3'!A4 -> 0 | B3: ='mk 001 10.3'!B4 -> 0 | C3: ='mk 001 10.3'!C4 -> 14/5/2569 | D3: ='mk 001 10.3'!D4 -> 14/5/2569 | E3: ='mk 001 10.3'!E4 -> 0 | F3: ='mk 001 10.3'!F4 -> 489M | G3: ='mk 001 10.3'!G4 -> Modern Trade (Makro) | H3: ='mk 001 10.3'!H4 -> 0 | ... X3: ='mk 001 10.3'!X4 -> 130 | Y3: =IFERROR(W3*Z3/X3,0) -> 130 | Z3: =IF(COUNTIFS(แปลงข้อมูล!H:H,Q3,แปลงข้อมูล!I:I,U3,แปลงข้อมูล!J:J,V3)>0,SUMIFS(แปลงข้อมูล!Q:Q,แปลงข้อมูล!I:I,U3,แปลงข้อมูล!H:H,Q3,แปลงข้อมูล!J:J,V3),'mk 001 10.3'!Z4) -> 130 | AA3: ='mk 001 10.3'!AA4 -> 0 | AB3: ='mk 001 10.3'!AB4 -> 0 | AC3: ='mk 001 10.3'!AC4 -> 0 | AD3: ='mk 001 10.3'!AD4 -> 0 | AE3: ='mk 001 10.3'!AE4 -> 130 | AF3: ='mk 001 10.3'!AF4 -> 130 | AG3: ='mk 001 10.3'!AG4 -> 0 | AH3: ='mk 001 10.3'!AH4 -> 0 | ... BN3: ='mk 001 10.3'!BN4 -> 0
A4: ='mk 001 10.3'!A5 -> 0 | B4: ='mk 001 10.3'!B5 -> 0 | C4: ='mk 001 10.3'!C5 -> 14/5/2569 | D4: ='mk 001 10.3'!D5 -> 14/5/2569 | E4: ='mk 001 10.3'!E5 -> 0 | F4: ='mk 001 10.3'!F5 -> 489M | G4: ='mk 001 10.3'!G5 -> Modern Trade (Makro) | H4: ='mk 001 10.3'!H5 -> 0 | ... X4: ='mk 001 10.3'!X5 -> 90 | Y4: =IFERROR(W4*Z4/X4,0) -> 90 | Z4: =IF(COUNTIFS(แปลงข้อมูล!H:H,Q4,แปลงข้อมูล!I:I,U4,แปลงข้อมูล!J:J,V4)>0,SUMIFS(แปลงข้อมูล!Q:Q,แปลงข้อมูล!I:I,U4,แปลงข้อมูล!H:H,Q4,แปลงข้อมูล!J:J,V4),'mk 001 10.3'!Z5) -> 90 | AA4: ='mk 001 10.3'!AA5 -> 0 | AB4: ='mk 001 10.3'!AB5 -> 0 | AC4: ='mk 001 10.3'!AC5 -> 0 | AD4: ='mk 001 10.3'!AD5 -> 0 | AE4: ='mk 001 10.3'!AE5 -> 90 | AF4: ='mk 001 10.3'!AF5 -> 90 | AG4: ='mk 001 10.3'!AG5 -> 0 | AH4: ='mk 001 10.3'!AH5 -> 0 | ... BN4: ='mk 001 10.3'!BN5 -> 0
A5: ='mk 001 10.3'!A6 -> 0 | B5: ='mk 001 10.3'!B6 -> 0 | C5: ='mk 001 10.3'!C6 -> 14/5/2569 | D5: ='mk 001 10.3'!D6 -> 14/5/2569 | E5: ='mk 001 10.3'!E6 -> 0 | F5: ='mk 001 10.3'!F6 -> 489M | G5: ='mk 001 10.3'!G6 -> Modern Trade (Makro) | H5: ='mk 001 10.3'!H6 -> 0 | ... X5: ='mk 001 10.3'!X6 -> 80 | Y5: =IFERROR(W5*Z5/X5,0) -> 80 | Z5: =IF(COUNTIFS(แปลงข้อมูล!H:H,Q5,แปลงข้อมูล!I:I,U5,แปลงข้อมูล!J:J,V5)>0,SUMIFS(แปลงข้อมูล!Q:Q,แปลงข้อมูล!I:I,U5,แปลงข้อมูล!H:H,Q5,แปลงข้อมูล!J:J,V5),'mk 001 10.3'!Z6) -> 80 | AA5: ='mk 001 10.3'!AA6 -> 0 | AB5: ='mk 001 10.3'!AB6 -> 0 | AC5: ='mk 001 10.3'!AC6 -> 0 | AD5: ='mk 001 10.3'!AD6 -> 0 | AE5: ='mk 001 10.3'!AE6 -> 80 | AF5: ='mk 001 10.3'!AF6 -> 80 | AG5: ='mk 001 10.3'!AG6 -> 0 | AH5: ='mk 001 10.3'!AH6 -> 0 | ... BN5: ='mk 001 10.3'!BN6 -> 0
A6: ='mk 001 10.3'!A7 -> 0 | B6: ='mk 001 10.3'!B7 -> 0 | C6: ='mk 001 10.3'!C7 -> 14/5/2569 | D6: ='mk 001 10.3'!D7 -> 14/5/2569 | E6: ='mk 001 10.3'!E7 -> 0 | F6: ='mk 001 10.3'!F7 -> 489M | G6: ='mk 001 10.3'!G7 -> Modern Trade (Makro) | H6: ='mk 001 10.3'!H7 -> 0 | ... X6: ='mk 001 10.3'!X7 -> 0 | Y6: =IFERROR(W6*Z6/X6,0) -> 0 | Z6: =IF(COUNTIFS(แปลงข้อมูล!H:H,Q6,แปลงข้อมูล!I:I,U6,แปลงข้อมูล!J:J,V6)>0,SUMIFS(แปลงข้อมูล!Q:Q,แปลงข้อมูล!I:I,U6,แปลงข้อมูล!H:H,Q6,แปลงข้อมูล!J:J,V6),'mk 001 10.3'!Z7) -> 0 | AA6: ='mk 001 10.3'!AA7 -> 0 | AB6: ='mk 001 10.3'!AB7 -> 0 | AC6: ='mk 001 10.3'!AC7 -> 0 | AD6: ='mk 001 10.3'!AD7 -> 0 | AE6: ='mk 001 10.3'!AE7 -> 0 | AF6: ='mk 001 10.3'!AF7 -> 0 | AG6: ='mk 001 10.3'!AG7 -> 0 | AH6: ='mk 001 10.3'!AH7 -> 0 | ... BN6: ='mk 001 10.3'!BN7 -> 0
A7: ='mk 001 10.3'!A8 -> 0 | B7: ='mk 001 10.3'!B8 -> 0 | C7: ='mk 001 10.3'!C8 -> 14/5/2569 | D7: ='mk 001 10.3'!D8 -> 14/5/2569 | E7: ='mk 001 10.3'!E8 -> 0 | F7: ='mk 001 10.3'!F8 -> 489M | G7: ='mk 001 10.3'!G8 -> Modern Trade (Makro) | H7: ='mk 001 10.3'!H8 -> 0 | ... X7: ='mk 001 10.3'!X8 -> 0 | Y7: =IFERROR(W7*Z7/X7,0) -> 0 | Z7: =IF(COUNTIFS(แปลงข้อมูล!H:H,Q7,แปลงข้อมูล!I:I,U7,แปลงข้อมูล!J:J,V7)>0,SUMIFS(แปลงข้อมูล!Q:Q,แปลงข้อมูล!I:I,U7,แปลงข้อมูล!H:H,Q7,แปลงข้อมูล!J:J,V7),'mk 001 10.3'!Z8) -> 0 | AA7: ='mk 001 10.3'!AA8 -> 0 | AB7: ='mk 001 10.3'!AB8 -> 0 | AC7: ='mk 001 10.3'!AC8 -> 0 | AD7: ='mk 001 10.3'!AD8 -> 0 | AE7: ='mk 001 10.3'!AE8 -> 0 | AF7: ='mk 001 10.3'!AF8 -> 0 | AG7: ='mk 001 10.3'!AG8 -> 0 | AH7: ='mk 001 10.3'!AH8 -> 0 | ... BN7: ='mk 001 10.3'!BN8 -> 0
A8: ='mk 001 10.3'!A9 -> 0 | B8: ='mk 001 10.3'!B9 -> 0 | C8: ='mk 001 10.3'!C9 -> 14/5/2569 | D8: ='mk 001 10.3'!D9 -> 14/5/2569 | E8: ='mk 001 10.3'!E9 -> 0 | F8: ='mk 001 10.3'!F9 -> 489M | G8: ='mk 001 10.3'!G9 -> Modern Trade (Makro) | H8: ='mk 001 10.3'!H9 -> 0 | ... X8: ='mk 001 10.3'!X9 -> 10 | Y8: =IFERROR(W8*Z8/X8,0) -> 10 | Z8: =IF(COUNTIFS(แปลงข้อมูล!H:H,Q8,แปลงข้อมูล!I:I,U8,แปลงข้อมูล!J:J,V8)>0,SUMIFS(แปลงข้อมูล!Q:Q,แปลงข้อมูล!I:I,U8,แปลงข้อมูล!H:H,Q8,แปลงข้อมูล!J:J,V8),'mk 001 10.3'!Z9) -> 10 | AA8: ='mk 001 10.3'!AA9 -> 0 | AB8: ='mk 001 10.3'!AB9 -> 0 | AC8: ='mk 001 10.3'!AC9 -> 0 | AD8: ='mk 001 10.3'!AD9 -> 0 | AE8: ='mk 001 10.3'!AE9 -> 10 | AF8: ='mk 001 10.3'!AF9 -> 10 | AG8: ='mk 001 10.3'!AG9 -> 0 | AH8: ='mk 001 10.3'!AH9 -> 0 | ... BN8: ='mk 001 10.3'!BN9 -> 0
A9: ='mk 001 10.3'!A10 -> 0 | B9: ='mk 001 10.3'!B10 -> 0 | C9: ='mk 001 10.3'!C10 -> 14/5/2569 | D9: ='mk 001 10.3'!D10 -> 14/5/2569 | E9: ='mk 001 10.3'!E10 -> 0 | F9: ='mk 001 10.3'!F10 -> 489M | G9: ='mk 001 10.3'!G10 -> Modern Trade (Makro) | H9: ='mk 001 10.3'!H10 -> 0 | ... X9: ='mk 001 10.3'!X10 -> 0 | Y9: =IFERROR(W9*Z9/X9,0) -> 0 | Z9: =IF(COUNTIFS(แปลงข้อมูล!H:H,Q9,แปลงข้อมูล!I:I,U9,แปลงข้อมูล!J:J,V9)>0,SUMIFS(แปลงข้อมูล!Q:Q,แปลงข้อมูล!I:I,U9,แปลงข้อมูล!H:H,Q9,แปลงข้อมูล!J:J,V9),'mk 001 10.3'!Z10) -> 0 | AA9: ='mk 001 10.3'!AA10 -> 0 | AB9: ='mk 001 10.3'!AB10 -> 0 | AC9: ='mk 001 10.3'!AC10 -> 0 | AD9: ='mk 001 10.3'!AD10 -> 0 | AE9: ='mk 001 10.3'!AE10 -> 0 | AF9: ='mk 001 10.3'!AF10 -> 0 | AG9: ='mk 001 10.3'!AG10 -> 0 | AH9: ='mk 001 10.3'!AH10 -> 0 | ... BN9: ='mk 001 10.3'!BN10 -> 0
A10: ='mk 001 10.3'!A11 -> 0 | B10: ='mk 001 10.3'!B11 -> 0 | C10: ='mk 001 10.3'!C11 -> 14/5/2569 | D10: ='mk 001 10.3'!D11 -> 14/5/2569 | E10: ='mk 001 10.3'!E11 -> 0 | F10: ='mk 001 10.3'!F11 -> 489M | G10: ='mk 001 10.3'!G11 -> Modern Trade (Makro) | H10: ='mk 001 10.3'!H11 -> 0 | ... X10: ='mk 001 10.3'!X11 -> 0 | Y10: =IFERROR(W10*Z10/X10,0) -> 0 | Z10: =IF(COUNTIFS(แปลงข้อมูล!H:H,Q10,แปลงข้อมูล!I:I,U10,แปลงข้อมูล!J:J,V10)>0,SUMIFS(แปลงข้อมูล!Q:Q,แปลงข้อมูล!I:I,U10,แปลงข้อมูล!H:H,Q10,แปลงข้อมูล!J:J,V10),'mk 001 10.3'!Z11) -> 0 | AA10: ='mk 001 10.3'!AA11 -> 0 | AB10: ='mk 001 10.3'!AB11 -> 0 | AC10: ='mk 001 10.3'!AC11 -> 0 | AD10: ='mk 001 10.3'!AD11 -> 0 | AE10: ='mk 001 10.3'!AE11 -> 0 | AF10: ='mk 001 10.3'!AF11 -> 0 | AG10: ='mk 001 10.3'!AG11 -> 0 | AH10: ='mk 001 10.3'!AH11 -> 0 | ... BN10: ='mk 001 10.3'!BN11 -> 0
A11: ='mk 001 10.3'!A12 -> 0 | B11: ='mk 001 10.3'!B12 -> 0 | C11: ='mk 001 10.3'!C12 -> 14/5/2569 | D11: ='mk 001 10.3'!D12 -> 14/5/2569 | E11: ='mk 001 10.3'!E12 -> 0 | F11: ='mk 001 10.3'!F12 -> 489M | G11: ='mk 001 10.3'!G12 -> Modern Trade (Makro) | H11: ='mk 001 10.3'!H12 -> 0 | ... X11: ='mk 001 10.3'!X12 -> 0 | Y11: =IFERROR(W11*Z11/X11,0) -> 0 | Z11: =IF(COUNTIFS(แปลงข้อมูล!H:H,Q11,แปลงข้อมูล!I:I,U11,แปลงข้อมูล!J:J,V11)>0,SUMIFS(แปลงข้อมูล!Q:Q,แปลงข้อมูล!I:I,U11,แปลงข้อมูล!H:H,Q11,แปลงข้อมูล!J:J,V11),'mk 001 10.3'!Z12) -> 0 | AA11: ='mk 001 10.3'!AA12 -> 0 | AB11: ='mk 001 10.3'!AB12 -> 0 | AC11: ='mk 001 10.3'!AC12 -> 0 | AD11: ='mk 001 10.3'!AD12 -> 0 | AE11: ='mk 001 10.3'!AE12 -> 0 | AF11: ='mk 001 10.3'!AF12 -> 0 | AG11: ='mk 001 10.3'!AG12 -> 0 | AH11: ='mk 001 10.3'!AH12 -> 0 | ... BN11: ='mk 001 10.3'!BN12 -> 0
A12: ='mk 001 10.3'!A13 -> 0 | B12: ='mk 001 10.3'!B13 -> 0 | C12: ='mk 001 10.3'!C13 -> 14/5/2569 | D12: ='mk 001 10.3'!D13 -> 14/5/2569 | E12: ='mk 001 10.3'!E13 -> 0 | F12: ='mk 001 10.3'!F13 -> 489M | G12: ='mk 001 10.3'!G13 -> Modern Trade (Makro) | H12: ='mk 001 10.3'!H13 -> 0 | ... X12: ='mk 001 10.3'!X13 -> 5 | Y12: =IFERROR(W12*Z12/X12,0) -> 5 | Z12: =IF(COUNTIFS(แปลงข้อมูล!H:H,Q12,แปลงข้อมูล!I:I,U12,แปลงข้อมูล!J:J,V12)>0,SUMIFS(แปลงข้อมูล!Q:Q,แปลงข้อมูล!I:I,U12,แปลงข้อมูล!H:H,Q12,แปลงข้อมูล!J:J,V12),'mk 001 10.3'!Z13) -> 5 | AA12: ='mk 001 10.3'!AA13 -> 0 | AB12: ='mk 001 10.3'!AB13 -> 0 | AC12: ='mk 001 10.3'!AC13 -> 0 | AD12: ='mk 001 10.3'!AD13 -> 0 | AE12: ='mk 001 10.3'!AE13 -> 5 | AF12: ='mk 001 10.3'!AF13 -> 5 | AG12: ='mk 001 10.3'!AG13 -> 0 | AH12: ='mk 001 10.3'!AH13 -> 0 | ... BN12: ='mk 001 10.3'!BN13 -> 0
A13: ='mk 001 10.3'!A14 -> 0 | B13: ='mk 001 10.3'!B14 -> 0 | C13: ='mk 001 10.3'!C14 -> 14/5/2569 | D13: ='mk 001 10.3'!D14 -> 14/5/2569 | E13: ='mk 001 10.3'!E14 -> 0 | F13: ='mk 001 10.3'!F14 -> 489M | G13: ='mk 001 10.3'!G14 -> Modern Trade (Makro) | H13: ='mk 001 10.3'!H14 -> 0 | ... X13: ='mk 001 10.3'!X14 -> 5 | Y13: =IFERROR(W13*Z13/X13,0) -> 5 | Z13: =IF(COUNTIFS(แปลงข้อมูล!H:H,Q13,แปลงข้อมูล!I:I,U13,แปลงข้อมูล!J:J,V13)>0,SUMIFS(แปลงข้อมูล!Q:Q,แปลงข้อมูล!I:I,U13,แปลงข้อมูล!H:H,Q13,แปลงข้อมูล!J:J,V13),'mk 001 10.3'!Z14) -> 5 | AA13: ='mk 001 10.3'!AA14 -> 0 | AB13: ='mk 001 10.3'!AB14 -> 0 | AC13: ='mk 001 10.3'!AC14 -> 0 | AD13: ='mk 001 10.3'!AD14 -> 0 | AE13: ='mk 001 10.3'!AE14 -> 5 | AF13: ='mk 001 10.3'!AF14 -> 5 | AG13: ='mk 001 10.3'!AG14 -> 0 | AH13: ='mk 001 10.3'!AH14 -> 0 | ... BN13: ='mk 001 10.3'!BN14 -> 0
... A500: ='mk 001 10.3'!A501 -> 0 | B500: ='mk 001 10.3'!B501 -> 0 | C500: ='mk 001 10.3'!C501 -> 0 | D500: ='mk 001 10.3'!D501 -> 0 | E500: ='mk 001 10.3'!E501 -> 0 | F500: ='mk 001 10.3'!F501 -> 0 | G500: ='mk 001 10.3'!G501 -> 0 | H500: ='mk 001 10.3'!H501 -> 0 | ... X500: ='mk 001 10.3'!X501 -> 0 | Y500: =IFERROR(W500*Z500/X500,0) -> 0 | Z500: =IF(COUNTIFS(แปลงข้อมูล!H:H,Q500,แปลงข้อมูล!I:I,U500,แปลงข้อมูล!J:J,V500)>0,SUMIFS(แปลงข้อมูล!Q:Q,แปลงข้อมูล!I:I,U500,แปลงข้อมูล!H:H,Q500,แปลงข้อมูล!J:J,V500),'mk 001 10.3'!Z501) -> 0 | AA500: ='mk 001 10.3'!AA501 -> 0 | AB500: ='mk 001 10.3'!AB501 -> 0 | AC500: ='mk 001 10.3'!AC501 -> 0 | AD500: ='mk 001 10.3'!AD501 -> 0 | AE500: ='mk 001 10.3'!AE501 -> 0 | AF500: ='mk 001 10.3'!AF501 -> 0 | AG500: ='mk 001 10.3'!AG501 -> 0 | AH500: ='mk 001 10.3'!AH501 -> 0 | ... BN500: ='mk 001 10.3'!BN501 -> 0
A502: {=_xlfn.UNIQUE(_xlfn._xlws.FILTER('เพิ่ม SO'!A1:BN200, 'เพิ่ม SO'!Q1:Q200<>""))} -> #VALUE!

Sheet Sheet1 (2)
A2: rOper_name | B2: Modern Trade (Makro)
A3: rBst_code | B3: 923
A4: rProduct_group_code2 | B4: (ทั้งหมด)
A5: rPO_no | B5: (ทั้งหมด)
A6: rProduct_code | B6: (ทั้งหมด)
A7: rReq_date | B7: 14/5/2569
A8: rProduct_name | B8: (ทั้งหมด)
A9: rDoc_number | B9: (ทั้งหมด)
B10: =+Sheet1!B8 -> คืน 13.5
A11: Sum of rPlan_wgt
A12: rShip_name | B12: ผลรวม
A13: MAKRO 0038 สระบุรี | B13: 680
A14: MAKRO 0047 ลพบุรี | B14: 2046.2
A15: MAKRO 0083 นครอินทร์ | B15: 452.4
A16: MAKRO 0096 ทาวน์ อิน ทาวน์ | B16: 705
A17: MAKRO 0164 สาขาชัยนาท | B17: 1450.6
A18: MAKRO 0114 สิงห์บุรี | B18: 1636.5998
A19: MAKRO 0051 อยุธยา | B19: 2846.2
A20: ผลรวมทั้งหมด | B20: 9816.9998

Sheet Sheet1 (3)
A2: rOper_name | B2: Modern Trade (Makro)
A3: rBst_code | B3: 923
A4: rProduct_group_code2 | B4: (หลายรายการ)
A5: rPO_no | B5: (ทั้งหมด)
A6: rProduct_code | B6: (ทั้งหมด)
A7: rReq_date | B7: 14/5/2569
A8: rProduct_name | B8: (ทั้งหมด)
A9: rDoc_number | B9: (ทั้งหมด)
B10: =+Sheet1!B8 -> คืน 13.5
A11: Sum of rPlan_wgt
A12: rShip_name | B12: ผลรวม | C12: คัน
A13: MAKRO 0047 ลพบุรี | B13: 11.2 | C13: 1
A14: MAKRO 0083 นครอินทร์ | B14: 21.4 | C14: 2
A15: MAKRO 0164 สาขาชัยนาท | B15: 5.6 | C15: 1
A16: MAKRO 0114 สิงห์บุรี | B16: 89.6
A17: MAKRO 0051 อยุธยา | B17: 11.2
A18: ผลรวมทั้งหมด | B18: 139

Sheet Sheet1 (4)
A2: rBst_code | B2: 923
A3: rOper_name | B3: (ทั้งหมด)
A4: rPO_no | B4: (ทั้งหมด)
A5: rReq_date | B5: 14/5/2569
A6: rProduct_group_code2 | B6: (หลายรายการ)
A7: rDoc_number | B7: (ทั้งหมด)
B8: =+Sheet1!B8 -> คืน 13.5
D9: Values
A10: rShip_name | B10: rProduct_code | C10: rProduct_name | D10: Sum of rPlan_qty | E10: Sum of rPlan_wgt
A11: MAKRO 0047 ลพบุรี | B11: 23084674 | C11: เลือดหมูก้อนปรุงรสพาสเจอร์ไรซ์400กรัม-C | D11: 28 | E11: 11.2
A12: MAKRO 0083 นครอินทร์ | B12: 23084674 | C12: เลือดหมูก้อนปรุงรสพาสเจอร์ไรซ์400กรัม-C | D12: 14 | E12: 5.6
B13: 23109351 | C13: สามชั้นหมูชีวาสไลซ์(ตรา ยูฟาร์ม)250 กรัม | D13: 4 | E13: 1
B14: 23109352 | C14: สันนอกหมูชีวาสไลซ์(ตรา ยูฟาร์ม) 250 กรัม | D14: 12 | E14: 3
B15: 23109353 | C15: สันคอหมูชีวาสไลซ์(ตรา ยูฟาร์ม) 250 กรัม | D15: 12 | E15: 3
B16: 23109357 | C16: สะโพกหมูชีวา (ตรา ยูฟาร์ม) 400 กรัม | D16: 2 | E16: 0.8
B17: 23109358 | C17: สามชั้นหมูชีวา (ตรา ยูฟาร์ม) 400 กรัม | D17: 4 | E17: 1.6
B18: 23109359 | C18: หมูชีวาบด (ตรา ยูฟาร์ม) 400 กรัม | D18: 12 | E18: 4.8
B19: 23109532 | C19: ตับหมูชีวา 400 กรัม | D19: 4 | E19: 1.6
A20: MAKRO 0164 สาขาชัยนาท | B20: 23084674 | C20: เลือดหมูก้อนปรุงรสพาสเจอร์ไรซ์400กรัม-C | D20: 14 | E20: 5.6
A21: MAKRO 0114 สิงห์บุรี | B21: 23084674 | C21: เลือดหมูก้อนปรุงรสพาสเจอร์ไรซ์400กรัม-C | D21: 14 | E21: 5.6
B22: 23110584 | C22: หมูบด ผสมมัน 30% แพ็คถาด 1 กก. | D22: 4 | E22: 4
B23: 23110587 | C23: สะโพกหมูสไลซ์ แพ็คถาด 1 กก. | D23: 4 | E23: 4
B24: 23110590 | C24: หมูบด ผสมมัน 10% แพ็คถาด 1 กก. | D24: 4 | E24: 4
B25: 23110593 | C25: สันนอกหมูสดสไลซ์ แพ็คถาด 1 กก. | D25: 4 | E25: 4
B26: 23110595 | C26: สามชั้นหมูสดสไลซ์ แพ็คถาด 1 กก. | D26: 4 | E26: 4
B27: 23110600 | C27: สันคอหมูสดสไลซ์ แพ็คถาด 1 กก. | D27: 4 | E27: 4
B28: 23111028 | C28: หมูบด ผสมมัน 30% แพ็คถาด 500 กรัม | D28: 4 | E28: 2
B29: 23111033 | C29: สามชั้นหมูสดสไลซ์แพ็คถาด 500 กรัม | D29: 12 | E29: 6
B30: 23111034 | C30: สันคอหมูสดสไลซ์ แพ็คถาด 500 กรัม | D30: 8 | E30: 4
B31: 23111035 | C31: สันนอกหมูสดสไลซ์ แพ็คถาด 500 กรัม | D31: 8 | E31: 4
B32: 23111036 | C32: สะโพกหมูสไลซ์ แพ็คถาด 500 กรัม | D32: 8 | E32: 4
B33: 23111037 | C33: หมูบด ผสมมัน 10% แพ็คถาด 500 กรัม | D33: 8 | E33: 4
... B45: 23110624 | C45: เครื่องในหมูรวม แพ็คถาด 500 กรัม | D45: 4 | E45: 2
A46: MAKRO 0051 อยุธยา | B46: 23084674 | C46: เลือดหมูก้อนปรุงรสพาสเจอร์ไรซ์400กรัม-C | D46: 28 | E46: 11.2
A47: ผลรวมทั้งหมด | D47: 268 | E47: 139

Sheet Sheet1 (8)
A1: rOper_name | B1: Modern Trade (Makro)
A2: rBst_code | B2: 923
A3: rProduct_group_code2 | B3: (ทั้งหมด)
A4: rShip_name | B4: MAKRO 0164 สาขาชัยนาท
A5: rPO_no | B5: (ทั้งหมด)
A6: rReq_date | B6: 14/5/2569
A7: rDoc_number | B7: (ทั้งหมด)
B8: =+Sheet1!B8 -> คืน 13.5
A9: Sum of rPlan_wgt
A10: rProduct_code | B10: rProduct_name | C10: ผลรวม
A11: 23000206 | B11: ชิ้นมันคอ | C11: 5
A12: 23057809 | B12: เนื้อไหล่(M) | C12: 30
A13: 23057812 | B13: สะโพก(M) | C13: 130
A14: 23057815 | B14: สันนอก(M) | C14: 100
A15: 23057818 | B15: สันใน(M) | C15: 0
A16: 23057821 | B16: สันคอ(M) | C16: 20
A17: 23057824 | B17: สามชั้น(M) | C17: 80
A18: 23058551 | B18: คอหมูย่าง (M) | C18: 5
A19: 23058552 | B19: มันสันหลัง (M) | C19: 0
A20: 23058553 | B20: หนังสันหลัง (M) | C20: 110
A21: 23058555 | B21: กระดูกซุป (M) | C21: 70
A22: 23058584 | B22: ตับหมู (M) | C22: 20
... A61: 23098991 | B61: พอร์คชอพตัดสเต็ก กก.ละ | C61: 0
A62: ผลรวมทั้งหมด | C62: 1450.6

Sheet Sheet1 (6)
A3: rOper_name | B3: Modern Trade (Makro)
A4: rBst_code | B4: 923
A5: rProduct_group_code2 | B5: (ทั้งหมด)
A6: rShip_name | B6: MAKRO 0038 สระบุรี
A7: rReq_date | B7: 14/5/2569
B8: =+Sheet1!B8 -> คืน 13.5
A9: Sum of rPlan_wgt | C9: rDoc_number | D9: rPO_no
C10: H6954RMA0059184 | D10: ผลรวมทั้งหมด
A11: rProduct_code | B11: rProduct_name | C11: 9044989536402
A12: 23015265 | B12: ซี่โครงหั่นชิ้น | C12: 30 | D12: 30
A13: 23057812 | B13: สะโพก(M) | C13: 0 | D13: 0
A14: 23057821 | B14: สันคอ(M) | C14: 0 | D14: 0
A15: 23058555 | B15: กระดูกซุป (M) | C15: 40 | D15: 40
A16: 23062095 | B16: หน้ากากหมูเผา(M) | C16: 20 | D16: 20
A17: 23065140 | B17: สะโพกสไลด์ | C17: 220 | D17: 220
A18: 23065141 | B18: สันนอกสไลด์ | C18: 30 | D18: 30
A19: 23065142 | B19: สันคอสไลด์ | C19: 20 | D19: 20
A20: 23065143 | B20: สามชั้นสไลด์ | C20: 180 | D20: 180
A21: 23068390 | B21: กระดูกซุปติดเนื้อพิเศษ(M) | C21: 40 | D21: 40
A22: 23108462 | B22: หมูบดปนมัน 30% แพ็ค กก.(M) | C22: 100 | D22: 100
A23: ผลรวมทั้งหมด | C23: 680 | D23: 680

Sheet Sheet1 (7)
A2: rOper_name | B2: (ทั้งหมด)
A3: rBst_code | B3: 923
A4: rProduct_group_code2 | B4: (ทั้งหมด)
A5: rPO_no | B5: (ทั้งหมด)
A6: rReq_date | B6: 14/5/2569
A7: rDoc_number | B7: (ทั้งหมด)
B8: =+Sheet1!B8 -> คืน 13.5
A9: Sum of rPlan_wgt | C9: rShip_name
A10: rProduct_code | B10: rProduct_name | C10: MAKRO 0038 สระบุรี | D10: MAKRO 0047 ลพบุรี | E10: MAKRO 0083 นครอินทร์ | F10: MAKRO 0096 ทาวน์ อิน ทาวน์ | G10: MAKRO 0164 สาขาชัยนาท | H10: MAKRO 0114 สิงห์บุรี | I10: MAKRO 0051 อยุธยา | J10: ผลรวมทั้งหมด
A11: 23000206 | B11: ชิ้นมันคอ | D11: 5 | G11: 5 | I11: 10 | J11: 20
A12: 23015265 | B12: ซี่โครงหั่นชิ้น | C12: 30 | D12: 50 | H12: 20 | J12: 100
A13: 23057809 | B13: เนื้อไหล่(M) | D13: 90 | F13: 70 | G13: 30 | H13: 100 | J13: 290
A14: 23057812 | B14: สะโพก(M) | C14: 0 | D14: 200 | F14: 100 | G14: 130 | H14: 300 | I14: 400 | J14: 1130
A15: 23057815 | B15: สันนอก(M) | D15: 100 | F15: 40 | G15: 100 | H15: 200 | I15: 100 | J15: 540
A16: 23057818 | B16: สันใน(M) | F16: 5 | G16: 0 | H16: 10 | I16: 60 | J16: 75
A17: 23057821 | B17: สันคอ(M) | C17: 0 | D17: 40 | F17: 5 | G17: 20 | H17: 0 | I17: 100 | J17: 165
A18: 23057824 | B18: สามชั้น(M) | D18: 50 | G18: 80 | I18: 100 | J18: 230
A19: 23057827 | B19: ซี่โครง(M) | D19: 0 | E19: 5 | J19: 5
A20: 23058551 | B20: คอหมูย่าง (M) | D20: 20 | F20: 5 | G20: 5 | H20: 20 | I20: 100 | J20: 150
A21: 23058552 | B21: มันสันหลัง (M) | D21: 20 | F21: 10 | G21: 0 | H21: 20 | I21: 40 | J21: 90
A22: 23058553 | B22: หนังสันหลัง (M) | G22: 110 | H22: 300 | I22: 10 | J22: 420
A23: 23058555 | B23: กระดูกซุป (M) | C23: 40 | D23: 140 | F23: 50 | G23: 70 | H23: 0 | I23: 250 | J23: 550
A24: 23058584 | B24: ตับหมู (M) | D24: 30 | F24: 10 | G24: 20 | H24: 20 | I24: 100 | J24: 180
A25: 23058585 | B25: ขั้วตับ (M) | G25: 10 | H25: 5 | J25: 15
A26: 23058586 | B26: ไต (M) | G26: 5 | I26: 5 | J26: 10
A27: 23058587 | B27: หัวใจหมู (M) | G27: 0 | H27: 5 | J27: 5
A28: 23058589 | B28: ไส้อ่อน (M) | D28: 20 | F28: 5 | G28: 5 | H28: 10 | I28: 40 | J28: 80
A29: 23058590 | B29: ไส้ใหญ่(ลวก) (M) | G29: 5 | H29: 120 | I29: 10 | J29: 135
A30: 23058591 | B30: กระดูกข้อ(คาตั๊ง) (M) | D30: 20 | E30: 20 | G30: 20 | H30: 20 | I30: 20 | J30: 100
A31: 23062095 | B31: หน้ากากหมูเผา(M) | C31: 20 | D31: 5 | G31: 5 | J31: 30
A32: 23062105 | B32: ไส้ตันลวก(M) | G32: 0 | H32: 5 | J32: 5
A33: 23063759 | B33: ขาหลังเผา(M) | F33: 160 | G33: 0 | J33: 160
A34: 23065140 | B34: สะโพกสไลด์ | C34: 220 | D34: 400 | F34: 30 | G34: 40 | I34: 100 | J34: 790
A35: 23065141 | B35: สันนอกสไลด์ | C35: 30 | G35: 15 | H35: 10 | J35: 55
A36: 23065142 | B36: สันคอสไลด์ | C36: 20 | F36: 10 | G36: 20 | H36: 10 | J36: 60
A37: 23065143 | B37: สามชั้นสไลด์ | C37: 180 | D37: 400 | F37: 20 | G37: 90 | H37: 0 | I37: 80 | J37: 770
A38: 23066875 | B38: ไส้ขม(M) | D38: 20 | J38: 20
A39: 23066879 | B39: กระดูกอ่อน(M) | F39: 5 | G39: 10 | H39: 10 | I39: 50 | J39: 75
A40: 23068390 | B40: กระดูกซุปติดเนื้อพิเศษ(M) | C40: 40 | J40: 40
A41: 23070475 | B41: สามชั้นหมูตัดเส้น 3-4 นิ้ว | E41: 40 | F41: 60 | H41: 5 | J41: 105
...

Sheet แผน Makro 100%
B1: rOper_name | C1: (ทั้งหมด)
B2: rBst_code | C2: 923
B3: rProduct_group_code2 | C3: (ทั้งหมด)
B4: rPO_no | C4: (ทั้งหมด)
B5: rReq_date | C5: 14/5/2569
B6: rDoc_number | C6: (ทั้งหมด)
C7: คืน 13.5
B8: Sum of rPlan_wgt | D8: rShip_name
A9: สายพาน | B9: rProduct_code | C9: rProduct_name | D9: MAKRO 0038 สระบุรี | E9: MAKRO 0047 ลพบุรี | F9: MAKRO 0083 นครอินทร์ | G9: MAKRO 0096 ทาวน์ อิน ทาวน์ | H9: MAKRO 0164 สาขาชัยนาท | I9: MAKRO 0114 สิงห์บุรี | J9: MAKRO 0051 อยุธยา | K9: ผลรวมทั้งหมด
A10: =IF(B10="Grand Total","Grand Total",IFERROR(VLOOKUP(B10,Master!$D$1:$G$1720,4,FALSE),"")) -> สามชั้นพิเศษ | B10: 23015198 | C10: พอร์คช็อป | I10: 0 | K10: =+SUM(D10:J10) -> 0
A11: =IF(B11="Grand Total","Grand Total",IFERROR(VLOOKUP(B11,Master!$D$1:$G$1720,4,FALSE),"")) -> สามชั้นพิเศษ | B11: 23015265 | C11: ซี่โครงหั่นชิ้น | D11: 30 | E11: 50 | I11: 20 | K11: =+SUM(D11:J11) -> 100
A12: =IF(B12="Grand Total","Grand Total",IFERROR(VLOOKUP(B12,Master!$D$1:$G$1720,4,FALSE),"")) -> สามชั้นพิเศษ | B12: 23058553 | C12: หนังสันหลัง (M) | H12: 110 | I12: 300 | J12: 10 | K12: =+SUM(D12:J12) -> 420
A13: =IF(B13="Grand Total","Grand Total",IFERROR(VLOOKUP(B13,Master!$D$1:$G$1720,4,FALSE),"")) -> สามชั้นพิเศษ | B13: 23070475 | C13: สามชั้นหมูตัดเส้น 3-4 นิ้ว | F13: 40 | G13: 60 | I13: 5 | K13: =+SUM(D13:J13) -> 105
A14: =IF(B14="Grand Total","Grand Total",IFERROR(VLOOKUP(B14,Master!$D$1:$G$1720,4,FALSE),"")) -> สามชั้นพิเศษ | B14: 23071882 | C14: ซี่โครงหมูสไลด์รวม (M) | G14: 40 | K14: =+SUM(D14:J14) -> 40
A15: =IF(B15="Grand Total","Grand Total",IFERROR(VLOOKUP(B15,Master!$D$1:$G$1720,4,FALSE),"")) -> สามชั้นพิเศษ | B15: 23073308 | C15: สามชั้นหมูตัดเส้น 1-2 นิ้ว(M) | J15: 50 | K15: =+SUM(D15:J15) -> 50
A16: =IF(B16="Grand Total","Grand Total",IFERROR(VLOOKUP(B16,Master!$D$1:$G$1720,4,FALSE),"")) -> สามชั้นพิเศษ | B16: 23075089 | C16: มันตัดเส้น(M) | H16: 0 | K16: =+SUM(D16:J16) -> 0
A17: =IF(B17="Grand Total","Grand Total",IFERROR(VLOOKUP(B17,Master!$D$1:$G$1720,4,FALSE),"")) -> สามชั้นพิเศษ | B17: 23097796 | C17: สามชั้นหมูตัดเส้น 1 กก. (M) | I17: 5 | K17: =+SUM(D17:J17) -> 5
A18: =IF(B18="Grand Total","Grand Total",IFERROR(VLOOKUP(B18,Master!$D$1:$G$1720,4,FALSE),"")) -> สามชั้นพิเศษ | B18: 23098990 | C18: สามชั้นหั่นพะโล้ กก.ละ | I18: 5 | K18: =+SUM(D18:J18) -> 5
A19: =IF(B19="Grand Total","Grand Total",IFERROR(VLOOKUP(B19,Master!$D$1:$G$1720,4,FALSE),"")) -> สามชั้นพิเศษ | B19: 23098991 | C19: พอร์คชอพตัดสเต็ก กก.ละ | H19: 0 | K19: =+SUM(D19:J19) -> 0
A20: =IF(B20="Grand Total","Grand Total",IFERROR(VLOOKUP(B20,Master!$D$1:$G$1720,4,FALSE),"")) -> สามชั้นพิเศษ | B20: 23098995 | C20: มันหั่นเต๋า กก ละ | E20: 70 | H20: 20 | I20: 0 | K20: =+SUM(D20:J20) -> 90
A21: =IF(B21="Grand Total","Grand Total",IFERROR(VLOOKUP(B21,Master!$D$1:$G$1720,4,FALSE),"")) -> สามชั้นพิเศษ | B21: 23109358 | C21: สามชั้นหมูชีวา (ตรา ยูฟาร์ม) 400 กรัม | F21: 1.6 | K21: =+SUM(D21:J21) -> 1.6
A22: =IF(B22="Grand Total","Grand Total",IFERROR(VLOOKUP(B22,Master!$D$1:$G$1720,4,FALSE),"")) -> สามชั้นพิเศษ | B22: 23110596 | C22: สามชั้นหมูหั่นแกง แพ็คถาด 1 กก. | I22: 4 | K22: =+SUM(D22:J22) -> 4
A23: =IF(B23="Grand Total","Grand Total",IFERROR(VLOOKUP(B23,Master!$D$1:$G$1720,4,FALSE),"")) -> สามชั้นพิเศษ | B23: 23110597 | C23: สามชั้นหั่นพะโล้ แพ็คถาด 1 กก. | I23: 4 | K23: =+SUM(D23:J23) -> 4
A24: =IF(B24="Grand Total","Grand Total",IFERROR(VLOOKUP(B24,Master!$D$1:$G$1720,4,FALSE),"")) -> สามชั้นพิเศษ | B24: 23110619 | C24: มันหมูหั่นเต๋า แพ็คถาด 500 กรัม | I24: 2 | K24: =+SUM(D24:J24) -> 2
A25: =IF(B25="Grand Total","Grand Total",IFERROR(VLOOKUP(B25,Master!$D$1:$G$1720,4,FALSE),"")) -> สามชั้นพิเศษ | B25: 23111031 | C25: สามชั้นหั่นพะโล้ แพ็คถาด 500 กรัม | I25: 2 | K25: =+SUM(D25:J25) -> 2
A26: =IF(B26="Grand Total","Grand Total",IFERROR(VLOOKUP(B26,Master!$D$1:$G$1720,4,FALSE),"")) -> สามชั้นพิเศษ | B26: 23111038 | C26: สามชั้นหมูหั่นแกง แพ็คถาด 500 กรัม | I26: 2 | K26: =+SUM(D26:J26) -> 2
A27: =IF(B27="Grand Total","Grand Total",IFERROR(VLOOKUP(B27,Master!$D$1:$G$1720,4,FALSE),"")) -> สามชั้น | B27: 23057815 | C27: สันนอก(M) | E27: 100 | G27: 40 | H27: 100 | I27: 200 | J27: 100 | K27: =+SUM(D27:J27) -> 540
A28: =IF(B28="Grand Total","Grand Total",IFERROR(VLOOKUP(B28,Master!$D$1:$G$1720,4,FALSE),"")) -> สามชั้น | B28: 23057818 | C28: สันใน(M) | G28: 5 | H28: 0 | I28: 10 | J28: 60 | K28: =+SUM(D28:J28) -> 75
A29: =IF(B29="Grand Total","Grand Total",IFERROR(VLOOKUP(B29,Master!$D$1:$G$1720,4,FALSE),"")) -> สามชั้น | B29: 23057824 | C29: สามชั้น(M) | E29: 50 | H29: 80 | J29: 100 | K29: =+SUM(D29:J29) -> 230
A30: =IF(B30="Grand Total","Grand Total",IFERROR(VLOOKUP(B30,Master!$D$1:$G$1720,4,FALSE),"")) -> สามชั้น | B30: 23057827 | C30: ซี่โครง(M) | E30: 0 | F30: 5 | K30: =+SUM(D30:J30) -> 5
